Workbook

Sheet ① 기입규약
A1: 지자기 시험 탐사 표준 야장 — 기입규약
A2: 이 야장은 서식이 아니라 «재발 방지 장치»다. 과거 야장 68개를 전수로 훑었더니 F 측정일시 실기재가 0건이어서 세션 단위 외부장 보정이 원리적으로 불가능해졌다. 칸이 없으면 그 값은 어떤 분석으로도 복원되지 않는다.
A3: ⚠ 이 양식은 Codex 독립 검토(2026-09-07, Critical 6 · Major 6)를 반영한 판본이다. 정량 임계값은 «파일럿 전 미확정»이며 판정 수식에 넣지 않았다 — 임계로 50점을 바로 가르지 말 것.
A5: 단위 — 논쟁 없이 고정한다
A6: 각도(현장 원시) | B6: 곤 gon (1회전 400 · 대척 200 gon). 현장 판독은 반드시 gon 으로 적는다. 도(°) 환산값은 읽기전용 계산 칸에만 둔다 — 단위를 고르게 하면 입력 후 단위를 바꿔도 값이 안 바뀌어 의미만 뒤집힌다.
A7: 총자력 F | B7: nT, 소수 1자리 (§17 0.1 nT 판독)
A8: 좌표 | B8: 십진도. 위도·경도를 «각각 다른 열»에 숫자로 적고 좌표계·취득방법·정확도를 함께 남긴다.
A9: 거리·높이 | B9: m, 소수 2자리
A11: 시각 — 세 자료의 시간대가 서로 다르다
A12: 기입 | B12: 날짜 + 시:분:초 를 한 칸에 (예 2026-10-14 13:24:05). 분까지만 적으면 세션 결합이 깨진다.
A13: 시간대 | B13: 야장은 KST. 상시관측소 CYG·Kp 는 UT, KASA 캐시는 KST — 결합 지점마다 확인할 것. UTC 환산은 계산 칸이 자동으로 만든다(KST − 9h).
A14: 자정 경계 | B14: 날짜를 함께 적으므로 자정을 넘겨도 세션이 끊기지 않는다.
A16: 방위각 — 정·역 혼동이 29쌍 있었다
A17: 규약 | B17: 진북 기준 · 북 = 0° · 시계방향 · **FROM = 기준점, TO = 방위표지**. 반대 방향을 적으면 그 방문의 편각이 통째로 틀어진다.
A18: 마크 식별 | B18: 표지마다 고정 Mark ID 를 부여하고 시준한 «지점»(표지 상단/중심 등)까지 적는다.
A19: 참방위각 | B19: 결정방법(천문·자이로·RTK 장기선·좌표계산)과 근거좌표·좌표 정확도를 남긴다. 이전 확정값과의 차이와 재결정 사유를 반드시 적는다 — 재방문 잔여 RMS 33.7′ 의 원인이 이것이다.
A21: 상태코드 — 빈칸을 0 으로 세지 않기 위해
A22: NOT AVAILABLE | B22: 자료가 존재하지 않음 (예: 항공자력 미측선 구역)
A23: NOT OBSERVED | B23: 관측을 실시하지 않음
A24: INVALID | B24: 관측했으나 무효 (장비 오류·기입 오류 등, 사유 필수)
A25: NOT APPLICABLE | B25: 그 점에는 해당하지 않는 항목
A26: PENDING | B26: 미정 — 확인 대기
A28: 색 규약
A29: 연한 노랑 | B29: 현장 기입란
A30: 연한 초록 | B30: 사전 채움 또는 계산값 — 현장에서 고치지 않는다
A31: 회색 | B31: 편집 금지
A32: 연한 적색 | B32: 주의·경고

Sheet ② 대상 50점
A1: 시험 탐사 대상 50점 — 등급 A 5 · B 도엽대표 29 · 기존점 16
A2: 선점 검토 결과 그대로다(export_selection_50 단일 출처). Site ID 는 이 야장 전체의 연결키이며 다른 시트는 이 값을 그대로 쓴다.
A3: ⚠ 「예측 |∇ΔT|」는 KIGAM 1.5분(약 2.8 km) 격자의 중앙차분값이다. 현장 수 m 스케일 측정과 «물리적으로 다른 양»이므로 합격기준으로 쓰지 않는다 — 사전 층화·탐색 변수일 뿐이다. 자료공백 5점(오호·문산·강화·포천·화천)은 NOT AVAILABLE 로 두고 감점하거나 보간하지 말 것.
A4: Site ID | B4: 연번 | C4: 구분 | D4: 원 번호 | E4: 지점명 | F4: 관할본부 | G4: 도엽번호 | H4: 도엽명 | I4: 위도(십진) | J4: 경도(십진) | K4: 표고(m) | L4: 소재지 | M4: 예측 |∇ΔT| (nT/km) ※판정 미사용 | N4: 예측 상태 | O4: 최근접 관측소 | P4: 관측소 거리(km) | Q4: 표지1 방위각 (기재값) | R4: 표지1 거리(m) | S4: 시험탐사 상태
A5: S01 | B5: 1 | C5: A | D5: DS-008 | E5: 태백 신규점 | F5: 대구경북 본부 | G5: NJ52-8-28 | H5: 태백 | I5: 37.020705 | J5: 128.98393 | K5: 872 | L5: 경북 봉화군 소천면 고선리 산 1 | M5: 15.6 | N5: OK | O5: 강릉 | P5: 83 | Q5: 178° 31' 53″ | R5: 69 | S5: 시험 탐사 대상
A6: S02 | B6: 2 | C6: A | D6: DS-015 | E6: 임계 신규점1 | F6: 강원 본부 | G6: NJ52-8-20 | H6: 임계 | I6: 37.359346 | J6: 128.97386 | K6: 844 | L6: 강원특별자치도 삼척시 하장면 숙암리 산 11-1 | M6: 24.3 | N6: OK | O6: 강릉 | P6: 46 | Q6: 177°43′54″ | R6: 79 | S6: 시험 탐사 대상
A7: S03 | B7: 3 | C7: A | D7: DS-076 | E7: 예산 신규점2 | F7: 대전세종충남 본부 | G7: NJ52-10-12 | H7: 예산 | I7: 36.534085 | J7: 126.93627 | K7: 116 | L7: 충남 공주시 신풍면 산정리 산 3 | M7: 9.3 | N7: OK | O7: 청양 | P7: 20 | Q7: 273°56′32″ | R7: 134 | S7: 시험 탐사 대상
A8: S04 | B8: 4 | C8: A | D8: DS-081 | E8: 진안 신규점1 | F8: 전북 본부 | G8: NI52-1-06 | H8: 진안 | I8: 35.891309 | J8: 127.30902 | K8: 297 | L8: 전북특별자치도 완주군 동상면 사봉리 산 107-2 | M8: 20.1 | N8: OK | O8: 청양 | P8: 67 | Q8: 328° 19' 19.77 | R8: 101 | S8: 시험 탐사 대상
A9: S05 | B9: 5 | C9: A | D9: DS-083 | E9: 무풍 신규점1 | F9: 전북 본부 | G9: NI52-1-08 | H9: 무풍 | I9: 35.945212 | J9: 127.80085 | K9: 584 | L9: 전북특별자치도 무주군 설천면 두길리 165 | M9: 26.6 | N9: OK | O9: 청양 | P9: 98 | Q9: 246° 16′ 35.46 | R9: 67 | S9: 시험 탐사 대상
A10: S06 | B10: 6 | C10: B | D10: DS-003 | E10: 길담 신규점 | F10: 전북 본부 | G10: NI52-1-13 | H10: 갈담 | I10: 35.604653 | J10: 127.23024 | K10: 281 | L10: 전북특별자치도 임실군 임실읍 신안리 산 87-1 | M10: 8.4 | N10: OK | O10: 청양 | P10: 91 | Q10: 351˚ 50´ 02˝ | R10: 64 | S10: 시험 탐사 대상
A11: S07 | B11: 7 | C11: B | D11: DS-004 | E11: 남해 신규점1 | F11: 경남 본부 | G11: NI52-4-08 | H11: 남해 | I11: 34.852281 | J11: 127.98147 | K11: 262 | L11: 경남 남해군 창선면 지족리 산 115 | M11: 5.4 | N11: OK | O11: 청양 | P11: 197 | Q11: 114°34′47″ | R11: 70 | S11: 시험 탐사 대상
A12: S08 | B12: 8 | C12: B | D12: DS-013 | E12: 청일 신규점2 | F12: 강원 본부 | G12: NJ52-8-09 | H12: 청일 | I12: 37.618578 | J12: 128.1698 | K12: 372 | L12: 강원특별자치도 횡성군 청일면 춘당리 산 1 | M12: 7.6 | N12: OK | O12: 강릉 | P12: 64 | Q12: 162° 55′ 36.41″ | R12: 63 | S12: 시험 탐사 대상
A13: S09 | B13: 9 | C13: B | D13: DS-014 | E13: 어론 신규점 | F13: 강원 본부 | G13: NJ52-8-01 | H13: 어론 | I13: 37.776326 | J13: 128.07586 | K13: 532 | L13: 강원특별자치도 홍천군 내촌면 화상대리 산 108-2 | M13: 4.7 | N13: OK | O13: 강릉 | P13: 70 | Q13: 278°9′11″ | R13: 37 | S13: 시험 탐사 대상
A14: S10 | B14: 10 | C14: B | D14: DS-020 | E14: 예안 신규점1 | F14: 대구경북 본부 | G14: NJ52-11-12 | H14: 예안 | I14: 36.745399 | J14: 128.85356 | K14: 293 | L14: 경북 안동시 도산면 토계리 350 | M14: 7.5 | N14: OK | O14: 강릉 | P14: 113 | Q14: 45°25′27 | R14: 28 | S14: 시험 탐사 대상
A15: S11 | B15: 11 | C15: B | D15: DS-025 | E15: 소천 신규점4 | F15: 대구경북 본부 | G15: NJ52-11-05 | H15: 소천 | I15: 36.765848 | J15: 129.15434 | K15: 380 | L15: 경북 영양군 일월면 문암리 산 59-2 | M15: 34.9 | N15: OK | O15: 강릉 | P15: 114 | Q15: 251°54'10" | R15: 38 | S15: 시험 탐사 대상
A16: S12 | B16: 12 | C16: B | D16: DS-030 | E16: 순창 신규점 | F16: 광주전남 본부 | G16: NI52-1-21 | H16: 순창 | I16: 35.284821 | J16: 127.09215 | K16: 219 | L16: 전남광주통합특별시 곡성군 오산면 운곡리 산 73-1 | M16: 23.1 | N16: OK | O16: 청양 | P16: 122 | Q16: 206°53′16″ | R16: 57 | S16: 시험 탐사 대상
... A22: S18 | B22: 18 | C22: B | D22: DS-045 | E22: 통영 신규점 | F22: 경남 본부 | G22: NI52-5-02 | H22: 통영 | I22: 34.792976 | J22: 128.39383 | K22: 79 | L22: 경남 통영시 산양읍 연화리 584 | M22: 140.1 | N22: OK | O22: 청양 | P22: 223 | Q22: 304°50'44" | R22: 26 | S22: 시험 탐사 대상
A23: S19 | B23: 19 | C23: B | D23: DS-046 | E23: 오호 신규점 | F23: 강원 본부 | G23: NJ52-5-19 | H23: 오호 | I23: 38.318869 | J23: 128.52176 | K23: 21 | L23: 강원특별자치도 고성군 죽왕면 삼포리 산 5 | N23: NOT AVAILABLE | O23: 강릉 | P23: 68 | Q23: 252°09′33.58" | R23: 36 | S23: 시험 탐사 대상
A24: S20 | B24: 20 | C24: B | D24: DS-049 | E24: 보령 신규점2 | F24: 대전세종충남 본부 | G24: NJ52-10-19 | H24: 보령 | I24: 36.266844 | J24: 126.70696 | K24: 277 | L24: 충남 부여군 외산면 가덕리 산 11-1 | M24: 4.4 | N24: OK | O24: 청양 | P24: 17 | Q24: 5° 15' 3.36 | R24: 75 | S24: 시험 탐사 대상
A25: S21 | B25: 21 | C25: B | D25: DS-051 | E25: 담양 신규점2 | F25: 전북 본부 | G25: NI52-1-20 | H25: 담양 | I25: 35.456101 | J25: 126.96205 | K25: 350 | L25: 전북특별자치도 순창군 복흥면 하리 산 27 | M25: 35.3 | N25: OK | O25: 청양 | P25: 102 | Q25: 227˚ 00´ 55˝ | R25: 44 | S25: 시험 탐사 대상
A26: S22 | B26: 22 | C26: B | D26: DS-055 | E26: 완도 신규점 | F26: 광주전남 본부 | G26: NI52-4-19 | H26: 완도 | I26: 34.328826 | J26: 126.54322 | K26: 131 | L26: 전남광주통합특별시 해남군 송지면 송호리 산 178-3 | M26: 48.2 | N26: OK | O26: 제주 | P26: 102 | Q26: 122º 46' 29 | R26: 38 | S26: 시험 탐사 대상
A27: S23 | B27: 23 | C27: B | D27: DS-057 | E27: 덕산 신규점1 | F27: 충북 본부 | G27: NJ52-11-01 | H27: 덕산 | I27: 36.888529 | J27: 128.19274 | K27: 388 | L27: 충북 제천시 덕산면 선고리 산 28-8 | M27: 9.9 | N27: OK | O27: 이천 | P27: 65 | Q27: 52˚41'47" | R27: 29 | S27: 시험 탐사 대상
A28: S24 | B28: 24 | C28: B | D28: DS-060 | E28: 회천 신규점2 | F28: 광주전남 본부 | G28: NI52-4-13 | H28: 회천 | I28: 34.680805 | J28: 127.04766 | K28: 99 | L28: 전남광주통합특별시 보성군 회천면 회령리 산 155 | M28: 10.1 | N28: OK | O28: 제주 | P28: 155 | Q28: 326° 39' 52 | R28: 27 | S28: 시험 탐사 대상
A29: S25 | B29: 25 | C29: B | D29: DS-068 | E29: 관리 신규점3 | F29: 대구경북 본부 | G29: NJ52-10-24 | H29: 관기 | I29: 36.325755 | J29: 127.90598 | K29: 383 | L29: 경북 상주시 모서면 득수리 산 146 | M29: 54.9 | N29: OK | O29: 청양 | P29: 95 | Q29: 141° 02’ 02 | R29: 60 | S29: 시험 탐사 대상
A30: S26 | B30: 26 | C30: B | D30: DS-075 | E30: 고남 신규점2 | F30: 대전세종충남 본부 | G30: NJ52-10-18 | H30: 고남 | I30: 36.452304 | J30: 126.3958 | K30: 38 | L30: 충남 태안군 고남면 누동리 산 6-514 | M30: 2.9 | N30: OK | O30: 청양 | P30: 42 | Q30: 29° 8' 15.13 | R30: 70 | S30: 시험 탐사 대상
A31: S27 | B31: 27 | C31: B | D31: DS-078 | E31: 전의 신규점 | F31: 대전세종충남 본부 | G31: NJ52-10-13 | H31: 전의 | I31: 36.579379 | J31: 127.0687 | K31: 372 | L31: 충남 공주시 사곡면 월가리 산 10-1 | M31: 2.9 | N31: OK | O31: 청양 | P31: 30 | Q31: 307°8′47″ | R31: 54 | S31: 시험 탐사 대상
A32: S28 | B32: 28 | C32: B | D32: DS-080 | E32: 이원 신규점 | F32: 대전세종충남 본부 | G32: NJ52-10-31 | H32: 이원 | I32: 36.16662 | J32: 127.58312 | K32: 300 | L32: 충남 금산군 제원면 신안리 산 4-1 | M32: 12 | N32: OK | O32: 청양 | P32: 70 | Q32: 157°40′41″ | R32: 42 | S32: 시험 탐사 대상
A33: S29 | B33: 29 | C33: B | D33: DS-084 | E33: 가야 신규점1 | F33: 경남 본부 | G33: NI52-2-01 | H33: 가야 | I33: 35.777986 | J33: 128.03683 | K33: 825 | L33: 경남 거창군 가북면 우혜리 산 3 | M33: 26.8 | N33: OK | O33: 청양 | P33: 125 | Q33: 115° 14' 22" | R33: 21 | S33: 시험 탐사 대상
A34: S30 | B34: 30 | C34: B | D34: DS-086 | E34: 창녕 신규점 | F34: 대구경북 본부 | G34: NI52-2-10 | H34: 창녕 | I34: 35.662586 | J34: 128.2981 | K34: 179 | L34: 경북 고령군 쌍림면 평지리 산 63 | M34: 22.7 | N34: OK | O34: 청양 | P34: 152 | Q34: 297° 30' 11 | R34: 23 | S34: 시험 탐사 대상
A35: S31 | B35: 31 | C35: B | D35: DS-089 | E35: 언양 신규점3 | F35: 대구경북 본부 | G35: NI52-2-13 | H35: 언양 | I35: 35.742364 | J35: 129.02982 | K35: 234 | L35: 경북 경주시 산내면 외칠리 산 183 | M35: 24.2 | N35: OK | O35: 이천 | P35: 205 | Q35: 352°5′13″ | R35: 33 | S35: 시험 탐사 대상
A36: S32 | B36: 32 | C36: B | D36: DS-096 | E36: 함양 신규점 | F36: 전북 본부 | G36: NI52-1-15 | H36: 함양 | I36: 35.586243 | J36: 127.57466 | K36: 478 | L36: 전북특별자치도 장수군 번암면 지지리 산 55 | M36: 16.5 | N36: OK | O36: 청양 | P36: 108 | Q36: 132º 38' 54 | R36: 34 | S36: 시험 탐사 대상
A37: S33 | B37: 33 | C37: B | D37: DS-098 | E37: 문산 신규점 | F37: 서울경기북부 본부 | G37: NJ52-7-04 | H37: 문산 | I37: 37.927676 | J37: 126.87031 | K37: 83 | L37: 경기 파주시 파평면 덕천리 산 40-3 | N37: NOT AVAILABLE | O37: 이천 | P37: 105 | Q37: 333° 29 '40.75 | R37: 94 | S37: 시험 탐사 대상
A38: S34 | B38: 34 | C38: B | D38: DS-102 | E38: 부안 신규점 | F38: 전북 본부 | G38: NI52-1-11 | H38: 부안 | I38: 35.541753 | J38: 126.64558 | K38: 112 | L38: 전북특별자치도 고창군 부안면 수앙리 산 79-8 | M38: 17 | N38: OK | O38: 청양 | P38: 93 | Q38: 115° 56' 52 | R38: 73 | S38: 시험 탐사 대상
A39: S35 | B39: 35 | C39: 기존점 | D39: 1-12-2 | E39: 상주 | G39: NJ52-14-16 | H39: 상주 | I39: 36.355288 | J39: 128.11048 | K39: 92.568 | L39: 경상북도 상주시 청리면 율리 436-2 밤깟마을(상주23) | M39: 43.6 | N39: OK | O39: 이천 | P39: 101 | Q39: NOT APPLICABLE | S39: 시험 탐사 대상
A40: S36 | B40: 36 | C40: 기존점 | D40: 1-13-2 | E40: 미원 | G40: NJ52-13-14 | H40: 미원 | I40: 36.725028 | J40: 127.58622 | K40: 97.952 | L40: 충청북도 청주시 청원구 북이면 영하리 산13-1(미원409) | M40: 5.4 | N40: OK | O40: 이천 | P40: 46 | Q40: NOT APPLICABLE | S40: HOLD — 좌표 353 m 불일치 — 표석 동일성 확인 전 과거 성과 대조 보류
A41: S37 | B41: 37 | C41: 기존점 | D41: 1-17-2 | E41: 부안 | G41: NJ52-01-10 | H41: 부안 | I41: 35.58775 | J41: 126.71614 | K41: 33.5 | L41: 전라북도 부안군 줄포면 난산리 440-2 목중새마을(부안423) | M41: 23.8 | N41: OK | O41: 청양 | P41: 87 | Q41: NOT APPLICABLE | S41: 시험 탐사 대상
A42: S38 | B42: 38 | C42: 기존점 | D42: 1-2-3 | E42: 강화 | G42: NJ52-09-09 | H42: 강화 | I42: 37.666124 | J42: 126.47878 | K42: 100.524 | L42: 인천광역시 강화군 길상면 길직리 산 148-6 | N42: NOT AVAILABLE | O42: 이천 | P42: 110 | Q42: NOT APPLICABLE | S42: 시험 탐사 대상
A43: S39 | B43: 39 | C43: 기존점 | D43: 1-23-1 | E43: 언양 | G43: NI52-2-13 | H43: 언양 | I43: 35.6762 | J43: 129.19087 | K43: 226.101 | L43: 울산광역시 울주군 두서면 미호리 산3(삼언양417) | M43: 38.3 | N43: OK | O43: 이천 | P43: 220 | Q43: NOT APPLICABLE | S43: 시험 탐사 대상
A44: S40 | B44: 40 | C44: 기존점 | D44: 1-24-3 | E44: 남지 | G44: NJ52-01-14 | H44: 남지 | I44: 35.436167 | J44: 128.47378 | L44: 창녕군 장마면 유리 1705-1 봉산지뚝 | M44: 9.4 | N44: OK | O44: 청양 | P44: 179 | Q44: NOT APPLICABLE | S44: 시험 탐사 대상
A45: S41 | B45: 41 | C45: 기존점 | D45: 1-25-2 | E45: 거제 | G45: NJ52-06-07 | H45: 거제 | I45: 34.870311 | J45: 128.59286 | K45: 91.014 | L45: 경상남도 거제시 거제면 옥산리 산83-6 | M45: 28.9 | N45: OK | O45: 청양 | P45: 229 | Q45: NOT APPLICABLE | S45: 시험 탐사 대상
...

Sheet ③ 점정보·좌표·이격
A1: 점 정보 · 좌표 검증 · §13② 이격거리
A2: 좌표는 «십진도 숫자»로 위도·경도를 각각 적고 좌표계·취득방법·정확도·출처를 함께 남긴다. 소수 자릿수만 맞추면 허위 정밀도가 생기고 위·경도 뒤바뀜도 못 막는다.
A3: ⚠ §13② 는 «도상 확인만으로 확정하지 않는다». 도상거리와 현장 확인거리를 각각 적고, 판정은 ⑨ 게이트에서 필수 조건으로 쓴다. 시설 분류가 불명확하면 임의 판정하지 말고 PENDING.
A4: Site ID | B4: 지점명 | C4: 구분 | D4: 사전 위도 | E4: 사전 경도 | F4: 현장 실측 위도 | G4: 현장 실측 경도 | H4: 좌표계 | I4: 측지기준 | J4: 취득방법 | K4: 수평정확도(m) | L4: 좌표 출처 | M4: 좌표 검증상태 | N4: 직류철도(km) 도상 | O4: 직류철도(km) 현장 | P4: 교류·일반철도(km) 도상 | Q4: 교류·일반철도(km) 현장 | R4: 고압철탑(km) 도상 | S4: 고압철탑(km) 현장 | T4: 송전탑(km) 도상 | U4: 송전탑(km) 현장 | V4: 최근접 시설 ID·유형 | W4: 자료 기준일 | X4: §13② 판정
A5: S01 | B5: 태백 신규점 | C5: A | D5: 37.020705 | E5: 128.98393
A6: S02 | B6: 임계 신규점1 | C6: A | D6: 37.359346 | E6: 128.97386
A7: S03 | B7: 예산 신규점2 | C7: A | D7: 36.534085 | E7: 126.93627
A8: S04 | B8: 진안 신규점1 | C8: A | D8: 35.891309 | E8: 127.30902
A9: S05 | B9: 무풍 신규점1 | C9: A | D9: 35.945212 | E9: 127.80085
A10: S06 | B10: 길담 신규점 | C10: B | D10: 35.604653 | E10: 127.23024
A11: S07 | B11: 남해 신규점1 | C11: B | D11: 34.852281 | E11: 127.98147
A12: S08 | B12: 청일 신규점2 | C12: B | D12: 37.618578 | E12: 128.1698
A13: S09 | B13: 어론 신규점 | C13: B | D13: 37.776326 | E13: 128.07586
A14: S10 | B14: 예안 신규점1 | C14: B | D14: 36.745399 | E14: 128.85356
A15: S11 | B15: 소천 신규점4 | C15: B | D15: 36.765848 | E15: 129.15434
A16: S12 | B16: 순창 신규점 | C16: B | D16: 35.284821 | E16: 127.09215
... A54: S50 | B54: 함양 | C54: 기존점 | D54: 35.542509 | E54: 127.62297

Sheet ④ 기존점 대조가능성
A1: 기존 관측점 16점 — 과거 성과와의 «성분별» 대조 가능성
A2: ⚠ 「기존 성과가 있다」와 「직접 비교할 수 있다」는 다른 문제다. 과거 기록에는 마크 방위각 변동(재방문 잔여 RMS 33.7′)·F 측정시각 전무·방위 방향 혼동이 섞여 있다. 따라서 적어도 편각 D 와 시간보정이 필요한 F 는 무조건 직접 비교할 수 없다.
A3: 성분마다 «비교 가능 / 조건부 / 불가»를 따로 판정하고, 근거를 적는다. 표석·표지 동일성이 확인되지 않으면 그 점 전체를 HOLD 로 둔다.
A4: Site ID | B4: 지점명 | C4: 지점코드 | D4: 종전 성과 연도 | E4: 종전 편각(°) | F4: 종전 복각(°) | G4: 종전 총자력(nT) | H4: 종전 관측장비 | I4: 동일 표석 확인 | J4: 동일 표지 확인 | K4: 좌표 검증 | L4: D 비교가능 | M4: I 비교가능 | N4: F 비교가능
A5: S35 | B5: 상주 | C5: 1-12-2 | D5: 2025.09.24. | E5: -8.193992 | F5: 52.758553 | G5: 50560 | H5: MAG-02H
A6: S36 | B6: 미원 | C6: 1-13-2 | D6: 2024.05.01. | E6: -9.122264 | F6: 53.412156 | G6: 50709.3 | H6: MAG-02H | I6: HOLD | J6: HOLD | K6: HOLD | L6: HOLD | M6: HOLD | N6: HOLD
A7: S37 | B7: 부안 | C7: 1-17-2 | D7: 2025.11.04. | E7: -8.473328 | F7: 52.376639 | G7: 50678.1 | H7: MAG-02H
A8: S38 | B8: 강화 | C8: 1-2-3 | D8: 2024.04.17 | E8: -8.659731 | F8: 54.765217 | G8: 51531.2 | H8: MAG-02H
A9: S39 | B9: 언양 | C9: 1-23-1 | D9: 2024.10.17 | E9: -9.003039 | F9: 51.749664 | G9: 49597.3 | H9: MAG-01H
A10: S40 | B10: 남지 | C10: 1-24-3 | D10: 2019.06.24 | E10: -7.60285 | F10: 51.288442 | G10: 49481.8 | H10: MAG-01H
A11: S41 | B11: 거제 | C11: 1-25-2 | D11: 2024.10.24. | E11: -8.147075 | F11: 51.198997 | G11: 49335.5 | H11: MAG-02H
A12: S42 | B12: 조도 | C12: 1-29-2 | D12: 2010연구성과 | E12: -6.0461111 | F12: 50.368333 | G12: 49534 | H12: 연구성과보고서
A13: S43 | B13: 포천 | C13: 1-3-3 | D13: 2025.05.27. | E13: -9.245017 | F13: 55.042983 | G13: 51495.3 | H13: MAG-02H
A14: S44 | B14: 성산 | C14: 1-30-2 | D14: 2025.05.15 | E14: -8.658169 | F14: 50.120781 | G14: 48909.9 | H14: MAG-03H
A15: S45 | B15: 여주 | C15: 1-4-4 | D15: 2023.09.07 | E15: -9.2674306 | F15: 54.423825 | G15: 51174.98 | H15: MAG-01H
A16: S46 | B16: 화천 | C16: 1-5-2 | D16: 2018.5.23 | E16: -8.933944 | F16: 54.944778 | G16: 51499.4 | H16: MAG-01H
A17: S47 | B17: 봉평 | C17: 1-7-2 | D17: 2015 | E17: -8.446667 | F17: 54.1425 | G17: 50634 | H17: MAG-04H
A18: S48 | B18: 삼척 | C18: 1-8-4 | D18: 2024.08.29. | E18: -8.223683 | F18: 54.325956 | G18: 50647.4 | H18: MAG-07H
... A20: S50 | B20: 함양 | C20: 1-20-3 | D20: 2025.10.29. | E20: -7.629208 | F20: 52.017197 | G20: 49779.9 | H20: MAG-02H

Sheet ⑤ 방위표지·참방위각
A1: 방위표지 · 참방위각 결정 — 편각 30′ 잔차의 주범
A2: ⚠ 규약: 진북 기준 · 북 = 0° · 시계방향 · FROM = 기준점 · TO = 방위표지. 현장 원시각은 «gon» 으로 적는다(1회전 400 · 대척 200). 도(°) 환산은 계산 칸이다. 200 gon 역방향과 180° 역방향이 섞이면 대규모 오류가 난다.
A3: 재방문 16구간 전부에서 마크 참방위각이 60″ 넘게 변했다. 마크를 바꾸는 것 자체는 오류가 아니지만, 바뀐 마크의 참방위각이 틀리면 그 방문의 편각이 통째로 틀어진다. 그래서 «이전 확정값 대비 차이»와 «재결정 사유»가 필수다.
A4: Site ID | B4: Mark ID | C4: 지점명 | D4: 표지 구분 | E4: 표지 위도 | F4: 표지 경도 | G4: 시준 지점(표지의 어디) | H4: FROM | I4: TO | J4: 정 시준 원시각(gon) | K4: 반 시준 원시각(gon) | L4: 폐합차(gon) | M4: 참방위각(gon) | N4: 참방위각(°) 계산 | O4: 역방위(°) 계산 | P4: 결정방법 | Q4: 근거좌표 정확도(m) | R4: 이전 확정 방위각(°) | S4: 이전값 대비 차(″) | T4: 재결정 사유
A5: S01 | B5: S01-M1 | C5: 태백 신규점 | D5: 방위표지1 | E5: 37.020007 | F5: 128.98392 | H5: 기준점 | I5: 방위표지 | L5: =IF(COUNT(J5:K5)=2,ABS(ABS(K5-J5)-200),"") | N5: =IF(N(M5)=0,"",M5*0.9) | O5: =IF(N(M5)=0,"",MOD(M5*0.9+180,360)) | S5: =IF(OR(N(M5)=0,N(R5)=0),"",(M5*0.9-R5)*3600)
A6: S01 | B6: S01-M2 | C6: 태백 신규점 | D6: 방위표지2 | E6: 37.021716 | F6: 128.98347 | H6: 기준점 | I6: 방위표지 | L6: =IF(COUNT(J6:K6)=2,ABS(ABS(K6-J6)-200),"") | N6: =IF(N(M6)=0,"",M6*0.9) | O6: =IF(N(M6)=0,"",MOD(M6*0.9+180,360)) | S6: =IF(OR(N(M6)=0,N(R6)=0),"",(M6*0.9-R6)*3600)
A7: S02 | B7: S02-M1 | C7: 임계 신규점1 | D7: 방위표지1 | E7: 37.3587 | F7: 128.9739 | H7: 기준점 | I7: 방위표지 | L7: =IF(COUNT(J7:K7)=2,ABS(ABS(K7-J7)-200),"") | N7: =IF(N(M7)=0,"",M7*0.9) | O7: =IF(N(M7)=0,"",MOD(M7*0.9+180,360)) | S7: =IF(OR(N(M7)=0,N(R7)=0),"",(M7*0.9-R7)*3600)
A8: S02 | B8: S02-M2 | C8: 임계 신규점1 | D8: 방위표지2 | E8: 37.358529 | F8: 128.97477 | H8: 기준점 | I8: 방위표지 | L8: =IF(COUNT(J8:K8)=2,ABS(ABS(K8-J8)-200),"") | N8: =IF(N(M8)=0,"",M8*0.9) | O8: =IF(N(M8)=0,"",MOD(M8*0.9+180,360)) | S8: =IF(OR(N(M8)=0,N(R8)=0),"",(M8*0.9-R8)*3600)
A9: S03 | B9: S03-M1 | C9: 예산 신규점2 | D9: 방위표지1 | E9: 36.534094 | F9: 126.93481 | H9: 기준점 | I9: 방위표지 | L9: =IF(COUNT(J9:K9)=2,ABS(ABS(K9-J9)-200),"") | N9: =IF(N(M9)=0,"",M9*0.9) | O9: =IF(N(M9)=0,"",MOD(M9*0.9+180,360)) | S9: =IF(OR(N(M9)=0,N(R9)=0),"",(M9*0.9-R9)*3600)
A10: S03 | B10: S03-M2 | C10: 예산 신규점2 | D10: 방위표지2 | E10: 36.533699 | F10: 126.93798 | H10: 기준점 | I10: 방위표지 | L10: =IF(COUNT(J10:K10)=2,ABS(ABS(K10-J10)-200),"") | N10: =IF(N(M10)=0,"",M10*0.9) | O10: =IF(N(M10)=0,"",MOD(M10*0.9+180,360)) | S10: =IF(OR(N(M10)=0,N(R10)=0),"",(M10*0.9-R10)*3600)
A11: S04 | B11: S04-M1 | C11: 진안 신규점1 | D11: 방위표지1 | E11: 35.891876 | F11: 127.30849 | H11: 기준점 | I11: 방위표지 | L11: =IF(COUNT(J11:K11)=2,ABS(ABS(K11-J11)-200),"") | N11: =IF(N(M11)=0,"",M11*0.9) | O11: =IF(N(M11)=0,"",MOD(M11*0.9+180,360)) | S11: =IF(OR(N(M11)=0,N(R11)=0),"",(M11*0.9-R11)*3600)
A12: S04 | B12: S04-M2 | C12: 진안 신규점1 | D12: 방위표지2 | E12: 35.89031 | F12: 127.30879 | H12: 기준점 | I12: 방위표지 | L12: =IF(COUNT(J12:K12)=2,ABS(ABS(K12-J12)-200),"") | N12: =IF(N(M12)=0,"",M12*0.9) | O12: =IF(N(M12)=0,"",MOD(M12*0.9+180,360)) | S12: =IF(OR(N(M12)=0,N(R12)=0),"",(M12*0.9-R12)*3600)
A13: S05 | B13: S05-M1 | C13: 무풍 신규점1 | D13: 방위표지1 | E13: 35.945053 | F13: 127.80054 | H13: 기준점 | I13: 방위표지 | L13: =IF(COUNT(J13:K13)=2,ABS(ABS(K13-J13)-200),"") | N13: =IF(N(M13)=0,"",M13*0.9) | O13: =IF(N(M13)=0,"",MOD(M13*0.9+180,360)) | S13: =IF(OR(N(M13)=0,N(R13)=0),"",(M13*0.9-R13)*3600)
A14: S05 | B14: S05-M2 | C14: 무풍 신규점1 | D14: 방위표지2 | E14: 35.946307 | F14: 127.80241 | H14: 기준점 | I14: 방위표지 | L14: =IF(COUNT(J14:K14)=2,ABS(ABS(K14-J14)-200),"") | N14: =IF(N(M14)=0,"",M14*0.9) | O14: =IF(N(M14)=0,"",MOD(M14*0.9+180,360)) | S14: =IF(OR(N(M14)=0,N(R14)=0),"",(M14*0.9-R14)*3600)
A15: S06 | B15: S06-M1 | C15: 길담 신규점 | D15: 방위표지1 | E15: 35.605228 | F15: 127.23014 | H15: 기준점 | I15: 방위표지 | L15: =IF(COUNT(J15:K15)=2,ABS(ABS(K15-J15)-200),"") | N15: =IF(N(M15)=0,"",M15*0.9) | O15: =IF(N(M15)=0,"",MOD(M15*0.9+180,360)) | S15: =IF(OR(N(M15)=0,N(R15)=0),"",(M15*0.9-R15)*3600)
A16: S06 | B16: S06-M2 | C16: 길담 신규점 | D16: 방위표지2 | E16: 35.604125 | F16: 127.23019 | H16: 기준점 | I16: 방위표지 | L16: =IF(COUNT(J16:K16)=2,ABS(ABS(K16-J16)-200),"") | N16: =IF(N(M16)=0,"",M16*0.9) | O16: =IF(N(M16)=0,"",MOD(M16*0.9+180,360)) | S16: =IF(OR(N(M16)=0,N(R16)=0),"",(M16*0.9-R16)*3600)
... A72: S34 | B72: S34-M2 | C72: 부안 신규점 | D72: 방위표지2 | E72: 35.542434 | F72: 126.64437 | H72: 기준점 | I72: 방위표지 | L72: =IF(COUNT(J72:K72)=2,ABS(ABS(K72-J72)-200),"") | N72: =IF(N(M72)=0,"",M72*0.9) | O72: =IF(N(M72)=0,"",MOD(M72*0.9+180,360)) | S72: =IF(OR(N(M72)=0,N(R72)=0),"",(M72*0.9-R72)*3600)
A73: S35 | B73: S35-M1 | C73: 상주 | D73: 방위표지1 | H73: 기준점 | I73: 방위표지 | L73: =IF(COUNT(J73:K73)=2,ABS(ABS(K73-J73)-200),"") | N73: =IF(N(M73)=0,"",M73*0.9) | O73: =IF(N(M73)=0,"",MOD(M73*0.9+180,360)) | S73: =IF(OR(N(M73)=0,N(R73)=0),"",(M73*0.9-R73)*3600)
A74: S35 | B74: S35-M2 | C74: 상주 | D74: 방위표지2 | H74: 기준점 | I74: 방위표지 | L74: =IF(COUNT(J74:K74)=2,ABS(ABS(K74-J74)-200),"") | N74: =IF(N(M74)=0,"",M74*0.9) | O74: =IF(N(M74)=0,"",MOD(M74*0.9+180,360)) | S74: =IF(OR(N(M74)=0,N(R74)=0),"",(M74*0.9-R74)*3600)
A75: S36 | B75: S36-M1 | C75: 미원 | D75: 방위표지1 | H75: 기준점 | I75: 방위표지 | L75: =IF(COUNT(J75:K75)=2,ABS(ABS(K75-J75)-200),"") | N75: =IF(N(M75)=0,"",M75*0.9) | O75: =IF(N(M75)=0,"",MOD(M75*0.9+180,360)) | S75: =IF(OR(N(M75)=0,N(R75)=0),"",(M75*0.9-R75)*3600)
A76: S36 | B76: S36-M2 | C76: 미원 | D76: 방위표지2 | H76: 기준점 | I76: 방위표지 | L76: =IF(COUNT(J76:K76)=2,ABS(ABS(K76-J76)-200),"") | N76: =IF(N(M76)=0,"",M76*0.9) | O76: =IF(N(M76)=0,"",MOD(M76*0.9+180,360)) | S76: =IF(OR(N(M76)=0,N(R76)=0),"",(M76*0.9-R76)*3600)
A77: S37 | B77: S37-M1 | C77: 부안 | D77: 방위표지1 | H77: 기준점 | I77: 방위표지 | L77: =IF(COUNT(J77:K77)=2,ABS(ABS(K77-J77)-200),"") | N77: =IF(N(M77)=0,"",M77*0.9) | O77: =IF(N(M77)=0,"",MOD(M77*0.9+180,360)) | S77: =IF(OR(N(M77)=0,N(R77)=0),"",(M77*0.9-R77)*3600)
A78: S37 | B78: S37-M2 | C78: 부안 | D78: 방위표지2 | H78: 기준점 | I78: 방위표지 | L78: =IF(COUNT(J78:K78)=2,ABS(ABS(K78-J78)-200),"") | N78: =IF(N(M78)=0,"",M78*0.9) | O78: =IF(N(M78)=0,"",MOD(M78*0.9+180,360)) | S78: =IF(OR(N(M78)=0,N(R78)=0),"",(M78*0.9-R78)*3600)
A79: S38 | B79: S38-M1 | C79: 강화 | D79: 방위표지1 | H79: 기준점 | I79: 방위표지 | L79: =IF(COUNT(J79:K79)=2,ABS(ABS(K79-J79)-200),"") | N79: =IF(N(M79)=0,"",M79*0.9) | O79: =IF(N(M79)=0,"",MOD(M79*0.9+180,360)) | S79: =IF(OR(N(M79)=0,N(R79)=0),"",(M79*0.9-R79)*3600)
A80: S38 | B80: S38-M2 | C80: 강화 | D80: 방위표지2 | H80: 기준점 | I80: 방위표지 | L80: =IF(COUNT(J80:K80)=2,ABS(ABS(K80-J80)-200),"") | N80: =IF(N(M80)=0,"",M80*0.9) | O80: =IF(N(M80)=0,"",MOD(M80*0.9+180,360)) | S80: =IF(OR(N(M80)=0,N(R80)=0),"",(M80*0.9-R80)*3600)
A81: S39 | B81: S39-M1 | C81: 언양 | D81: 방위표지1 | H81: 기준점 | I81: 방위표지 | L81: =IF(COUNT(J81:K81)=2,ABS(ABS(K81-J81)-200),"") | N81: =IF(N(M81)=0,"",M81*0.9) | O81: =IF(N(M81)=0,"",MOD(M81*0.9+180,360)) | S81: =IF(OR(N(M81)=0,N(R81)=0),"",(M81*0.9-R81)*3600)
A82: S39 | B82: S39-M2 | C82: 언양 | D82: 방위표지2 | H82: 기준점 | I82: 방위표지 | L82: =IF(COUNT(J82:K82)=2,ABS(ABS(K82-J82)-200),"") | N82: =IF(N(M82)=0,"",M82*0.9) | O82: =IF(N(M82)=0,"",MOD(M82*0.9+180,360)) | S82: =IF(OR(N(M82)=0,N(R82)=0),"",(M82*0.9-R82)*3600)
A83: S40 | B83: S40-M1 | C83: 남지 | D83: 방위표지1 | H83: 기준점 | I83: 방위표지 | L83: =IF(COUNT(J83:K83)=2,ABS(ABS(K83-J83)-200),"") | N83: =IF(N(M83)=0,"",M83*0.9) | O83: =IF(N(M83)=0,"",MOD(M83*0.9+180,360)) | S83: =IF(OR(N(M83)=0,N(R83)=0),"",(M83*0.9-R83)*3600)
A84: S40 | B84: S40-M2 | C84: 남지 | D84: 방위표지2 | H84: 기준점 | I84: 방위표지 | L84: =IF(COUNT(J84:K84)=2,ABS(ABS(K84-J84)-200),"") | N84: =IF(N(M84)=0,"",M84*0.9) | O84: =IF(N(M84)=0,"",MOD(M84*0.9+180,360)) | S84: =IF(OR(N(M84)=0,N(R84)=0),"",(M84*0.9-R84)*3600)
... A104: S50 | B104: S50-M2 | C104: 함양 | D104: 방위표지2 | H104: 기준점 | I104: 방위표지 | L104: =IF(COUNT(J104:K104)=2,ABS(ABS(K104-J104)-200),"") | N104: =IF(N(M104)=0,"",M104*0.9) | O104: =IF(N(M104)=0,"",MOD(M104*0.9+180,360)) | S104: =IF(OR(N(M104)=0,N(R104)=0),"",(M104*0.9-R104)*3600)

Sheet ⑥ 기준자력계
A1: 현지 기준자력계(연속 기록) — 일변화와 공간변화를 나누는 유일한 수단
A2: ⚠ 같은 측선을 시간을 두고 두 번 재는 것만으로는 «공간장»과 «시간변화»를 나눌 수 없다. 같은 순서로 돌면 위치와 시각이 함께 움직이기 때문이다. 상시관측소는 중앙 101 km · 최대 229 km 떨어져 있고, 그 거리에서 «외부장이 전역 균일»하다는 근사가 깨짐을 이 프로젝트가 이미 실증했다.
A3: → 현지 고정점에 기준자력계를 두고 «초 단위로 동기화»해 연속 기록한다. 기준자력계를 운용하지 못한 점은 ⑩ 판정에서 「시간변화 미분리」로 표시하고 **선점 확정 근거로 쓰지 않는다**. (투입 여부는 예산·인력 판단 — ⑫ 참조)
A4: Site ID | B4: Visit ID | C4: 기준자력계 위치 ID | D4: 위도 | E4: 경도 | F4: 센서 높이(m) | G4: 기기 제조사·모델 | H4: 기기번호 | I4: 기록 간격(s) | J4: 기록 시작(KST) | K4: 기록 종료(KST) | L4: 이동 자력계와 시계 동기 방법 | M4: 기록파일명

Sheet ⑦ 자기환경 측선
A1: 자기환경 시험 — 측점 «관측행»
A2: 측선 설계는 **파일럿 먼저**다. 소수 지점에서 조밀하게 재어 필요한 간격·범위를 정한 뒤 전 지점에 최소 공통 설계를 적용하고, 이상 징후가 있는 곳만 격자를 추가한다 — 처음부터 전 지점 516 판독을 강제하면 일정에 눌려 좌표·시각 기록이 먼저 생략된다.
A3: ⚠ 순회 순서는 «중심점 재관측(A–B–A)»과 «역순 재측선»을 포함해야 한다. 같은 순서로 두 번 도는 것은 시간변화를 분리하지 못한다. 판독은 «3회를 각각» 남기고 중앙값은 계산 칸이다 — 중앙값만 남기면 오기·순간이상·제외값을 재검증할 수 없다.
A4: Site ID | B4: Visit ID | C4: Point ID | D4: 측선 | E4: 순회 회차 | F4: 순회 순서(정/역) | G4: E 오프셋(m) | H4: N 오프셋(m) | I4: 실제 센서 높이(m) | J4: 높이 기준 | K4: 기기번호 | L4: 관측 시각(KST) | M4: UTC 환산 | N4: F 판독1(nT) | O4: F 판독2(nT) | P4: F 판독3(nT) | Q4: 중앙값(nT) | R4: 상태·비고
M5: =IF(L5="","",L5-TIME(9,0,0)) | Q5: =IF(COUNT(N5:P5)=0,"",MEDIAN(N5:P5))
M6: =IF(L6="","",L6-TIME(9,0,0)) | Q6: =IF(COUNT(N6:P6)=0,"",MEDIAN(N6:P6))
M7: =IF(L7="","",L7-TIME(9,0,0)) | Q7: =IF(COUNT(N7:P7)=0,"",MEDIAN(N7:P7))
M8: =IF(L8="","",L8-TIME(9,0,0)) | Q8: =IF(COUNT(N8:P8)=0,"",MEDIAN(N8:P8))
M9: =IF(L9="","",L9-TIME(9,0,0)) | Q9: =IF(COUNT(N9:P9)=0,"",MEDIAN(N9:P9))
M10: =IF(L10="","",L10-TIME(9,0,0)) | Q10: =IF(COUNT(N10:P10)=0,"",MEDIAN(N10:P10))
M11: =IF(L11="","",L11-TIME(9,0,0)) | Q11: =IF(COUNT(N11:P11)=0,"",MEDIAN(N11:P11))
M12: =IF(L12="","",L12-TIME(9,0,0)) | Q12: =IF(COUNT(N12:P12)=0,"",MEDIAN(N12:P12))
M13: =IF(L13="","",L13-TIME(9,0,0)) | Q13: =IF(COUNT(N13:P13)=0,"",MEDIAN(N13:P13))
M14: =IF(L14="","",L14-TIME(9,0,0)) | Q14: =IF(COUNT(N14:P14)=0,"",MEDIAN(N14:P14))
M15: =IF(L15="","",L15-TIME(9,0,0)) | Q15: =IF(COUNT(N15:P15)=0,"",MEDIAN(N15:P15))
M16: =IF(L16="","",L16-TIME(9,0,0)) | Q16: =IF(COUNT(N16:P16)=0,"",MEDIAN(N16:P16))
... M404: =IF(L404="","",L404-TIME(9,0,0)) | Q404: =IF(COUNT(N404:P404)=0,"",MEDIAN(N404:P404))

Sheet ⑧ 절대측정 관측행
A1: 절대측정 — 세션 아래 «관측행». 이 시트가 이 야장의 중심이다
A2: 연결키: Site — Visit — Date — Session — Seq — Component — Location — Instrument. 이 여덟 중 하나만 비어도 D·I·F 를 다시 묶을 수 없다. 과거에 F 시각이 사라진 것이 정확히 이 결합의 실패였다.
A3: ⚠ F 는 «판독마다» 초 단위 시각을 적는다(§19①6 총자기장·시간 동시 측정). D·I 는 시작·종료 시각을 각각 적는다(§20 20분 이내 판정 근거). 원시 판독값을 남기고 최종값만 적지 않는다.
A4: Site ID | B4: Visit ID | C4: 관측일자 | D4: Session | E4: Seq | F4: Component | G4: Location ID | H4: Instrument | I4: 시작 시각(KST) | J4: 종료 시각(KST) | K4: 소요(분) 계산 | L4: UTC 시작 계산 | M4: 원시 판독(gon) | N4: 원시 판독 단위 | O4: 산출값 | P4: D(°) | Q4: I(°) | R4: F(nT) | S4: 센서 높이(m) | T4: 관측자 | U4: 상태 | V4: 비고
K5: =IF(OR(I5="",J5=""),"",(J5-I5)*1440) | L5: =IF(I5="","",I5-TIME(9,0,0)) | N5: gon
K6: =IF(OR(I6="",J6=""),"",(J6-I6)*1440) | L6: =IF(I6="","",I6-TIME(9,0,0)) | N6: gon
K7: =IF(OR(I7="",J7=""),"",(J7-I7)*1440) | L7: =IF(I7="","",I7-TIME(9,0,0)) | N7: gon
K8: =IF(OR(I8="",J8=""),"",(J8-I8)*1440) | L8: =IF(I8="","",I8-TIME(9,0,0)) | N8: gon
K9: =IF(OR(I9="",J9=""),"",(J9-I9)*1440) | L9: =IF(I9="","",I9-TIME(9,0,0)) | N9: gon
K10: =IF(OR(I10="",J10=""),"",(J10-I10)*1440) | L10: =IF(I10="","",I10-TIME(9,0,0)) | N10: gon
K11: =IF(OR(I11="",J11=""),"",(J11-I11)*1440) | L11: =IF(I11="","",I11-TIME(9,0,0)) | N11: gon
K12: =IF(OR(I12="",J12=""),"",(J12-I12)*1440) | L12: =IF(I12="","",I12-TIME(9,0,0)) | N12: gon
K13: =IF(OR(I13="",J13=""),"",(J13-I13)*1440) | L13: =IF(I13="","",I13-TIME(9,0,0)) | N13: gon
K14: =IF(OR(I14="",J14=""),"",(J14-I14)*1440) | L14: =IF(I14="","",I14-TIME(9,0,0)) | N14: gon
K15: =IF(OR(I15="",J15=""),"",(J15-I15)*1440) | L15: =IF(I15="","",I15-TIME(9,0,0)) | N15: gon
K16: =IF(OR(I16="",J16=""),"",(J16-I16)*1440) | L16: =IF(I16="","",I16-TIME(9,0,0)) | N16: gon
... K504: =IF(OR(I504="",J504=""),"",(J504-I504)*1440) | L504: =IF(I504="","",I504-TIME(9,0,0)) | N504: gon

Sheet ⑨ 두지점 F·기기대조
A1: 두 지점 F (센서 위치차) · 기기 상호대조 — A–B–A 로 시간변화를 뺀다
A2: ⚠ 두 지점을 한 번씩 순차로 재면 «위치차 + 그 사이 시간변화»가 섞인다. A(DI점) → B(원격점) → A(DI점) 순서로 재고, A 두 값의 선형내삽으로 B 시각의 A 값을 추정해 ΔF 를 낸다. 두 기기를 «서로 바꿔» 한 번 더 재면 기기 바이어스도 분리된다.
A3: 과거 야장의 「기본값」은 두 번째 지점 측정값이 아니라 «측정값의 정수부»였다 — 즉 센서 위치차 보정에 쓸 두 지점 F 가 애초에 존재하지 않았다(68개 전수 확인).
A4: Site ID | B4: Visit ID | C4: Set ID | D4: 순서 | E4: Location ID | F4: 실제 거리 A↔B(m) | G4: 방위(기준점→원격점, °) | H4: 기기번호 | I4: 센서 높이(m) | J4: 관측 시각(KST) | K4: F 판독1 | L4: F 판독2 | M4: F 판독3 | N4: 중앙값 계산 | O4: 교차배치(swap) 여부 | P4: ΔF(위치차, nT) | Q4: 비고
N5: =IF(COUNT(K5:M5)=0,"",MEDIAN(K5:M5))
N6: =IF(COUNT(K6:M6)=0,"",MEDIAN(K6:M6))
N7: =IF(COUNT(K7:M7)=0,"",MEDIAN(K7:M7))
N8: =IF(COUNT(K8:M8)=0,"",MEDIAN(K8:M8))
N9: =IF(COUNT(K9:M9)=0,"",MEDIAN(K9:M9))
N10: =IF(COUNT(K10:M10)=0,"",MEDIAN(K10:M10))
N11: =IF(COUNT(K11:M11)=0,"",MEDIAN(K11:M11))
N12: =IF(COUNT(K12:M12)=0,"",MEDIAN(K12:M12))
N13: =IF(COUNT(K13:M13)=0,"",MEDIAN(K13:M13))
N14: =IF(COUNT(K14:M14)=0,"",MEDIAN(K14:M14))
N15: =IF(COUNT(K15:M15)=0,"",MEDIAN(K15:M15))
N16: =IF(COUNT(K16:M16)=0,"",MEDIAN(K16:M16))
... N204: =IF(COUNT(K204:M204)=0,"",MEDIAN(K204:M204))

Sheet ⑩ 게이트 점검
A1: 법정 요건 · 기록 완전성 게이트 — 통과/실패로만 가른다
A2: ⚠ 근거 없는 정량 임계로 선점을 확정하지 않기 위해, 판정을 두 층으로 나눈다. 이 시트는 «반드시 통과해야 하는 것»만 다룬다 — 법정 조문과 기록 완전성이다. 정량 지표는 ⑪에서 «참고»로만 본다.
A4: Site ID | B4: 지점명 | C4: §13② 이격 | D4: §17 0.1 nT 판독 | E4: §19① 1일 6세션 이상 | F4: §19①6 F·시각 동시 | G4: §20 정수차 30′ | H4: §20 20분 이내 | I4: §21 상시 기준점 대조 | J4: 기준자력계 연속기록 | K4: 두 지점 F(A–B–A) | L4: 참방위각 결정 | M4: 좌표 검증 | N4: 게이트 종합
A5: S01 | B5: 태백 신규점 | N5: =IF(COUNTIF(C5:L5,"실패")>0,"실패",IF(COUNTIF(C5:L5,"통과")=10,"통과","미완"))
A6: S02 | B6: 임계 신규점1 | N6: =IF(COUNTIF(C6:L6,"실패")>0,"실패",IF(COUNTIF(C6:L6,"통과")=10,"통과","미완"))
A7: S03 | B7: 예산 신규점2 | N7: =IF(COUNTIF(C7:L7,"실패")>0,"실패",IF(COUNTIF(C7:L7,"통과")=10,"통과","미완"))
A8: S04 | B8: 진안 신규점1 | N8: =IF(COUNTIF(C8:L8,"실패")>0,"실패",IF(COUNTIF(C8:L8,"통과")=10,"통과","미완"))
A9: S05 | B9: 무풍 신규점1 | N9: =IF(COUNTIF(C9:L9,"실패")>0,"실패",IF(COUNTIF(C9:L9,"통과")=10,"통과","미완"))
A10: S06 | B10: 길담 신규점 | N10: =IF(COUNTIF(C10:L10,"실패")>0,"실패",IF(COUNTIF(C10:L10,"통과")=10,"통과","미완"))
A11: S07 | B11: 남해 신규점1 | N11: =IF(COUNTIF(C11:L11,"실패")>0,"실패",IF(COUNTIF(C11:L11,"통과")=10,"통과","미완"))
A12: S08 | B12: 청일 신규점2 | N12: =IF(COUNTIF(C12:L12,"실패")>0,"실패",IF(COUNTIF(C12:L12,"통과")=10,"통과","미완"))
A13: S09 | B13: 어론 신규점 | N13: =IF(COUNTIF(C13:L13,"실패")>0,"실패",IF(COUNTIF(C13:L13,"통과")=10,"통과","미완"))
A14: S10 | B14: 예안 신규점1 | N14: =IF(COUNTIF(C14:L14,"실패")>0,"실패",IF(COUNTIF(C14:L14,"통과")=10,"통과","미완"))
A15: S11 | B15: 소천 신규점4 | N15: =IF(COUNTIF(C15:L15,"실패")>0,"실패",IF(COUNTIF(C15:L15,"통과")=10,"통과","미완"))
A16: S12 | B16: 순창 신규점 | N16: =IF(COUNTIF(C16:L16,"실패")>0,"실패",IF(COUNTIF(C16:L16,"통과")=10,"통과","미완"))
... A54: S50 | B54: 함양 | N54: =IF(COUNTIF(C54:L54,"실패")>0,"실패",IF(COUNTIF(C54:L54,"통과")=10,"통과","미완"))

Sheet ⑪ 지표·판정
A1: 정량 지표 · 시험 탐사 판정
A2: ⚠ 아래 지표의 «임계값은 아직 정해지지 않았다». 파일럿에서 반복일·기기·관측자 분산을 추정하고, 후속 D·I·F 허용오차에서 역산한 오차예산과 결합해 정한 뒤 «50점 판정 전에 동결»한다. 그전에는 이 칸의 수치로 선점을 확정·부적합 처리하지 않는다.
A3: 「예측 |∇ΔT|」와 「현장 국소구배」는 공간 지지범위가 달라 직접 비교 대상이 아니다 — 일치·불일치를 자료 오류나 부적합으로 읽지 말 것. 탐색적 연관성 분석에만 쓴다.
A4: Site ID | B4: 지점명 | C4: 구분 | D4: 현장 국소구배 중앙(nT/m) | E4: 측정범위 max−min(nT) | F4: 반복 재현성 RMS(nT) | G4: 기기 상호대조차(nT) | H4: 세션 정수차(′) | I4: 시간변화 분리 여부 | J4: 예측 |∇ΔT|(참고) | K4: 게이트 종합 | L4: 시험 탐사 판정 | M4: 판정 근거·특이사항
A5: S01 | B5: 태백 신규점 | C5: A | J5: 15.6 | K5: ='⑩ 게이트 점검'!N5
A6: S02 | B6: 임계 신규점1 | C6: A | J6: 24.3 | K6: ='⑩ 게이트 점검'!N6
A7: S03 | B7: 예산 신규점2 | C7: A | J7: 9.3 | K7: ='⑩ 게이트 점검'!N7
A8: S04 | B8: 진안 신규점1 | C8: A | J8: 20.1 | K8: ='⑩ 게이트 점검'!N8
A9: S05 | B9: 무풍 신규점1 | C9: A | J9: 26.6 | K9: ='⑩ 게이트 점검'!N9
A10: S06 | B10: 길담 신규점 | C10: B | J10: 8.4 | K10: ='⑩ 게이트 점검'!N10
A11: S07 | B11: 남해 신규점1 | C11: B | J11: 5.4 | K11: ='⑩ 게이트 점검'!N11
A12: S08 | B12: 청일 신규점2 | C12: B | J12: 7.6 | K12: ='⑩ 게이트 점검'!N12
A13: S09 | B13: 어론 신규점 | C13: B | J13: 4.7 | K13: ='⑩ 게이트 점검'!N13
A14: S10 | B14: 예안 신규점1 | C14: B | J14: 7.5 | K14: ='⑩ 게이트 점검'!N14
A15: S11 | B15: 소천 신규점4 | C15: B | J15: 34.9 | K15: ='⑩ 게이트 점검'!N15
A16: S12 | B16: 순창 신규점 | C16: B | J16: 23.1 | K16: ='⑩ 게이트 점검'!N16
... A22: S18 | B22: 통영 신규점 | C22: B | J22: 140.1 | K22: ='⑩ 게이트 점검'!N22
A23: S19 | B23: 오호 신규점 | C23: B | J23: NOT AVAILABLE | K23: ='⑩ 게이트 점검'!N23
A24: S20 | B24: 보령 신규점2 | C24: B | J24: 4.4 | K24: ='⑩ 게이트 점검'!N24
A25: S21 | B25: 담양 신규점2 | C25: B | J25: 35.3 | K25: ='⑩ 게이트 점검'!N25
A26: S22 | B26: 완도 신규점 | C26: B | J26: 48.2 | K26: ='⑩ 게이트 점검'!N26
A27: S23 | B27: 덕산 신규점1 | C27: B | J27: 9.9 | K27: ='⑩ 게이트 점검'!N27
A28: S24 | B28: 회천 신규점2 | C28: B | J28: 10.1 | K28: ='⑩ 게이트 점검'!N28
A29: S25 | B29: 관리 신규점3 | C29: B | J29: 54.9 | K29: ='⑩ 게이트 점검'!N29
A30: S26 | B30: 고남 신규점2 | C30: B | J30: 2.9 | K30: ='⑩ 게이트 점검'!N30
A31: S27 | B31: 전의 신규점 | C31: B | J31: 2.9 | K31: ='⑩ 게이트 점검'!N31
A32: S28 | B32: 이원 신규점 | C32: B | J32: 12 | K32: ='⑩ 게이트 점검'!N32
A33: S29 | B33: 가야 신규점1 | C33: B | J33: 26.8 | K33: ='⑩ 게이트 점검'!N33
A34: S30 | B34: 창녕 신규점 | C34: B | J34: 22.7 | K34: ='⑩ 게이트 점검'!N34
A35: S31 | B35: 언양 신규점3 | C35: B | J35: 24.2 | K35: ='⑩ 게이트 점검'!N35
A36: S32 | B36: 함양 신규점 | C36: B | J36: 16.5 | K36: ='⑩ 게이트 점검'!N36
A37: S33 | B37: 문산 신규점 | C37: B | J37: NOT AVAILABLE | K37: ='⑩ 게이트 점검'!N37
A38: S34 | B38: 부안 신규점 | C38: B | J38: 17 | K38: ='⑩ 게이트 점검'!N38
A39: S35 | B39: 상주 | C39: 기존점 | J39: 43.6 | K39: ='⑩ 게이트 점검'!N39
A40: S36 | B40: 미원 | C40: 기존점 | J40: 5.4 | K40: ='⑩ 게이트 점검'!N40
A41: S37 | B41: 부안 | C41: 기존점 | J41: 23.8 | K41: ='⑩ 게이트 점검'!N41
A42: S38 | B42: 강화 | C42: 기존점 | J42: NOT AVAILABLE | K42: ='⑩ 게이트 점검'!N42
A43: S39 | B43: 언양 | C43: 기존점 | J43: 38.3 | K43: ='⑩ 게이트 점검'!N43
A44: S40 | B44: 남지 | C44: 기존점 | J44: 9.4 | K44: ='⑩ 게이트 점검'!N44
A45: S41 | B45: 거제 | C45: 기존점 | J45: 28.9 | K45: ='⑩ 게이트 점검'!N45
...

Sheet ⑫ 확인 필요
A1: Human 확인 필요 — 이 야장이 답하지 않는 것
A2: Codex 독립 검토(2026-09-07)가 「기관 확인 없이는 확정할 수 없다」고 지목한 항목이다. 야장 설계로는 해소되지 않으므로 착수 전에 결정해야 한다.
A3: # | B3: 항목 | C3: 왜 확인해야 하는가 | D3: 결정 주체 | E3: 상태
A4: 1 | B4: §19·§20 의 «세션» 및 20분 요건 공식 적용단위 | C4: 1일 6회의 «회»가 무엇인지, 20분이 어느 구간인지에 따라 야장 관측행 설계와 적합 판정이 달라진다. 법적·제도적 해석 사항. | D4: 국토지리정보원
A5: 2 | B5: 기존 16점의 표석·표지 동일성과 공식 좌표 | C5: 과거 성과와 신규 관측을 견주려면 같은 물리점임이 확인돼야 한다. 미원은 좌표가 353 m 어긋나 HOLD 로 두었다. | D5: 국토지리정보원
A6: 3 | B6: 현지 기준자력계 투입 여부 | C6: 이것 없이는 일변화와 공간변화를 분리할 수 없어 시험 결과를 선점 확정 근거로 쓸 수 없다. 추가 기기·인력·관측시간이 든다. | D6: 발주기관 · 예산
A7: 4 | B7: 정량 임계값과 허용 오판위험 승인 | C7: 임계를 어디에 두느냐가 «부적합지를 통과시키는 위험»과 «양호지를 탈락시키는 위험» 의 교환이다. 가치판단이 필요하다. | D7: 발주기관
A8: 5 | B8: §13② 시설 분류와 거리 산정 방법 | C8: 시설 유형 분류가 애매하면 법정 이격 판정이 갈린다. 대외 법정 적합성에 직결. | D8: 국토지리정보원
A9: 6 | B9: 상시관측소 원자료의 제공조건·시간해상도 | C9: 자료가 «존재한다»와 «쓸 수 있다»는 다르다. §21 대조의 실현 가능성이 여기 달렸다. | D9: 청양(INTERMAGNET) · KASA
