Workbook

Sheet ① 기입규약
A1: 지자기 시험 탐사 표준 야장 (자기교란 확인표) — 기입규약
A2: 측정 설계·판정기준은 「20260825_중간보고회_초안_v3_수정.pptx」에 확정된 것을 그대로 쓴다. 현행 규정과의 관계: 현행 규정(§13 도상선점 · §14 선점실시 · §15 위치도 및 조서 작성)은 주변 자기장 측정의 «필요성»은 규정하나 측정방향·간격·반복횟수·판정방법이 없다. IAGA 절차를 참고해 구체화하는 것이 이 야장의 목적이다.
A3: ⚠ 야장에 칸이 없으면 그 값은 어떤 분석으로도 복원되지 않는다. 과거 야장 68개에 F 측정일시가 0건이어서 세션 외부장 보정이 원리적으로 막힌 전례가 이 설계의 근거다.
A5: 기록양식 3종 중 이 야장의 자리 (원 자료 23면)
A6: 1. 도상선점 | B6: 위치·접근성·기존점·자기교란시설 사전검토 → 「도상선점표」 · 완료(103점)
A7: 2. 현황조사 | B7: 현장사진·접근성·시설물·상공장애·방위표지 확인 → 「지자기점 현황조사표」 · 완료(34점 도출)
A8: 3. 자기환경 측정·평가 | B8: 중심점 반복관측·교차 프로파일·수평·수직 자기구배 → 「자기교란 확인표」 · ← 이 야장
A10: 측정 설계 — Guide for Magnetic Repeat Station Surveys §4.2 (IAGA, 1996)
A11: 장비 기준 | B11: PPM(GSM-19T) **1대**. 자력계가 하나뿐이라 위치와 시각이 함께 움직인다 — 그래서 중심점 전·후 반복관측이 필수다.
A12: 수평 | B12: P0 → 방향별 측정 → P0 재측정. 한 방향 0.5, 1, 2, 3, 4, 5, 6, 7, 8, 9, 10 m → 동·서·남·북 네 방향 반복.
A13: 수직 | B13: 중심점(P0)에서 지상 20~200 cm 를 20 cm 간격으로 순차 측정.
A14: 시간변화 보정 | B14: P0추정(t) = F0 + (F1−F0)·(t−t0)/(t1−t0) · ΔF = F측정 − P0추정 · 변화율 = ΔF ÷ 거리. 중심점 자기장이 측정시간 동안 «선형적으로» 변한다고 가정한 근사 보정이다. 가정이 깨지는 교란시에는 성립하지 않는다.
A15: 원 계획 예시 | B15: P0 100 nT(10:00) → 동쪽 **거리 2 m** 지점 106 nT(10:02) → P0 105 nT(10:04) ⇒ P0추정 102.5 · ΔF 3.5 · 변화율 **1.75 nT/m**. 보정하지 않으면 3.0 nT/m 로 71 % 과대평가된다.
A16: ⚠ Set 검증 | B16: 유효한 P0(전)·P0(후)가 «각각 정확히 1개»이고 측정시각이 그 사이일 때만 계산한다. 아니면 수치 대신 오류 사유가 뜬다 — 다른 방향의 P0 를 물거나 중복 P0 를 합산하는 사고를 구조적으로 막는다.
A18: 판정기준 — 국제 권고이며 **국내 기준은 확정되지 않았다**
A19: 총자기장 변화 | B19: IAGA 「Guide for Magnetic Repeat Station Surveys」 §4.2 — 반경 10 m 내 총자기장 변화가 약 50 nT 를 초과하면 다른 후보지 검토
A20: 자기구배 | B20: 유럽 「Recommendations for European Magnetic Repeat Station Surveys」 p.3 — 자기구배 3 nT/m 미만, PPM 교차 프로파일 확인 및 수직 자기구배 점검
A21: ⚠ 공간 범위 | B21: 4방향 측선은 원 내부의 «일부 선»만 잰다. 측선 사이와 대각선은 관측하지 않으므로 「반경 10 m 전체가 50 nT 이내」라고 말할 수 없다. 「반경 10 m 내 4개 방위 측선의 관측점에서 확인된 변화」로 적는다.
A22: ⚠ 연산 미확정 | B22: 50 nT 를 max|F−P0| 로 볼지 관측값 max−min 으로 볼지, 지점 대표 구배를 최대·중앙·특정 거리 중 무엇으로 할지 «정해지지 않았다». 야장은 셋 다 산출해 두고 확정은 국내 적용방안에 맡긴다.
A23: ⚠ 현실성 | B23: 시범관측 두 곳이 이미 네 방향 모두 3 nT/m 를 넘었다(이원 여의저수지 최대 250.7 · 다른 기존점 최대 38.5, 1 m 기준). 두 지점만으로는 「임계가 비현실적」·「1 m 가 전제와 다름」·「그 점이 실제 부적합」 셋을 구분할 수 없다 — 자동 탈락시키지 말 것.
A24: 산출물 | B24: 합격/불합격만이 아니다. 함양 임도처럼 **중심점을 가장 균질한 지점으로 조정**하는 것이 목적의 하나다(⑩). 옮겼으면 새 중심에서 재측정할지를 명시해야 한다 — 옛 중심 자료가 새 중심을 입증하지는 않는다.
A26: 단위 — 논쟁 없이 고정한다
A27: 각도(현장 원시) | B27: 곤 gon (1회전 400 · 대척 200 gon). 도(°) 환산은 읽기전용 계산 칸.
A28: 총자력 F | B28: nT, 소수 1자리 (§17 0.1 nT 판독)
A29: 좌표 | B29: 십진도. 위도·경도를 각각 다른 열에 숫자로 + 좌표계·취득방법·정확도
A30: 거리·높이 | B30: 수평 거리 m, 수직 높이 cm. **명목값과 실측값을 따로** 적는다
A31: 부호 | B31: ΔF·변화율은 **부호를 보존**한다. 절댓값은 별도 열이다
A33: 시각
A34: 기입 | B34: 날짜 + 시:분:초 (예 2026-10-14 13:24:05). 분까지만 적으면 선형보간이 깨진다.
A35: 시간대 | B35: 야장은 KST. CYG·Kp 는 UT, KASA 캐시는 KST. UTC 환산은 계산 칸이 만든다.
A37: 방위각 — 정·역 혼동이 29쌍 있었다
A38: 규약 | B38: 진북 기준 · 북 = 0° · 시계방향 · **FROM = 기준점, TO = 방위표지**
A39: 참방위각 | B39: 결정방법·근거좌표·정확도와 **이전 확정값 대비 차이·재결정 사유** — 재방문 잔여 RMS 33.7′ 의 원인이 이것이다.
A41: 관측 조건 (원 자료 31면)
A42: 1 | B42: [절대관측 단계] 자기장 일변화가 안정적인 야간 시간대에 절대관측 수행
A43: 2 | B43: 우주기상 예보와 Kp 지수를 확인하여 관측일정 편성
A44: 3 | B44: 현장측량 기간 동안 이동식 Variometer 연속관측
A45: 4 | B45: 자기교란 발생 시 해당 관측구간 제외 또는 재관측
A46: 5 | B46: 타 기관 상시관측자료와 교차검증
A47: 6 | B47: [시험 탐사] 야간 의무는 없으나 «시간변화가 안정된 구간»을 골라 측정한다
...

Sheet ② 대상 50점
A1: 시험 탐사 대상 50점 — 등급 A 5 · B 도엽대표 29 · 기존점 16
A2: 선점 검토 결과 그대로다(export_selection_50 단일 출처). Site ID 는 이 야장 전체의 연결키이며 다른 시트가 그대로 쓴다.
A3: ⚠ 「예측 |∇ΔT|」는 KIGAM 1.5분(약 2.8 km) 격자값으로 현장 수 m 스케일과 «물리적으로 다른 양»이다 — 합격기준으로 쓰지 않는다. 자료공백 5점(오호·문산·강화·포천·화천)은 NOT AVAILABLE 로 두고 감점·보간 금지.
A4: Site ID | B4: 연번 | C4: 구분 | D4: 원 번호 | E4: 지점명 | F4: 관할본부 | G4: 도엽번호 | H4: 도엽명 | I4: 위도(십진) | J4: 경도(십진) | K4: 표고(m) | L4: 소재지 | M4: 예측 |∇ΔT| (nT/km) ※판정 미사용 | N4: 예측 상태 | O4: 최근접 관측소 | P4: 관측소 거리(km) | Q4: 표지1 방위각 (기재값) | R4: 표지1 거리(m) | S4: 원 계획 유의사항 | T4: HOLD 범위
A5: S01 | B5: 1 | C5: A | D5: DS-008 | E5: 태백 신규점 | F5: 대구경북 본부 | G5: NJ52-8-28 | H5: 태백 | I5: 37.020705 | J5: 128.98393 | K5: 872 | L5: 경북 봉화군 소천면 고선리 산 1 | M5: 15.6 | N5: OK | O5: 강릉 | P5: 83 | Q5: 178° 31' 53″ | R5: 69 | T5: 없음 — 전 항목 진행
A6: S02 | B6: 2 | C6: A | D6: DS-015 | E6: 임계 신규점1 | F6: 강원 본부 | G6: NJ52-8-20 | H6: 임계 | I6: 37.359346 | J6: 128.97386 | K6: 844 | L6: 강원특별자치도 삼척시 하장면 숙암리 산 11-1 | M6: 24.3 | N6: OK | O6: 강릉 | P6: 46 | Q6: 177°43′54″ | R6: 79 | T6: 없음 — 전 항목 진행
A7: S03 | B7: 3 | C7: A | D7: DS-076 | E7: 예산 신규점2 | F7: 대전세종충남 본부 | G7: NJ52-10-12 | H7: 예산 | I7: 36.534085 | J7: 126.93627 | K7: 116 | L7: 충남 공주시 신풍면 산정리 산 3 | M7: 9.3 | N7: OK | O7: 청양 | P7: 20 | Q7: 273°56′32″ | R7: 134 | T7: 없음 — 전 항목 진행
A8: S04 | B8: 4 | C8: A | D8: DS-081 | E8: 진안 신규점1 | F8: 전북 본부 | G8: NI52-1-06 | H8: 진안 | I8: 35.891309 | J8: 127.30902 | K8: 297 | L8: 전북특별자치도 완주군 동상면 사봉리 산 107-2 | M8: 20.1 | N8: OK | O8: 청양 | P8: 67 | Q8: 328° 19' 19.77 | R8: 101 | T8: 없음 — 전 항목 진행
A9: S05 | B9: 5 | C9: A | D9: DS-083 | E9: 무풍 신규점1 | F9: 전북 본부 | G9: NI52-1-08 | H9: 무풍 | I9: 35.945212 | J9: 127.80085 | K9: 584 | L9: 전북특별자치도 무주군 설천면 두길리 165 | M9: 26.6 | N9: OK | O9: 청양 | P9: 98 | Q9: 246° 16′ 35.46 | R9: 67 | T9: 없음 — 전 항목 진행
A10: S06 | B10: 6 | C10: B | D10: DS-003 | E10: 길담 신규점 | F10: 전북 본부 | G10: NI52-1-13 | H10: 갈담 | I10: 35.604653 | J10: 127.23024 | K10: 281 | L10: 전북특별자치도 임실군 임실읍 신안리 산 87-1 | M10: 8.4 | N10: OK | O10: 청양 | P10: 91 | Q10: 351˚ 50´ 02˝ | R10: 64 | T10: 없음 — 전 항목 진행
A11: S07 | B11: 7 | C11: B | D11: DS-004 | E11: 남해 신규점1 | F11: 경남 본부 | G11: NI52-4-08 | H11: 남해 | I11: 34.852281 | J11: 127.98147 | K11: 262 | L11: 경남 남해군 창선면 지족리 산 115 | M11: 5.4 | N11: OK | O11: 청양 | P11: 197 | Q11: 114°34′47″ | R11: 70 | T11: 없음 — 전 항목 진행
A12: S08 | B12: 8 | C12: B | D12: DS-013 | E12: 청일 신규점2 | F12: 강원 본부 | G12: NJ52-8-09 | H12: 청일 | I12: 37.618578 | J12: 128.1698 | K12: 372 | L12: 강원특별자치도 횡성군 청일면 춘당리 산 1 | M12: 7.6 | N12: OK | O12: 강릉 | P12: 64 | Q12: 162° 55′ 36.41″ | R12: 63 | T12: 없음 — 전 항목 진행
A13: S09 | B13: 9 | C13: B | D13: DS-014 | E13: 어론 신규점 | F13: 강원 본부 | G13: NJ52-8-01 | H13: 어론 | I13: 37.776326 | J13: 128.07586 | K13: 532 | L13: 강원특별자치도 홍천군 내촌면 화상대리 산 108-2 | M13: 4.7 | N13: OK | O13: 강릉 | P13: 70 | Q13: 278°9′11″ | R13: 37 | T13: 없음 — 전 항목 진행
A14: S10 | B14: 10 | C14: B | D14: DS-020 | E14: 예안 신규점1 | F14: 대구경북 본부 | G14: NJ52-11-12 | H14: 예안 | I14: 36.745399 | J14: 128.85356 | K14: 293 | L14: 경북 안동시 도산면 토계리 350 | M14: 7.5 | N14: OK | O14: 강릉 | P14: 113 | Q14: 45°25′27 | R14: 28 | T14: 없음 — 전 항목 진행
A15: S11 | B15: 11 | C15: B | D15: DS-025 | E15: 소천 신규점4 | F15: 대구경북 본부 | G15: NJ52-11-05 | H15: 소천 | I15: 36.765848 | J15: 129.15434 | K15: 380 | L15: 경북 영양군 일월면 문암리 산 59-2 | M15: 34.9 | N15: OK | O15: 강릉 | P15: 114 | Q15: 251°54'10" | R15: 38 | T15: 없음 — 전 항목 진행
A16: S12 | B16: 12 | C16: B | D16: DS-030 | E16: 순창 신규점 | F16: 광주전남 본부 | G16: NI52-1-21 | H16: 순창 | I16: 35.284821 | J16: 127.09215 | K16: 219 | L16: 전남광주통합특별시 곡성군 오산면 운곡리 산 73-1 | M16: 23.1 | N16: OK | O16: 청양 | P16: 122 | Q16: 206°53′16″ | R16: 57 | T16: 없음 — 전 항목 진행
... A22: S18 | B22: 18 | C22: B | D22: DS-045 | E22: 통영 신규점 | F22: 경남 본부 | G22: NI52-5-02 | H22: 통영 | I22: 34.792976 | J22: 128.39383 | K22: 79 | L22: 경남 통영시 산양읍 연화리 584 | M22: 140.1 | N22: OK | O22: 청양 | P22: 223 | Q22: 304°50'44" | R22: 26 | T22: 없음 — 전 항목 진행
A23: S19 | B23: 19 | C23: B | D23: DS-046 | E23: 오호 신규점 | F23: 강원 본부 | G23: NJ52-5-19 | H23: 오호 | I23: 38.318869 | J23: 128.52176 | K23: 21 | L23: 강원특별자치도 고성군 죽왕면 삼포리 산 5 | N23: NOT AVAILABLE | O23: 강릉 | P23: 68 | Q23: 252°09′33.58" | R23: 36 | T23: 없음 — 전 항목 진행
A24: S20 | B24: 20 | C24: B | D24: DS-049 | E24: 보령 신규점2 | F24: 대전세종충남 본부 | G24: NJ52-10-19 | H24: 보령 | I24: 36.266844 | J24: 126.70696 | K24: 277 | L24: 충남 부여군 외산면 가덕리 산 11-1 | M24: 4.4 | N24: OK | O24: 청양 | P24: 17 | Q24: 5° 15' 3.36 | R24: 75 | T24: 없음 — 전 항목 진행
A25: S21 | B25: 21 | C25: B | D25: DS-051 | E25: 담양 신규점2 | F25: 전북 본부 | G25: NI52-1-20 | H25: 담양 | I25: 35.456101 | J25: 126.96205 | K25: 350 | L25: 전북특별자치도 순창군 복흥면 하리 산 27 | M25: 35.3 | N25: OK | O25: 청양 | P25: 102 | Q25: 227˚ 00´ 55˝ | R25: 44 | T25: 없음 — 전 항목 진행
A26: S22 | B26: 22 | C26: B | D26: DS-055 | E26: 완도 신규점 | F26: 광주전남 본부 | G26: NI52-4-19 | H26: 완도 | I26: 34.328826 | J26: 126.54322 | K26: 131 | L26: 전남광주통합특별시 해남군 송지면 송호리 산 178-3 | M26: 48.2 | N26: OK | O26: 제주 | P26: 102 | Q26: 122º 46' 29 | R26: 38 | T26: 없음 — 전 항목 진행
A27: S23 | B27: 23 | C27: B | D27: DS-057 | E27: 덕산 신규점1 | F27: 충북 본부 | G27: NJ52-11-01 | H27: 덕산 | I27: 36.888529 | J27: 128.19274 | K27: 388 | L27: 충북 제천시 덕산면 선고리 산 28-8 | M27: 9.9 | N27: OK | O27: 이천 | P27: 65 | Q27: 52˚41'47" | R27: 29 | T27: 없음 — 전 항목 진행
A28: S24 | B28: 24 | C28: B | D28: DS-060 | E28: 회천 신규점2 | F28: 광주전남 본부 | G28: NI52-4-13 | H28: 회천 | I28: 34.680805 | J28: 127.04766 | K28: 99 | L28: 전남광주통합특별시 보성군 회천면 회령리 산 155 | M28: 10.1 | N28: OK | O28: 제주 | P28: 155 | Q28: 326° 39' 52 | R28: 27 | T28: 없음 — 전 항목 진행
A29: S25 | B29: 25 | C29: B | D29: DS-068 | E29: 관리 신규점3 | F29: 대구경북 본부 | G29: NJ52-10-24 | H29: 관기 | I29: 36.325755 | J29: 127.90598 | K29: 383 | L29: 경북 상주시 모서면 득수리 산 146 | M29: 54.9 | N29: OK | O29: 청양 | P29: 95 | Q29: 141° 02’ 02 | R29: 60 | T29: 없음 — 전 항목 진행
A30: S26 | B30: 26 | C30: B | D30: DS-075 | E30: 고남 신규점2 | F30: 대전세종충남 본부 | G30: NJ52-10-18 | H30: 고남 | I30: 36.452304 | J30: 126.3958 | K30: 38 | L30: 충남 태안군 고남면 누동리 산 6-514 | M30: 2.9 | N30: OK | O30: 청양 | P30: 42 | Q30: 29° 8' 15.13 | R30: 70 | T30: 없음 — 전 항목 진행
A31: S27 | B31: 27 | C31: B | D31: DS-078 | E31: 전의 신규점 | F31: 대전세종충남 본부 | G31: NJ52-10-13 | H31: 전의 | I31: 36.579379 | J31: 127.0687 | K31: 372 | L31: 충남 공주시 사곡면 월가리 산 10-1 | M31: 2.9 | N31: OK | O31: 청양 | P31: 30 | Q31: 307°8′47″ | R31: 54 | T31: 없음 — 전 항목 진행
A32: S28 | B32: 28 | C32: B | D32: DS-080 | E32: 이원 신규점 | F32: 대전세종충남 본부 | G32: NJ52-10-31 | H32: 이원 | I32: 36.16662 | J32: 127.58312 | K32: 300 | L32: 충남 금산군 제원면 신안리 산 4-1 | M32: 12 | N32: OK | O32: 청양 | P32: 70 | Q32: 157°40′41″ | R32: 42 | T32: 없음 — 전 항목 진행
A33: S29 | B33: 29 | C33: B | D33: DS-084 | E33: 가야 신규점1 | F33: 경남 본부 | G33: NI52-2-01 | H33: 가야 | I33: 35.777986 | J33: 128.03683 | K33: 825 | L33: 경남 거창군 가북면 우혜리 산 3 | M33: 26.8 | N33: OK | O33: 청양 | P33: 125 | Q33: 115° 14' 22" | R33: 21 | T33: 없음 — 전 항목 진행
A34: S30 | B34: 30 | C34: B | D34: DS-086 | E34: 창녕 신규점 | F34: 대구경북 본부 | G34: NI52-2-10 | H34: 창녕 | I34: 35.662586 | J34: 128.2981 | K34: 179 | L34: 경북 고령군 쌍림면 평지리 산 63 | M34: 22.7 | N34: OK | O34: 청양 | P34: 152 | Q34: 297° 30' 11 | R34: 23 | T34: 없음 — 전 항목 진행
A35: S31 | B35: 31 | C35: B | D35: DS-089 | E35: 언양 신규점3 | F35: 대구경북 본부 | G35: NI52-2-13 | H35: 언양 | I35: 35.742364 | J35: 129.02982 | K35: 234 | L35: 경북 경주시 산내면 외칠리 산 183 | M35: 24.2 | N35: OK | O35: 이천 | P35: 205 | Q35: 352°5′13″ | R35: 33 | T35: 없음 — 전 항목 진행
A36: S32 | B36: 32 | C36: B | D36: DS-096 | E36: 함양 신규점 | F36: 전북 본부 | G36: NI52-1-15 | H36: 함양 | I36: 35.586243 | J36: 127.57466 | K36: 478 | L36: 전북특별자치도 장수군 번암면 지지리 산 55 | M36: 16.5 | N36: OK | O36: 청양 | P36: 108 | Q36: 132º 38' 54 | R36: 34 | T36: 없음 — 전 항목 진행
A37: S33 | B37: 33 | C37: B | D37: DS-098 | E37: 문산 신규점 | F37: 서울경기북부 본부 | G37: NJ52-7-04 | H37: 문산 | I37: 37.927676 | J37: 126.87031 | K37: 83 | L37: 경기 파주시 파평면 덕천리 산 40-3 | N37: NOT AVAILABLE | O37: 이천 | P37: 105 | Q37: 333° 29 '40.75 | R37: 94 | T37: 없음 — 전 항목 진행
A38: S34 | B38: 34 | C38: B | D38: DS-102 | E38: 부안 신규점 | F38: 전북 본부 | G38: NI52-1-11 | H38: 부안 | I38: 35.541753 | J38: 126.64558 | K38: 112 | L38: 전북특별자치도 고창군 부안면 수앙리 산 79-8 | M38: 17 | N38: OK | O38: 청양 | P38: 93 | Q38: 115° 56' 52 | R38: 73 | T38: 없음 — 전 항목 진행
A39: S35 | B39: 35 | C39: 기존점 | D39: 1-12-2 | E39: 상주 | G39: NJ52-14-16 | H39: 상주 | I39: 36.355288 | J39: 128.11048 | K39: 92.568 | L39: 경상북도 상주시 청리면 율리 436-2 밤깟마을(상주23) | M39: 43.6 | N39: OK | O39: 이천 | P39: 101 | Q39: NOT APPLICABLE | T39: 없음 — 전 항목 진행
A40: S36 | B40: 36 | C40: 기존점 | D40: 1-13-2 | E40: 미원 | G40: NJ52-13-14 | H40: 미원 | I40: 36.725028 | J40: 127.58622 | K40: 97.952 | L40: 충청북도 청주시 청원구 북이면 영하리 산13-1(미원409) | M40: 5.4 | N40: OK | O40: 이천 | P40: 46 | Q40: NOT APPLICABLE | T40: 과거대조 보류 — '10~'19 성과표와 2019 야장 좌표가 353 m 어긋난다. 현 표석에서의 신규 측정은 별도 Location ID 로 진행하되, 과거 성과와의 대조는 표석 동일성 확인 전까지 보류.
A41: S37 | B41: 37 | C41: 기존점 | D41: 1-17-2 | E41: 부안 | G41: NJ52-01-10 | H41: 부안 | I41: 35.58775 | J41: 126.71614 | K41: 33.5 | L41: 전라북도 부안군 줄포면 난산리 440-2 목중새마을(부안423) | M41: 23.8 | N41: OK | O41: 청양 | P41: 87 | Q41: NOT APPLICABLE | S41: 주변 태양광 위치 | T41: 없음 — 전 항목 진행
A42: S38 | B42: 38 | C42: 기존점 | D42: 1-2-3 | E42: 강화 | G42: NJ52-09-09 | H42: 강화 | I42: 37.666124 | J42: 126.47878 | K42: 100.524 | L42: 인천광역시 강화군 길상면 길직리 산 148-6 | N42: NOT AVAILABLE | O42: 이천 | P42: 110 | Q42: NOT APPLICABLE | T42: 없음 — 전 항목 진행
A43: S39 | B43: 39 | C43: 기존점 | D43: 1-23-1 | E43: 언양 | G43: NI52-2-13 | H43: 언양 | I43: 35.6762 | J43: 129.19087 | K43: 226.101 | L43: 울산광역시 울주군 두서면 미호리 산3(삼언양417) | M43: 38.3 | N43: OK | O43: 이천 | P43: 220 | Q43: NOT APPLICABLE | S43: 도로 접근성 나쁨 | T43: 없음 — 전 항목 진행
A44: S40 | B44: 40 | C44: 기존점 | D44: 1-24-3 | E44: 남지 | G44: NJ52-01-14 | H44: 남지 | I44: 35.436167 | J44: 128.47378 | L44: 창녕군 장마면 유리 1705-1 봉산지뚝 | M44: 9.4 | N44: OK | O44: 청양 | P44: 179 | Q44: NOT APPLICABLE | T44: 없음 — 전 항목 진행
A45: S41 | B45: 41 | C45: 기존점 | D45: 1-25-2 | E45: 거제 | G45: NJ52-06-07 | H45: 거제 | I45: 34.870311 | J45: 128.59286 | K45: 91.014 | L45: 경상남도 거제시 거제면 옥산리 산83-6 | M45: 28.9 | N45: OK | O45: 청양 | P45: 229 | Q45: NOT APPLICABLE | T45: 없음 — 전 항목 진행
...

Sheet ③ 점정보·좌표
A1: 점 정보 · 좌표 검증
A2: 좌표는 «십진도 숫자»로 위도·경도를 각각 적고 좌표계·취득방법·정확도·출처를 함께 남긴다. 자릿수만 맞추면 허위 정밀도가 생기고 위·경도 뒤바뀜도 못 막는다. 선점 절차: GNSS 수신기 — 좌표·방위각 확인 → 오버하우저 — 자기구배 확인 → 중심점 선정 및 표지 설치
A4: Site ID | B4: 지점명 | C4: 구분 | D4: 사전 위도 | E4: 사전 경도 | F4: 현장 실측 위도 | G4: 현장 실측 경도 | H4: 좌표계 | I4: 측지기준 | J4: 취득방법 | K4: 수평정확도(m) | L4: 좌표 출처 | M4: 좌표 검증상태
A5: S01 | B5: 태백 신규점 | C5: A | D5: 37.020705 | E5: 128.98393
A6: S02 | B6: 임계 신규점1 | C6: A | D6: 37.359346 | E6: 128.97386
A7: S03 | B7: 예산 신규점2 | C7: A | D7: 36.534085 | E7: 126.93627
A8: S04 | B8: 진안 신규점1 | C8: A | D8: 35.891309 | E8: 127.30902
A9: S05 | B9: 무풍 신규점1 | C9: A | D9: 35.945212 | E9: 127.80085
A10: S06 | B10: 길담 신규점 | C10: B | D10: 35.604653 | E10: 127.23024
A11: S07 | B11: 남해 신규점1 | C11: B | D11: 34.852281 | E11: 127.98147
A12: S08 | B12: 청일 신규점2 | C12: B | D12: 37.618578 | E12: 128.1698
A13: S09 | B13: 어론 신규점 | C13: B | D13: 37.776326 | E13: 128.07586
A14: S10 | B14: 예안 신규점1 | C14: B | D14: 36.745399 | E14: 128.85356
A15: S11 | B15: 소천 신규점4 | C15: B | D15: 36.765848 | E15: 129.15434
A16: S12 | B16: 순창 신규점 | C16: B | D16: 35.284821 | E16: 127.09215
... A54: S50 | B54: 함양 | C54: 기존점 | D54: 35.542509 | E54: 127.62297

Sheet ④ §13② 이격거리
A1: §13② 이격거리 — 시설 유형마다 한 행
A2: 법정 기준: 직류철도 5.0 km · 교류·일반철도 2.0 km · 고압철탑 1.0 km · 송전탑 0.5 km
A3: ⚠ 도상 확인만으로 확정하지 않는다. 시설 분류·자료 기준일·거리 산정점·최근 설치 여부에 따라 결과가 달라지므로 시설 ID·출처·좌표·현장 확인값·확인방법·사진·확인자를 각각 남긴다. 분류가 불명확하면 임의 판정하지 말고 PENDING.
A4: Site ID | B4: 지점명 | C4: 시설 유형 | D4: 기준(km) | E4: 최근접 시설 ID | F4: 시설 명칭 | G4: 자료 출처 | H4: 자료 기준일 | I4: 시설 위도 | J4: 시설 경도 | K4: 도상거리(km) | L4: 현장 확인거리(km) | M4: 확인 방법 | N4: 사진 파일명 | O4: 판정 | P4: 확인자 | Q4: 비고
A5: S01 | B5: 태백 신규점 | C5: 직류철도 | D5: 5
A6: S01 | B6: 태백 신규점 | C6: 교류·일반철도 | D6: 2
A7: S01 | B7: 태백 신규점 | C7: 고압철탑 | D7: 1
A8: S01 | B8: 태백 신규점 | C8: 송전탑 | D8: 0.5
A9: S02 | B9: 임계 신규점1 | C9: 직류철도 | D9: 5
A10: S02 | B10: 임계 신규점1 | C10: 교류·일반철도 | D10: 2
A11: S02 | B11: 임계 신규점1 | C11: 고압철탑 | D11: 1
A12: S02 | B12: 임계 신규점1 | C12: 송전탑 | D12: 0.5
A13: S03 | B13: 예산 신규점2 | C13: 직류철도 | D13: 5
A14: S03 | B14: 예산 신규점2 | C14: 교류·일반철도 | D14: 2
A15: S03 | B15: 예산 신규점2 | C15: 고압철탑 | D15: 1
A16: S03 | B16: 예산 신규점2 | C16: 송전탑 | D16: 0.5
... A204: S50 | B204: 함양 | C204: 송전탑 | D204: 0.5

Sheet ⑤ 기존점 대조가능성
A1: 기존 관측점 16점 — 과거 성과와의 «성분별» 대조 가능성
A2: ⚠ 「기존 성과가 있다」와 「직접 비교할 수 있다」는 다른 문제다. 과거 기록에는 마크 방위각 변동(재방문 잔여 RMS 33.7′)·F 측정시각 전무·방위 방향 혼동이 섞여 있다. 편각 D 와 시간보정이 필요한 F 는 무조건 직접 비교할 수 없다.
A3: HOLD 는 범위를 나눈다 — 「현 물리점 식별」이 안 되면 전부 보류지만, 현 표석이 확실하고 과거 좌표와의 연결만 불명확하면 **신규 측정은 별도 Location ID 로 진행**하고 과거 대조만 보류한다.
A4: Site ID | B4: 지점명 | C4: 지점코드 | D4: 종전 성과 연도 | E4: 종전 편각(°) | F4: 종전 복각(°) | G4: 종전 총자력(nT) | H4: 종전 관측장비 | I4: 현 물리점 식별 | J4: 공식 좌표 확인 | K4: 과거점 동일성 | L4: 동일 표석 | M4: 동일 표지 | N4: D 대조가능 | O4: I 대조가능 | P4: F 대조가능 | Q4: 근거·비고
A5: S35 | B5: 상주 | C5: 1-12-2 | D5: 2025.09.24. | E5: -8.193992 | F5: 52.758553 | G5: 50560 | H5: MAG-02H
A6: S36 | B6: 미원 | C6: 1-13-2 | D6: 2024.05.01. | E6: -9.122264 | F6: 53.412156 | G6: 50709.3 | H6: MAG-02H | K6: HOLD | L6: HOLD | M6: HOLD | N6: HOLD | O6: HOLD | P6: HOLD | Q6: '10~'19 성과표와 2019 야장 좌표가 353 m 어긋난다. 현 표석에서의 신규 측정은 별도 Location ID 로 진행하되, 과거 성과와의 대조는 표석 동일성 확인 전까지 보류.
A7: S37 | B7: 부안 | C7: 1-17-2 | D7: 2025.11.04. | E7: -8.473328 | F7: 52.376639 | G7: 50678.1 | H7: MAG-02H
A8: S38 | B8: 강화 | C8: 1-2-3 | D8: 2024.04.17 | E8: -8.659731 | F8: 54.765217 | G8: 51531.2 | H8: MAG-02H
A9: S39 | B9: 언양 | C9: 1-23-1 | D9: 2024.10.17 | E9: -9.003039 | F9: 51.749664 | G9: 49597.3 | H9: MAG-01H
A10: S40 | B10: 남지 | C10: 1-24-3 | D10: 2019.06.24 | E10: -7.60285 | F10: 51.288442 | G10: 49481.8 | H10: MAG-01H
A11: S41 | B11: 거제 | C11: 1-25-2 | D11: 2024.10.24. | E11: -8.147075 | F11: 51.198997 | G11: 49335.5 | H11: MAG-02H
A12: S42 | B12: 조도 | C12: 1-29-2 | D12: 2010연구성과 | E12: -6.0461111 | F12: 50.368333 | G12: 49534 | H12: 연구성과보고서
A13: S43 | B13: 포천 | C13: 1-3-3 | D13: 2025.05.27. | E13: -9.245017 | F13: 55.042983 | G13: 51495.3 | H13: MAG-02H
A14: S44 | B14: 성산 | C14: 1-30-2 | D14: 2025.05.15 | E14: -8.658169 | F14: 50.120781 | G14: 48909.9 | H14: MAG-03H
A15: S45 | B15: 여주 | C15: 1-4-4 | D15: 2023.09.07 | E15: -9.2674306 | F15: 54.423825 | G15: 51174.98 | H15: MAG-01H
A16: S46 | B16: 화천 | C16: 1-5-2 | D16: 2018.5.23 | E16: -8.933944 | F16: 54.944778 | G16: 51499.4 | H16: MAG-01H
A17: S47 | B17: 봉평 | C17: 1-7-2 | D17: 2015 | E17: -8.446667 | F17: 54.1425 | G17: 50634 | H17: MAG-04H
A18: S48 | B18: 삼척 | C18: 1-8-4 | D18: 2024.08.29. | E18: -8.223683 | F18: 54.325956 | G18: 50647.4 | H18: MAG-07H
... A20: S50 | B20: 함양 | C20: 1-20-3 | D20: 2025.10.29. | E20: -7.629208 | F20: 52.017197 | G20: 49779.9 | H20: MAG-02H

Sheet ⑥ 방위표지·참방위각
A1: 방위표지 · 참방위각 결정 — 편각 30′ 잔차의 주범
A2: ⚠ 규약: 진북 기준 · 북 = 0° · 시계방향 · FROM = 기준점 · TO = 방위표지. 현장 원시각은 «gon»(1회전 400 · 대척 200). 200 gon 역방향과 180° 역방향이 섞이면 대규모 오류가 난다.
A3: 재방문 16구간 전부에서 마크 참방위각이 60″ 넘게 변했다. 마크를 바꾸는 것 자체는 오류가 아니지만 바뀐 마크의 참방위각이 틀리면 그 방문의 편각이 통째로 틀어진다 — 「이전값 대비 차」와 「재결정 사유」가 필수다.
A4: Site ID | B4: Mark ID | C4: 지점명 | D4: 표지 구분 | E4: 표지 위도 | F4: 표지 경도 | G4: 시준 지점(표지의 어디) | H4: FROM | I4: TO | J4: 정 시준 원시각(gon) | K4: 반 시준 원시각(gon) | L4: 폐합차(gon) 계산 | M4: 참방위각(gon) | N4: 참방위각(°) 계산 | O4: 역방위(°) 계산 | P4: 결정방법 | Q4: 근거좌표 정확도(m) | R4: 이전 확정 방위각(°) | S4: 이전값 대비 차(″) 계산 | T4: 재결정 사유
A5: S01 | B5: S01-M1 | C5: 태백 신규점 | D5: 방위표지1 | E5: 37.020007 | F5: 128.98392 | H5: 기준점 | I5: 방위표지 | L5: =IF(COUNT(J5:K5)=2,ABS(ABS(K5-J5)-200),"") | N5: =IF(ISNUMBER(M5),M5*0.9,"") | O5: =IF(ISNUMBER(M5),MOD(M5*0.9+180,360),"") | S5: =IF(AND(ISNUMBER(M5),ISNUMBER(R5)),(M5*0.9-R5)*3600,"")
A6: S01 | B6: S01-M2 | C6: 태백 신규점 | D6: 방위표지2 | E6: 37.021716 | F6: 128.98347 | H6: 기준점 | I6: 방위표지 | L6: =IF(COUNT(J6:K6)=2,ABS(ABS(K6-J6)-200),"") | N6: =IF(ISNUMBER(M6),M6*0.9,"") | O6: =IF(ISNUMBER(M6),MOD(M6*0.9+180,360),"") | S6: =IF(AND(ISNUMBER(M6),ISNUMBER(R6)),(M6*0.9-R6)*3600,"")
A7: S02 | B7: S02-M1 | C7: 임계 신규점1 | D7: 방위표지1 | E7: 37.3587 | F7: 128.9739 | H7: 기준점 | I7: 방위표지 | L7: =IF(COUNT(J7:K7)=2,ABS(ABS(K7-J7)-200),"") | N7: =IF(ISNUMBER(M7),M7*0.9,"") | O7: =IF(ISNUMBER(M7),MOD(M7*0.9+180,360),"") | S7: =IF(AND(ISNUMBER(M7),ISNUMBER(R7)),(M7*0.9-R7)*3600,"")
A8: S02 | B8: S02-M2 | C8: 임계 신규점1 | D8: 방위표지2 | E8: 37.358529 | F8: 128.97477 | H8: 기준점 | I8: 방위표지 | L8: =IF(COUNT(J8:K8)=2,ABS(ABS(K8-J8)-200),"") | N8: =IF(ISNUMBER(M8),M8*0.9,"") | O8: =IF(ISNUMBER(M8),MOD(M8*0.9+180,360),"") | S8: =IF(AND(ISNUMBER(M8),ISNUMBER(R8)),(M8*0.9-R8)*3600,"")
A9: S03 | B9: S03-M1 | C9: 예산 신규점2 | D9: 방위표지1 | E9: 36.534094 | F9: 126.93481 | H9: 기준점 | I9: 방위표지 | L9: =IF(COUNT(J9:K9)=2,ABS(ABS(K9-J9)-200),"") | N9: =IF(ISNUMBER(M9),M9*0.9,"") | O9: =IF(ISNUMBER(M9),MOD(M9*0.9+180,360),"") | S9: =IF(AND(ISNUMBER(M9),ISNUMBER(R9)),(M9*0.9-R9)*3600,"")
A10: S03 | B10: S03-M2 | C10: 예산 신규점2 | D10: 방위표지2 | E10: 36.533699 | F10: 126.93798 | H10: 기준점 | I10: 방위표지 | L10: =IF(COUNT(J10:K10)=2,ABS(ABS(K10-J10)-200),"") | N10: =IF(ISNUMBER(M10),M10*0.9,"") | O10: =IF(ISNUMBER(M10),MOD(M10*0.9+180,360),"") | S10: =IF(AND(ISNUMBER(M10),ISNUMBER(R10)),(M10*0.9-R10)*3600,"")
A11: S04 | B11: S04-M1 | C11: 진안 신규점1 | D11: 방위표지1 | E11: 35.891876 | F11: 127.30849 | H11: 기준점 | I11: 방위표지 | L11: =IF(COUNT(J11:K11)=2,ABS(ABS(K11-J11)-200),"") | N11: =IF(ISNUMBER(M11),M11*0.9,"") | O11: =IF(ISNUMBER(M11),MOD(M11*0.9+180,360),"") | S11: =IF(AND(ISNUMBER(M11),ISNUMBER(R11)),(M11*0.9-R11)*3600,"")
A12: S04 | B12: S04-M2 | C12: 진안 신규점1 | D12: 방위표지2 | E12: 35.89031 | F12: 127.30879 | H12: 기준점 | I12: 방위표지 | L12: =IF(COUNT(J12:K12)=2,ABS(ABS(K12-J12)-200),"") | N12: =IF(ISNUMBER(M12),M12*0.9,"") | O12: =IF(ISNUMBER(M12),MOD(M12*0.9+180,360),"") | S12: =IF(AND(ISNUMBER(M12),ISNUMBER(R12)),(M12*0.9-R12)*3600,"")
A13: S05 | B13: S05-M1 | C13: 무풍 신규점1 | D13: 방위표지1 | E13: 35.945053 | F13: 127.80054 | H13: 기준점 | I13: 방위표지 | L13: =IF(COUNT(J13:K13)=2,ABS(ABS(K13-J13)-200),"") | N13: =IF(ISNUMBER(M13),M13*0.9,"") | O13: =IF(ISNUMBER(M13),MOD(M13*0.9+180,360),"") | S13: =IF(AND(ISNUMBER(M13),ISNUMBER(R13)),(M13*0.9-R13)*3600,"")
A14: S05 | B14: S05-M2 | C14: 무풍 신규점1 | D14: 방위표지2 | E14: 35.946307 | F14: 127.80241 | H14: 기준점 | I14: 방위표지 | L14: =IF(COUNT(J14:K14)=2,ABS(ABS(K14-J14)-200),"") | N14: =IF(ISNUMBER(M14),M14*0.9,"") | O14: =IF(ISNUMBER(M14),MOD(M14*0.9+180,360),"") | S14: =IF(AND(ISNUMBER(M14),ISNUMBER(R14)),(M14*0.9-R14)*3600,"")
A15: S06 | B15: S06-M1 | C15: 길담 신규점 | D15: 방위표지1 | E15: 35.605228 | F15: 127.23014 | H15: 기준점 | I15: 방위표지 | L15: =IF(COUNT(J15:K15)=2,ABS(ABS(K15-J15)-200),"") | N15: =IF(ISNUMBER(M15),M15*0.9,"") | O15: =IF(ISNUMBER(M15),MOD(M15*0.9+180,360),"") | S15: =IF(AND(ISNUMBER(M15),ISNUMBER(R15)),(M15*0.9-R15)*3600,"")
A16: S06 | B16: S06-M2 | C16: 길담 신규점 | D16: 방위표지2 | E16: 35.604125 | F16: 127.23019 | H16: 기준점 | I16: 방위표지 | L16: =IF(COUNT(J16:K16)=2,ABS(ABS(K16-J16)-200),"") | N16: =IF(ISNUMBER(M16),M16*0.9,"") | O16: =IF(ISNUMBER(M16),MOD(M16*0.9+180,360),"") | S16: =IF(AND(ISNUMBER(M16),ISNUMBER(R16)),(M16*0.9-R16)*3600,"")
... A72: S34 | B72: S34-M2 | C72: 부안 신규점 | D72: 방위표지2 | E72: 35.542434 | F72: 126.64437 | H72: 기준점 | I72: 방위표지 | L72: =IF(COUNT(J72:K72)=2,ABS(ABS(K72-J72)-200),"") | N72: =IF(ISNUMBER(M72),M72*0.9,"") | O72: =IF(ISNUMBER(M72),MOD(M72*0.9+180,360),"") | S72: =IF(AND(ISNUMBER(M72),ISNUMBER(R72)),(M72*0.9-R72)*3600,"")
A73: S35 | B73: S35-M1 | C73: 상주 | D73: 방위표지1 | H73: 기준점 | I73: 방위표지 | L73: =IF(COUNT(J73:K73)=2,ABS(ABS(K73-J73)-200),"") | N73: =IF(ISNUMBER(M73),M73*0.9,"") | O73: =IF(ISNUMBER(M73),MOD(M73*0.9+180,360),"") | S73: =IF(AND(ISNUMBER(M73),ISNUMBER(R73)),(M73*0.9-R73)*3600,"")
A74: S35 | B74: S35-M2 | C74: 상주 | D74: 방위표지2 | H74: 기준점 | I74: 방위표지 | L74: =IF(COUNT(J74:K74)=2,ABS(ABS(K74-J74)-200),"") | N74: =IF(ISNUMBER(M74),M74*0.9,"") | O74: =IF(ISNUMBER(M74),MOD(M74*0.9+180,360),"") | S74: =IF(AND(ISNUMBER(M74),ISNUMBER(R74)),(M74*0.9-R74)*3600,"")
A75: S36 | B75: S36-M1 | C75: 미원 | D75: 방위표지1 | H75: 기준점 | I75: 방위표지 | L75: =IF(COUNT(J75:K75)=2,ABS(ABS(K75-J75)-200),"") | N75: =IF(ISNUMBER(M75),M75*0.9,"") | O75: =IF(ISNUMBER(M75),MOD(M75*0.9+180,360),"") | S75: =IF(AND(ISNUMBER(M75),ISNUMBER(R75)),(M75*0.9-R75)*3600,"")
A76: S36 | B76: S36-M2 | C76: 미원 | D76: 방위표지2 | H76: 기준점 | I76: 방위표지 | L76: =IF(COUNT(J76:K76)=2,ABS(ABS(K76-J76)-200),"") | N76: =IF(ISNUMBER(M76),M76*0.9,"") | O76: =IF(ISNUMBER(M76),MOD(M76*0.9+180,360),"") | S76: =IF(AND(ISNUMBER(M76),ISNUMBER(R76)),(M76*0.9-R76)*3600,"")
A77: S37 | B77: S37-M1 | C77: 부안 | D77: 방위표지1 | H77: 기준점 | I77: 방위표지 | L77: =IF(COUNT(J77:K77)=2,ABS(ABS(K77-J77)-200),"") | N77: =IF(ISNUMBER(M77),M77*0.9,"") | O77: =IF(ISNUMBER(M77),MOD(M77*0.9+180,360),"") | S77: =IF(AND(ISNUMBER(M77),ISNUMBER(R77)),(M77*0.9-R77)*3600,"")
A78: S37 | B78: S37-M2 | C78: 부안 | D78: 방위표지2 | H78: 기준점 | I78: 방위표지 | L78: =IF(COUNT(J78:K78)=2,ABS(ABS(K78-J78)-200),"") | N78: =IF(ISNUMBER(M78),M78*0.9,"") | O78: =IF(ISNUMBER(M78),MOD(M78*0.9+180,360),"") | S78: =IF(AND(ISNUMBER(M78),ISNUMBER(R78)),(M78*0.9-R78)*3600,"")
A79: S38 | B79: S38-M1 | C79: 강화 | D79: 방위표지1 | H79: 기준점 | I79: 방위표지 | L79: =IF(COUNT(J79:K79)=2,ABS(ABS(K79-J79)-200),"") | N79: =IF(ISNUMBER(M79),M79*0.9,"") | O79: =IF(ISNUMBER(M79),MOD(M79*0.9+180,360),"") | S79: =IF(AND(ISNUMBER(M79),ISNUMBER(R79)),(M79*0.9-R79)*3600,"")
A80: S38 | B80: S38-M2 | C80: 강화 | D80: 방위표지2 | H80: 기준점 | I80: 방위표지 | L80: =IF(COUNT(J80:K80)=2,ABS(ABS(K80-J80)-200),"") | N80: =IF(ISNUMBER(M80),M80*0.9,"") | O80: =IF(ISNUMBER(M80),MOD(M80*0.9+180,360),"") | S80: =IF(AND(ISNUMBER(M80),ISNUMBER(R80)),(M80*0.9-R80)*3600,"")
A81: S39 | B81: S39-M1 | C81: 언양 | D81: 방위표지1 | H81: 기준점 | I81: 방위표지 | L81: =IF(COUNT(J81:K81)=2,ABS(ABS(K81-J81)-200),"") | N81: =IF(ISNUMBER(M81),M81*0.9,"") | O81: =IF(ISNUMBER(M81),MOD(M81*0.9+180,360),"") | S81: =IF(AND(ISNUMBER(M81),ISNUMBER(R81)),(M81*0.9-R81)*3600,"")
A82: S39 | B82: S39-M2 | C82: 언양 | D82: 방위표지2 | H82: 기준점 | I82: 방위표지 | L82: =IF(COUNT(J82:K82)=2,ABS(ABS(K82-J82)-200),"") | N82: =IF(ISNUMBER(M82),M82*0.9,"") | O82: =IF(ISNUMBER(M82),MOD(M82*0.9+180,360),"") | S82: =IF(AND(ISNUMBER(M82),ISNUMBER(R82)),(M82*0.9-R82)*3600,"")
A83: S40 | B83: S40-M1 | C83: 남지 | D83: 방위표지1 | H83: 기준점 | I83: 방위표지 | L83: =IF(COUNT(J83:K83)=2,ABS(ABS(K83-J83)-200),"") | N83: =IF(ISNUMBER(M83),M83*0.9,"") | O83: =IF(ISNUMBER(M83),MOD(M83*0.9+180,360),"") | S83: =IF(AND(ISNUMBER(M83),ISNUMBER(R83)),(M83*0.9-R83)*3600,"")
A84: S40 | B84: S40-M2 | C84: 남지 | D84: 방위표지2 | H84: 기준점 | I84: 방위표지 | L84: =IF(COUNT(J84:K84)=2,ABS(ABS(K84-J84)-200),"") | N84: =IF(ISNUMBER(M84),M84*0.9,"") | O84: =IF(ISNUMBER(M84),MOD(M84*0.9+180,360),"") | S84: =IF(AND(ISNUMBER(M84),ISNUMBER(R84)),(M84*0.9-R84)*3600,"")
... A104: S50 | B104: S50-M2 | C104: 함양 | D104: 방위표지2 | H104: 기준점 | I104: 방위표지 | L104: =IF(COUNT(J104:K104)=2,ABS(ABS(K104-J104)-200),"") | N104: =IF(ISNUMBER(M104),M104*0.9,"") | O104: =IF(ISNUMBER(M104),MOD(M104*0.9+180,360),"") | S104: =IF(AND(ISNUMBER(M104),ISNUMBER(R104)),(M104*0.9-R104)*3600,"")

Sheet ⑦ 장비·검교정
A1: 관측 장비 · 검교정 이력
A2: 검교정 주기는 KOLAS-G-008 고시(국가표준기본법 §14) 기준이다. 성적서 번호와 유효기간을 적지 않으면 그 관측의 신뢰성을 사후에 입증할 수 없다.
A3: ⚠ 이동 자력계는 GSM-19T **1대**가 전제다. 두 번째 PPM 을 요구하는 절차(교차배치 등)는 «2대 확보 시에만» 수행하며 미확보 시 NOT APPLICABLE 로 남긴다.
A4: ■ 보유 장비 (원 자료 31면)
A5: 구분 | B5: 모델 | C5: 용도 | D5: 유의사항 | E5: 기기번호 | F5: 검정일 | G5: 유효기간 | H5: 검정기관 | I5: 성적서 번호 | J5: 시험 탐사 범위
A6: 오버하우저 | B6: GSM-19T | C6: 전자력(F) 측정 · 자기구배 확인 | D6: 한국표준과학연구원(KRISS) | J6: 시험 탐사 투입
A7: 이동식 Variometer | C7: 측량기간 중 자기장 시간변화 연속기록 | D7: P0 선형보간의 선형성을 검증할 유일한 수단 | J7: 시험 탐사 투입
A8: GNSS 수신기 | C8: 좌표·방위각 확인 | J8: 시험 탐사 투입
A9: DI-flux | B9: MinGeo 010B | C9: 편각(D)·복각(I) 절대관측 | D9: 제조사(헝가리) — 해외 발송 장기화·예비장비 부재 시 측정 공백 | J9: 범위 밖 — 절대관측 단계
A11: ■ 검교정 주기 — KOLAS-G-008 고시 · 국가표준기본법 §14
A12: 장비 분류 | B12: 분류번호 | C12: 주기 | D12: 적용 기기번호 | E12: 직전 검정일 | F12: 다음 예정일 | G12: 상태
A13: 저자기장 측정기 | B13: 404505 | C13: 1년
A14: 마그네토미터 | B14: 404508 | C14: 1년
A15: 데오도라이트·트랜지트 | B15: 10321 | C15: 2년

Sheet ⑧ 관측조건·변동관측
A1: 관측 조건 · 이동식 Variometer 연속기록
A2: ⚠ P0 전·후 선형보간은 «중심점 자기장이 그 사이 선형으로 변한다»는 가정이며, 두 끝점만으로는 중간의 비선형 변화나 순간 교란을 «탐지할 수 없다». Variometer 연속기록이 있어야 그 가정을 검증할 수 있다 — 없는 세트는 ⑬에서 「선형성 미검증」으로 구분한다.
A3: 최근접 상시관측소는 중앙 101 km · 최대 229 km(거제)이고, 그 거리에서 「외부장이 전역 균일」 근사가 깨짐을 이 프로젝트가 실증했다. 관측 조건: [절대관측 단계] 자기장 일변화가 안정적인 야간 시간대에 절대관측 수행 / 우주기상 예보와 Kp 지수를 확인하여 관측일정 편성 / 현장측량 기간 동안 이동식 Variometer 연속관측 / 자기교란 발생 시 해당 관측구간 제외 또는 재관측 / 타 기관 상시관측자료와 교차검증 / [시험 탐사] 야간 의무는 없으나 «시간변화가 안정된 구간»을 골라 측정한다
A4: Site ID | B4: Visit ID | C4: 관측일자 | D4: 야간 관측 여부 | E4: Kp 확인값 | F4: 우주기상 예보 확인 | G4: Variometer 파일 ID | H4: 위치 ID | I4: 위도 | J4: 경도 | K4: 기록 간격(s) | L4: 기록 시작(KST) | M4: 기록 종료(KST) | N4: 자료공백 구간 | O4: 시계 동기 방법 | P4: 동기 오차(s)

Sheet ⑨ 수평 자기구배
A1: 수평 자기구배 — Guide for Magnetic Repeat Station Surveys §4.2 (IAGA, 1996)
A2: P0 → 방향별 측정 → P0 재측정. 한 방향 0.5, 1, 2, 3, 4, 5, 6, 7, 8, 9, 10 m 를 재고 동·서·남·북 네 방향을 반복한다. 방향마다 P0(전)·P0(후) 행이 따로 있고 그 둘의 «선형보간»으로 각 측정 시각의 중심점을 추정한다.
A3: ⚠ 「Set 검증」이 OK 일 때만 계산된다 — 유효 P0 가 전·후 각각 정확히 1개이고 측정시각이 그 사이여야 한다. 아니면 수치 대신 오류 사유가 뜬다. ΔF·변화율은 **부호를 보존**하고 절댓값은 별도 열이다. 「중심점기준 변화율(ΔF/d)」과 「인접구간 변화율」은 서로 다른 양이니 섞지 말 것.
A4: Site ID | B4: 지점명 | C4: Set ID | D4: 구분 | E4: 방향 | F4: 명목거리(m) | G4: 실측거리(m) | H4: 측정 시각(KST) | I4: F 판독1(nT) | J4: F 판독2 | K4: F 판독3 | L4: 중앙값 계산 | M4: Set 검증 계산 | N4: P0전 시각 계산 | O4: P0전 F 계산 | P4: P0후 시각 계산 | Q4: P0후 F 계산 | R4: P0 추정값 계산 | S4: ΔF(nT) 계산 | T4: 중심점기준 변화율(nT/m) 계산 | U4: |변화율| 계산 | V4: 인접구간 변화율(nT/m) 계산 | W4: Set 지속(분) 계산 | X4: 기기번호 | Y4: Variometer 파일 ID | Z4: Set 상태 | AA4: 중단 시각·사유 | AB4: 상태·비고
A5: S01 | B5: 태백 신규점 | C5: S01-H동 | D5: P0(전) | E5: 동 | L5: =IF(COUNT(I5:K5)=0,"",MEDIAN(I5:K5))
A6: S01 | B6: 태백 신규점 | C6: S01-H동 | D6: 측정 | E6: 동 | F6: 0.5 | L6: =IF(COUNT(I6:K6)=0,"",MEDIAN(I6:K6)) | M6: =IF(COUNTIFS($C:$C,$C6,$D:$D,"P0(전)",$L:$L,">0")<>1,"P0(전) 유효 1개 아님",IF(COUNTIFS($C:$C,$C6,$D:$D,"P0(후)",$L:$L,">0")<>1,"P0(후) 유효 1개 아님",IF(NOT(AND(ISNUMBER(N6),ISNUMBER(P6),ISNUMBER(H6))),"시각 결측",IF(P6<=N6,"P0 시각 역전",IF(OR(H6<N6,H6>P6),"측정시각 구간 밖","OK"))))) | N6: =IF(COUNTIFS($C:$C,$C6,$D:$D,"P0(전)",$L:$L,">0")<>1,"",SUMIFS($H:$H,$C:$C,$C6,$D:$D,"P0(전)")) | O6: =IF(COUNTIFS($C:$C,$C6,$D:$D,"P0(전)",$L:$L,">0")<>1,"",SUMIFS($L:$L,$C:$C,$C6,$D:$D,"P0(전)")) | P6: =IF(COUNTIFS($C:$C,$C6,$D:$D,"P0(후)",$L:$L,">0")<>1,"",SUMIFS($H:$H,$C:$C,$C6,$D:$D,"P0(후)")) | Q6: =IF(COUNTIFS($C:$C,$C6,$D:$D,"P0(후)",$L:$L,">0")<>1,"",SUMIFS($L:$L,$C:$C,$C6,$D:$D,"P0(후)")) | R6: =IF(M6<>"OK","",O6+(Q6-O6)*(H6-N6)/(P6-N6)) | S6: =IF(OR(M6<>"OK",NOT(ISNUMBER(L6))),"",L6-R6) | T6: =IF(OR(NOT(ISNUMBER(S6)),IF(ISNUMBER(G6),G6,F6)=0),"",S6/IF(ISNUMBER(G6),G6,F6)) | U6: =IF(ISNUMBER(T6),ABS(T6),"") | V6: =IF(OR($D5<>"측정",$C5<>$C6,NOT(ISNUMBER(L6)),NOT(ISNUMBER(L5)),(IF(ISNUMBER(G6),G6,F6)-IF(ISNUMBER(G5),G5,F5))=0),"",(L6-L5)/(IF(ISNUMBER(G6),G6,F6)-IF(ISNUMBER(G5),G5,F5))) | W6: =IF(NOT(AND(ISNUMBER(N6),ISNUMBER(P6))),"",(P6-N6)*1440)
A7: S01 | B7: 태백 신규점 | C7: S01-H동 | D7: 측정 | E7: 동 | F7: 1 | L7: =IF(COUNT(I7:K7)=0,"",MEDIAN(I7:K7)) | M7: =IF(COUNTIFS($C:$C,$C7,$D:$D,"P0(전)",$L:$L,">0")<>1,"P0(전) 유효 1개 아님",IF(COUNTIFS($C:$C,$C7,$D:$D,"P0(후)",$L:$L,">0")<>1,"P0(후) 유효 1개 아님",IF(NOT(AND(ISNUMBER(N7),ISNUMBER(P7),ISNUMBER(H7))),"시각 결측",IF(P7<=N7,"P0 시각 역전",IF(OR(H7<N7,H7>P7),"측정시각 구간 밖","OK"))))) | N7: =IF(COUNTIFS($C:$C,$C7,$D:$D,"P0(전)",$L:$L,">0")<>1,"",SUMIFS($H:$H,$C:$C,$C7,$D:$D,"P0(전)")) | O7: =IF(COUNTIFS($C:$C,$C7,$D:$D,"P0(전)",$L:$L,">0")<>1,"",SUMIFS($L:$L,$C:$C,$C7,$D:$D,"P0(전)")) | P7: =IF(COUNTIFS($C:$C,$C7,$D:$D,"P0(후)",$L:$L,">0")<>1,"",SUMIFS($H:$H,$C:$C,$C7,$D:$D,"P0(후)")) | Q7: =IF(COUNTIFS($C:$C,$C7,$D:$D,"P0(후)",$L:$L,">0")<>1,"",SUMIFS($L:$L,$C:$C,$C7,$D:$D,"P0(후)")) | R7: =IF(M7<>"OK","",O7+(Q7-O7)*(H7-N7)/(P7-N7)) | S7: =IF(OR(M7<>"OK",NOT(ISNUMBER(L7))),"",L7-R7) | T7: =IF(OR(NOT(ISNUMBER(S7)),IF(ISNUMBER(G7),G7,F7)=0),"",S7/IF(ISNUMBER(G7),G7,F7)) | U7: =IF(ISNUMBER(T7),ABS(T7),"") | V7: =IF(OR($D6<>"측정",$C6<>$C7,NOT(ISNUMBER(L7)),NOT(ISNUMBER(L6)),(IF(ISNUMBER(G7),G7,F7)-IF(ISNUMBER(G6),G6,F6))=0),"",(L7-L6)/(IF(ISNUMBER(G7),G7,F7)-IF(ISNUMBER(G6),G6,F6))) | W7: =IF(NOT(AND(ISNUMBER(N7),ISNUMBER(P7))),"",(P7-N7)*1440)
A8: S01 | B8: 태백 신규점 | C8: S01-H동 | D8: 측정 | E8: 동 | F8: 2 | L8: =IF(COUNT(I8:K8)=0,"",MEDIAN(I8:K8)) | M8: =IF(COUNTIFS($C:$C,$C8,$D:$D,"P0(전)",$L:$L,">0")<>1,"P0(전) 유효 1개 아님",IF(COUNTIFS($C:$C,$C8,$D:$D,"P0(후)",$L:$L,">0")<>1,"P0(후) 유효 1개 아님",IF(NOT(AND(ISNUMBER(N8),ISNUMBER(P8),ISNUMBER(H8))),"시각 결측",IF(P8<=N8,"P0 시각 역전",IF(OR(H8<N8,H8>P8),"측정시각 구간 밖","OK"))))) | N8: =IF(COUNTIFS($C:$C,$C8,$D:$D,"P0(전)",$L:$L,">0")<>1,"",SUMIFS($H:$H,$C:$C,$C8,$D:$D,"P0(전)")) | O8: =IF(COUNTIFS($C:$C,$C8,$D:$D,"P0(전)",$L:$L,">0")<>1,"",SUMIFS($L:$L,$C:$C,$C8,$D:$D,"P0(전)")) | P8: =IF(COUNTIFS($C:$C,$C8,$D:$D,"P0(후)",$L:$L,">0")<>1,"",SUMIFS($H:$H,$C:$C,$C8,$D:$D,"P0(후)")) | Q8: =IF(COUNTIFS($C:$C,$C8,$D:$D,"P0(후)",$L:$L,">0")<>1,"",SUMIFS($L:$L,$C:$C,$C8,$D:$D,"P0(후)")) | R8: =IF(M8<>"OK","",O8+(Q8-O8)*(H8-N8)/(P8-N8)) | S8: =IF(OR(M8<>"OK",NOT(ISNUMBER(L8))),"",L8-R8) | T8: =IF(OR(NOT(ISNUMBER(S8)),IF(ISNUMBER(G8),G8,F8)=0),"",S8/IF(ISNUMBER(G8),G8,F8)) | U8: =IF(ISNUMBER(T8),ABS(T8),"") | V8: =IF(OR($D7<>"측정",$C7<>$C8,NOT(ISNUMBER(L8)),NOT(ISNUMBER(L7)),(IF(ISNUMBER(G8),G8,F8)-IF(ISNUMBER(G7),G7,F7))=0),"",(L8-L7)/(IF(ISNUMBER(G8),G8,F8)-IF(ISNUMBER(G7),G7,F7))) | W8: =IF(NOT(AND(ISNUMBER(N8),ISNUMBER(P8))),"",(P8-N8)*1440)
A9: S01 | B9: 태백 신규점 | C9: S01-H동 | D9: 측정 | E9: 동 | F9: 3 | L9: =IF(COUNT(I9:K9)=0,"",MEDIAN(I9:K9)) | M9: =IF(COUNTIFS($C:$C,$C9,$D:$D,"P0(전)",$L:$L,">0")<>1,"P0(전) 유효 1개 아님",IF(COUNTIFS($C:$C,$C9,$D:$D,"P0(후)",$L:$L,">0")<>1,"P0(후) 유효 1개 아님",IF(NOT(AND(ISNUMBER(N9),ISNUMBER(P9),ISNUMBER(H9))),"시각 결측",IF(P9<=N9,"P0 시각 역전",IF(OR(H9<N9,H9>P9),"측정시각 구간 밖","OK"))))) | N9: =IF(COUNTIFS($C:$C,$C9,$D:$D,"P0(전)",$L:$L,">0")<>1,"",SUMIFS($H:$H,$C:$C,$C9,$D:$D,"P0(전)")) | O9: =IF(COUNTIFS($C:$C,$C9,$D:$D,"P0(전)",$L:$L,">0")<>1,"",SUMIFS($L:$L,$C:$C,$C9,$D:$D,"P0(전)")) | P9: =IF(COUNTIFS($C:$C,$C9,$D:$D,"P0(후)",$L:$L,">0")<>1,"",SUMIFS($H:$H,$C:$C,$C9,$D:$D,"P0(후)")) | Q9: =IF(COUNTIFS($C:$C,$C9,$D:$D,"P0(후)",$L:$L,">0")<>1,"",SUMIFS($L:$L,$C:$C,$C9,$D:$D,"P0(후)")) | R9: =IF(M9<>"OK","",O9+(Q9-O9)*(H9-N9)/(P9-N9)) | S9: =IF(OR(M9<>"OK",NOT(ISNUMBER(L9))),"",L9-R9) | T9: =IF(OR(NOT(ISNUMBER(S9)),IF(ISNUMBER(G9),G9,F9)=0),"",S9/IF(ISNUMBER(G9),G9,F9)) | U9: =IF(ISNUMBER(T9),ABS(T9),"") | V9: =IF(OR($D8<>"측정",$C8<>$C9,NOT(ISNUMBER(L9)),NOT(ISNUMBER(L8)),(IF(ISNUMBER(G9),G9,F9)-IF(ISNUMBER(G8),G8,F8))=0),"",(L9-L8)/(IF(ISNUMBER(G9),G9,F9)-IF(ISNUMBER(G8),G8,F8))) | W9: =IF(NOT(AND(ISNUMBER(N9),ISNUMBER(P9))),"",(P9-N9)*1440)
A10: S01 | B10: 태백 신규점 | C10: S01-H동 | D10: 측정 | E10: 동 | F10: 4 | L10: =IF(COUNT(I10:K10)=0,"",MEDIAN(I10:K10)) | M10: =IF(COUNTIFS($C:$C,$C10,$D:$D,"P0(전)",$L:$L,">0")<>1,"P0(전) 유효 1개 아님",IF(COUNTIFS($C:$C,$C10,$D:$D,"P0(후)",$L:$L,">0")<>1,"P0(후) 유효 1개 아님",IF(NOT(AND(ISNUMBER(N10),ISNUMBER(P10),ISNUMBER(H10))),"시각 결측",IF(P10<=N10,"P0 시각 역전",IF(OR(H10<N10,H10>P10),"측정시각 구간 밖","OK"))))) | N10: =IF(COUNTIFS($C:$C,$C10,$D:$D,"P0(전)",$L:$L,">0")<>1,"",SUMIFS($H:$H,$C:$C,$C10,$D:$D,"P0(전)")) | O10: =IF(COUNTIFS($C:$C,$C10,$D:$D,"P0(전)",$L:$L,">0")<>1,"",SUMIFS($L:$L,$C:$C,$C10,$D:$D,"P0(전)")) | P10: =IF(COUNTIFS($C:$C,$C10,$D:$D,"P0(후)",$L:$L,">0")<>1,"",SUMIFS($H:$H,$C:$C,$C10,$D:$D,"P0(후)")) | Q10: =IF(COUNTIFS($C:$C,$C10,$D:$D,"P0(후)",$L:$L,">0")<>1,"",SUMIFS($L:$L,$C:$C,$C10,$D:$D,"P0(후)")) | R10: =IF(M10<>"OK","",O10+(Q10-O10)*(H10-N10)/(P10-N10)) | S10: =IF(OR(M10<>"OK",NOT(ISNUMBER(L10))),"",L10-R10) | T10: =IF(OR(NOT(ISNUMBER(S10)),IF(ISNUMBER(G10),G10,F10)=0),"",S10/IF(ISNUMBER(G10),G10,F10)) | U10: =IF(ISNUMBER(T10),ABS(T10),"") | V10: =IF(OR($D9<>"측정",$C9<>$C10,NOT(ISNUMBER(L10)),NOT(ISNUMBER(L9)),(IF(ISNUMBER(G10),G10,F10)-IF(ISNUMBER(G9),G9,F9))=0),"",(L10-L9)/(IF(ISNUMBER(G10),G10,F10)-IF(ISNUMBER(G9),G9,F9))) | W10: =IF(NOT(AND(ISNUMBER(N10),ISNUMBER(P10))),"",(P10-N10)*1440)
A11: S01 | B11: 태백 신규점 | C11: S01-H동 | D11: 측정 | E11: 동 | F11: 5 | L11: =IF(COUNT(I11:K11)=0,"",MEDIAN(I11:K11)) | M11: =IF(COUNTIFS($C:$C,$C11,$D:$D,"P0(전)",$L:$L,">0")<>1,"P0(전) 유효 1개 아님",IF(COUNTIFS($C:$C,$C11,$D:$D,"P0(후)",$L:$L,">0")<>1,"P0(후) 유효 1개 아님",IF(NOT(AND(ISNUMBER(N11),ISNUMBER(P11),ISNUMBER(H11))),"시각 결측",IF(P11<=N11,"P0 시각 역전",IF(OR(H11<N11,H11>P11),"측정시각 구간 밖","OK"))))) | N11: =IF(COUNTIFS($C:$C,$C11,$D:$D,"P0(전)",$L:$L,">0")<>1,"",SUMIFS($H:$H,$C:$C,$C11,$D:$D,"P0(전)")) | O11: =IF(COUNTIFS($C:$C,$C11,$D:$D,"P0(전)",$L:$L,">0")<>1,"",SUMIFS($L:$L,$C:$C,$C11,$D:$D,"P0(전)")) | P11: =IF(COUNTIFS($C:$C,$C11,$D:$D,"P0(후)",$L:$L,">0")<>1,"",SUMIFS($H:$H,$C:$C,$C11,$D:$D,"P0(후)")) | Q11: =IF(COUNTIFS($C:$C,$C11,$D:$D,"P0(후)",$L:$L,">0")<>1,"",SUMIFS($L:$L,$C:$C,$C11,$D:$D,"P0(후)")) | R11: =IF(M11<>"OK","",O11+(Q11-O11)*(H11-N11)/(P11-N11)) | S11: =IF(OR(M11<>"OK",NOT(ISNUMBER(L11))),"",L11-R11) | T11: =IF(OR(NOT(ISNUMBER(S11)),IF(ISNUMBER(G11),G11,F11)=0),"",S11/IF(ISNUMBER(G11),G11,F11)) | U11: =IF(ISNUMBER(T11),ABS(T11),"") | V11: =IF(OR($D10<>"측정",$C10<>$C11,NOT(ISNUMBER(L11)),NOT(ISNUMBER(L10)),(IF(ISNUMBER(G11),G11,F11)-IF(ISNUMBER(G10),G10,F10))=0),"",(L11-L10)/(IF(ISNUMBER(G11),G11,F11)-IF(ISNUMBER(G10),G10,F10))) | W11: =IF(NOT(AND(ISNUMBER(N11),ISNUMBER(P11))),"",(P11-N11)*1440)
A12: S01 | B12: 태백 신규점 | C12: S01-H동 | D12: 측정 | E12: 동 | F12: 6 | L12: =IF(COUNT(I12:K12)=0,"",MEDIAN(I12:K12)) | M12: =IF(COUNTIFS($C:$C,$C12,$D:$D,"P0(전)",$L:$L,">0")<>1,"P0(전) 유효 1개 아님",IF(COUNTIFS($C:$C,$C12,$D:$D,"P0(후)",$L:$L,">0")<>1,"P0(후) 유효 1개 아님",IF(NOT(AND(ISNUMBER(N12),ISNUMBER(P12),ISNUMBER(H12))),"시각 결측",IF(P12<=N12,"P0 시각 역전",IF(OR(H12<N12,H12>P12),"측정시각 구간 밖","OK"))))) | N12: =IF(COUNTIFS($C:$C,$C12,$D:$D,"P0(전)",$L:$L,">0")<>1,"",SUMIFS($H:$H,$C:$C,$C12,$D:$D,"P0(전)")) | O12: =IF(COUNTIFS($C:$C,$C12,$D:$D,"P0(전)",$L:$L,">0")<>1,"",SUMIFS($L:$L,$C:$C,$C12,$D:$D,"P0(전)")) | P12: =IF(COUNTIFS($C:$C,$C12,$D:$D,"P0(후)",$L:$L,">0")<>1,"",SUMIFS($H:$H,$C:$C,$C12,$D:$D,"P0(후)")) | Q12: =IF(COUNTIFS($C:$C,$C12,$D:$D,"P0(후)",$L:$L,">0")<>1,"",SUMIFS($L:$L,$C:$C,$C12,$D:$D,"P0(후)")) | R12: =IF(M12<>"OK","",O12+(Q12-O12)*(H12-N12)/(P12-N12)) | S12: =IF(OR(M12<>"OK",NOT(ISNUMBER(L12))),"",L12-R12) | T12: =IF(OR(NOT(ISNUMBER(S12)),IF(ISNUMBER(G12),G12,F12)=0),"",S12/IF(ISNUMBER(G12),G12,F12)) | U12: =IF(ISNUMBER(T12),ABS(T12),"") | V12: =IF(OR($D11<>"측정",$C11<>$C12,NOT(ISNUMBER(L12)),NOT(ISNUMBER(L11)),(IF(ISNUMBER(G12),G12,F12)-IF(ISNUMBER(G11),G11,F11))=0),"",(L12-L11)/(IF(ISNUMBER(G12),G12,F12)-IF(ISNUMBER(G11),G11,F11))) | W12: =IF(NOT(AND(ISNUMBER(N12),ISNUMBER(P12))),"",(P12-N12)*1440)
A13: S01 | B13: 태백 신규점 | C13: S01-H동 | D13: 측정 | E13: 동 | F13: 7 | L13: =IF(COUNT(I13:K13)=0,"",MEDIAN(I13:K13)) | M13: =IF(COUNTIFS($C:$C,$C13,$D:$D,"P0(전)",$L:$L,">0")<>1,"P0(전) 유효 1개 아님",IF(COUNTIFS($C:$C,$C13,$D:$D,"P0(후)",$L:$L,">0")<>1,"P0(후) 유효 1개 아님",IF(NOT(AND(ISNUMBER(N13),ISNUMBER(P13),ISNUMBER(H13))),"시각 결측",IF(P13<=N13,"P0 시각 역전",IF(OR(H13<N13,H13>P13),"측정시각 구간 밖","OK"))))) | N13: =IF(COUNTIFS($C:$C,$C13,$D:$D,"P0(전)",$L:$L,">0")<>1,"",SUMIFS($H:$H,$C:$C,$C13,$D:$D,"P0(전)")) | O13: =IF(COUNTIFS($C:$C,$C13,$D:$D,"P0(전)",$L:$L,">0")<>1,"",SUMIFS($L:$L,$C:$C,$C13,$D:$D,"P0(전)")) | P13: =IF(COUNTIFS($C:$C,$C13,$D:$D,"P0(후)",$L:$L,">0")<>1,"",SUMIFS($H:$H,$C:$C,$C13,$D:$D,"P0(후)")) | Q13: =IF(COUNTIFS($C:$C,$C13,$D:$D,"P0(후)",$L:$L,">0")<>1,"",SUMIFS($L:$L,$C:$C,$C13,$D:$D,"P0(후)")) | R13: =IF(M13<>"OK","",O13+(Q13-O13)*(H13-N13)/(P13-N13)) | S13: =IF(OR(M13<>"OK",NOT(ISNUMBER(L13))),"",L13-R13) | T13: =IF(OR(NOT(ISNUMBER(S13)),IF(ISNUMBER(G13),G13,F13)=0),"",S13/IF(ISNUMBER(G13),G13,F13)) | U13: =IF(ISNUMBER(T13),ABS(T13),"") | V13: =IF(OR($D12<>"측정",$C12<>$C13,NOT(ISNUMBER(L13)),NOT(ISNUMBER(L12)),(IF(ISNUMBER(G13),G13,F13)-IF(ISNUMBER(G12),G12,F12))=0),"",(L13-L12)/(IF(ISNUMBER(G13),G13,F13)-IF(ISNUMBER(G12),G12,F12))) | W13: =IF(NOT(AND(ISNUMBER(N13),ISNUMBER(P13))),"",(P13-N13)*1440)
A14: S01 | B14: 태백 신규점 | C14: S01-H동 | D14: 측정 | E14: 동 | F14: 8 | L14: =IF(COUNT(I14:K14)=0,"",MEDIAN(I14:K14)) | M14: =IF(COUNTIFS($C:$C,$C14,$D:$D,"P0(전)",$L:$L,">0")<>1,"P0(전) 유효 1개 아님",IF(COUNTIFS($C:$C,$C14,$D:$D,"P0(후)",$L:$L,">0")<>1,"P0(후) 유효 1개 아님",IF(NOT(AND(ISNUMBER(N14),ISNUMBER(P14),ISNUMBER(H14))),"시각 결측",IF(P14<=N14,"P0 시각 역전",IF(OR(H14<N14,H14>P14),"측정시각 구간 밖","OK"))))) | N14: =IF(COUNTIFS($C:$C,$C14,$D:$D,"P0(전)",$L:$L,">0")<>1,"",SUMIFS($H:$H,$C:$C,$C14,$D:$D,"P0(전)")) | O14: =IF(COUNTIFS($C:$C,$C14,$D:$D,"P0(전)",$L:$L,">0")<>1,"",SUMIFS($L:$L,$C:$C,$C14,$D:$D,"P0(전)")) | P14: =IF(COUNTIFS($C:$C,$C14,$D:$D,"P0(후)",$L:$L,">0")<>1,"",SUMIFS($H:$H,$C:$C,$C14,$D:$D,"P0(후)")) | Q14: =IF(COUNTIFS($C:$C,$C14,$D:$D,"P0(후)",$L:$L,">0")<>1,"",SUMIFS($L:$L,$C:$C,$C14,$D:$D,"P0(후)")) | R14: =IF(M14<>"OK","",O14+(Q14-O14)*(H14-N14)/(P14-N14)) | S14: =IF(OR(M14<>"OK",NOT(ISNUMBER(L14))),"",L14-R14) | T14: =IF(OR(NOT(ISNUMBER(S14)),IF(ISNUMBER(G14),G14,F14)=0),"",S14/IF(ISNUMBER(G14),G14,F14)) | U14: =IF(ISNUMBER(T14),ABS(T14),"") | V14: =IF(OR($D13<>"측정",$C13<>$C14,NOT(ISNUMBER(L14)),NOT(ISNUMBER(L13)),(IF(ISNUMBER(G14),G14,F14)-IF(ISNUMBER(G13),G13,F13))=0),"",(L14-L13)/(IF(ISNUMBER(G14),G14,F14)-IF(ISNUMBER(G13),G13,F13))) | W14: =IF(NOT(AND(ISNUMBER(N14),ISNUMBER(P14))),"",(P14-N14)*1440)
A15: S01 | B15: 태백 신규점 | C15: S01-H동 | D15: 측정 | E15: 동 | F15: 9 | L15: =IF(COUNT(I15:K15)=0,"",MEDIAN(I15:K15)) | M15: =IF(COUNTIFS($C:$C,$C15,$D:$D,"P0(전)",$L:$L,">0")<>1,"P0(전) 유효 1개 아님",IF(COUNTIFS($C:$C,$C15,$D:$D,"P0(후)",$L:$L,">0")<>1,"P0(후) 유효 1개 아님",IF(NOT(AND(ISNUMBER(N15),ISNUMBER(P15),ISNUMBER(H15))),"시각 결측",IF(P15<=N15,"P0 시각 역전",IF(OR(H15<N15,H15>P15),"측정시각 구간 밖","OK"))))) | N15: =IF(COUNTIFS($C:$C,$C15,$D:$D,"P0(전)",$L:$L,">0")<>1,"",SUMIFS($H:$H,$C:$C,$C15,$D:$D,"P0(전)")) | O15: =IF(COUNTIFS($C:$C,$C15,$D:$D,"P0(전)",$L:$L,">0")<>1,"",SUMIFS($L:$L,$C:$C,$C15,$D:$D,"P0(전)")) | P15: =IF(COUNTIFS($C:$C,$C15,$D:$D,"P0(후)",$L:$L,">0")<>1,"",SUMIFS($H:$H,$C:$C,$C15,$D:$D,"P0(후)")) | Q15: =IF(COUNTIFS($C:$C,$C15,$D:$D,"P0(후)",$L:$L,">0")<>1,"",SUMIFS($L:$L,$C:$C,$C15,$D:$D,"P0(후)")) | R15: =IF(M15<>"OK","",O15+(Q15-O15)*(H15-N15)/(P15-N15)) | S15: =IF(OR(M15<>"OK",NOT(ISNUMBER(L15))),"",L15-R15) | T15: =IF(OR(NOT(ISNUMBER(S15)),IF(ISNUMBER(G15),G15,F15)=0),"",S15/IF(ISNUMBER(G15),G15,F15)) | U15: =IF(ISNUMBER(T15),ABS(T15),"") | V15: =IF(OR($D14<>"측정",$C14<>$C15,NOT(ISNUMBER(L15)),NOT(ISNUMBER(L14)),(IF(ISNUMBER(G15),G15,F15)-IF(ISNUMBER(G14),G14,F14))=0),"",(L15-L14)/(IF(ISNUMBER(G15),G15,F15)-IF(ISNUMBER(G14),G14,F14))) | W15: =IF(NOT(AND(ISNUMBER(N15),ISNUMBER(P15))),"",(P15-N15)*1440)
A16: S01 | B16: 태백 신규점 | C16: S01-H동 | D16: 측정 | E16: 동 | F16: 10 | L16: =IF(COUNT(I16:K16)=0,"",MEDIAN(I16:K16)) | M16: =IF(COUNTIFS($C:$C,$C16,$D:$D,"P0(전)",$L:$L,">0")<>1,"P0(전) 유효 1개 아님",IF(COUNTIFS($C:$C,$C16,$D:$D,"P0(후)",$L:$L,">0")<>1,"P0(후) 유효 1개 아님",IF(NOT(AND(ISNUMBER(N16),ISNUMBER(P16),ISNUMBER(H16))),"시각 결측",IF(P16<=N16,"P0 시각 역전",IF(OR(H16<N16,H16>P16),"측정시각 구간 밖","OK"))))) | N16: =IF(COUNTIFS($C:$C,$C16,$D:$D,"P0(전)",$L:$L,">0")<>1,"",SUMIFS($H:$H,$C:$C,$C16,$D:$D,"P0(전)")) | O16: =IF(COUNTIFS($C:$C,$C16,$D:$D,"P0(전)",$L:$L,">0")<>1,"",SUMIFS($L:$L,$C:$C,$C16,$D:$D,"P0(전)")) | P16: =IF(COUNTIFS($C:$C,$C16,$D:$D,"P0(후)",$L:$L,">0")<>1,"",SUMIFS($H:$H,$C:$C,$C16,$D:$D,"P0(후)")) | Q16: =IF(COUNTIFS($C:$C,$C16,$D:$D,"P0(후)",$L:$L,">0")<>1,"",SUMIFS($L:$L,$C:$C,$C16,$D:$D,"P0(후)")) | R16: =IF(M16<>"OK","",O16+(Q16-O16)*(H16-N16)/(P16-N16)) | S16: =IF(OR(M16<>"OK",NOT(ISNUMBER(L16))),"",L16-R16) | T16: =IF(OR(NOT(ISNUMBER(S16)),IF(ISNUMBER(G16),G16,F16)=0),"",S16/IF(ISNUMBER(G16),G16,F16)) | U16: =IF(ISNUMBER(T16),ABS(T16),"") | V16: =IF(OR($D15<>"측정",$C15<>$C16,NOT(ISNUMBER(L16)),NOT(ISNUMBER(L15)),(IF(ISNUMBER(G16),G16,F16)-IF(ISNUMBER(G15),G15,F15))=0),"",(L16-L15)/(IF(ISNUMBER(G16),G16,F16)-IF(ISNUMBER(G15),G15,F15))) | W16: =IF(NOT(AND(ISNUMBER(N16),ISNUMBER(P16))),"",(P16-N16)*1440)
A17: S01 | B17: 태백 신규점 | C17: S01-H동 | D17: P0(후) | E17: 동 | L17: =IF(COUNT(I17:K17)=0,"",MEDIAN(I17:K17))
A18: S01 | B18: 태백 신규점 | C18: S01-H서 | D18: P0(전) | E18: 서 | L18: =IF(COUNT(I18:K18)=0,"",MEDIAN(I18:K18))
A19: S01 | B19: 태백 신규점 | C19: S01-H서 | D19: 측정 | E19: 서 | F19: 0.5 | L19: =IF(COUNT(I19:K19)=0,"",MEDIAN(I19:K19)) | M19: =IF(COUNTIFS($C:$C,$C19,$D:$D,"P0(전)",$L:$L,">0")<>1,"P0(전) 유효 1개 아님",IF(COUNTIFS($C:$C,$C19,$D:$D,"P0(후)",$L:$L,">0")<>1,"P0(후) 유효 1개 아님",IF(NOT(AND(ISNUMBER(N19),ISNUMBER(P19),ISNUMBER(H19))),"시각 결측",IF(P19<=N19,"P0 시각 역전",IF(OR(H19<N19,H19>P19),"측정시각 구간 밖","OK"))))) | N19: =IF(COUNTIFS($C:$C,$C19,$D:$D,"P0(전)",$L:$L,">0")<>1,"",SUMIFS($H:$H,$C:$C,$C19,$D:$D,"P0(전)")) | O19: =IF(COUNTIFS($C:$C,$C19,$D:$D,"P0(전)",$L:$L,">0")<>1,"",SUMIFS($L:$L,$C:$C,$C19,$D:$D,"P0(전)")) | P19: =IF(COUNTIFS($C:$C,$C19,$D:$D,"P0(후)",$L:$L,">0")<>1,"",SUMIFS($H:$H,$C:$C,$C19,$D:$D,"P0(후)")) | Q19: =IF(COUNTIFS($C:$C,$C19,$D:$D,"P0(후)",$L:$L,">0")<>1,"",SUMIFS($L:$L,$C:$C,$C19,$D:$D,"P0(후)")) | R19: =IF(M19<>"OK","",O19+(Q19-O19)*(H19-N19)/(P19-N19)) | S19: =IF(OR(M19<>"OK",NOT(ISNUMBER(L19))),"",L19-R19) | T19: =IF(OR(NOT(ISNUMBER(S19)),IF(ISNUMBER(G19),G19,F19)=0),"",S19/IF(ISNUMBER(G19),G19,F19)) | U19: =IF(ISNUMBER(T19),ABS(T19),"") | V19: =IF(OR($D18<>"측정",$C18<>$C19,NOT(ISNUMBER(L19)),NOT(ISNUMBER(L18)),(IF(ISNUMBER(G19),G19,F19)-IF(ISNUMBER(G18),G18,F18))=0),"",(L19-L18)/(IF(ISNUMBER(G19),G19,F19)-IF(ISNUMBER(G18),G18,F18))) | W19: =IF(NOT(AND(ISNUMBER(N19),ISNUMBER(P19))),"",(P19-N19)*1440)
A20: S01 | B20: 태백 신규점 | C20: S01-H서 | D20: 측정 | E20: 서 | F20: 1 | L20: =IF(COUNT(I20:K20)=0,"",MEDIAN(I20:K20)) | M20: =IF(COUNTIFS($C:$C,$C20,$D:$D,"P0(전)",$L:$L,">0")<>1,"P0(전) 유효 1개 아님",IF(COUNTIFS($C:$C,$C20,$D:$D,"P0(후)",$L:$L,">0")<>1,"P0(후) 유효 1개 아님",IF(NOT(AND(ISNUMBER(N20),ISNUMBER(P20),ISNUMBER(H20))),"시각 결측",IF(P20<=N20,"P0 시각 역전",IF(OR(H20<N20,H20>P20),"측정시각 구간 밖","OK"))))) | N20: =IF(COUNTIFS($C:$C,$C20,$D:$D,"P0(전)",$L:$L,">0")<>1,"",SUMIFS($H:$H,$C:$C,$C20,$D:$D,"P0(전)")) | O20: =IF(COUNTIFS($C:$C,$C20,$D:$D,"P0(전)",$L:$L,">0")<>1,"",SUMIFS($L:$L,$C:$C,$C20,$D:$D,"P0(전)")) | P20: =IF(COUNTIFS($C:$C,$C20,$D:$D,"P0(후)",$L:$L,">0")<>1,"",SUMIFS($H:$H,$C:$C,$C20,$D:$D,"P0(후)")) | Q20: =IF(COUNTIFS($C:$C,$C20,$D:$D,"P0(후)",$L:$L,">0")<>1,"",SUMIFS($L:$L,$C:$C,$C20,$D:$D,"P0(후)")) | R20: =IF(M20<>"OK","",O20+(Q20-O20)*(H20-N20)/(P20-N20)) | S20: =IF(OR(M20<>"OK",NOT(ISNUMBER(L20))),"",L20-R20) | T20: =IF(OR(NOT(ISNUMBER(S20)),IF(ISNUMBER(G20),G20,F20)=0),"",S20/IF(ISNUMBER(G20),G20,F20)) | U20: =IF(ISNUMBER(T20),ABS(T20),"") | V20: =IF(OR($D19<>"측정",$C19<>$C20,NOT(ISNUMBER(L20)),NOT(ISNUMBER(L19)),(IF(ISNUMBER(G20),G20,F20)-IF(ISNUMBER(G19),G19,F19))=0),"",(L20-L19)/(IF(ISNUMBER(G20),G20,F20)-IF(ISNUMBER(G19),G19,F19))) | W20: =IF(NOT(AND(ISNUMBER(N20),ISNUMBER(P20))),"",(P20-N20)*1440)
A21: S01 | B21: 태백 신규점 | C21: S01-H서 | D21: 측정 | E21: 서 | F21: 2 | L21: =IF(COUNT(I21:K21)=0,"",MEDIAN(I21:K21)) | M21: =IF(COUNTIFS($C:$C,$C21,$D:$D,"P0(전)",$L:$L,">0")<>1,"P0(전) 유효 1개 아님",IF(COUNTIFS($C:$C,$C21,$D:$D,"P0(후)",$L:$L,">0")<>1,"P0(후) 유효 1개 아님",IF(NOT(AND(ISNUMBER(N21),ISNUMBER(P21),ISNUMBER(H21))),"시각 결측",IF(P21<=N21,"P0 시각 역전",IF(OR(H21<N21,H21>P21),"측정시각 구간 밖","OK"))))) | N21: =IF(COUNTIFS($C:$C,$C21,$D:$D,"P0(전)",$L:$L,">0")<>1,"",SUMIFS($H:$H,$C:$C,$C21,$D:$D,"P0(전)")) | O21: =IF(COUNTIFS($C:$C,$C21,$D:$D,"P0(전)",$L:$L,">0")<>1,"",SUMIFS($L:$L,$C:$C,$C21,$D:$D,"P0(전)")) | P21: =IF(COUNTIFS($C:$C,$C21,$D:$D,"P0(후)",$L:$L,">0")<>1,"",SUMIFS($H:$H,$C:$C,$C21,$D:$D,"P0(후)")) | Q21: =IF(COUNTIFS($C:$C,$C21,$D:$D,"P0(후)",$L:$L,">0")<>1,"",SUMIFS($L:$L,$C:$C,$C21,$D:$D,"P0(후)")) | R21: =IF(M21<>"OK","",O21+(Q21-O21)*(H21-N21)/(P21-N21)) | S21: =IF(OR(M21<>"OK",NOT(ISNUMBER(L21))),"",L21-R21) | T21: =IF(OR(NOT(ISNUMBER(S21)),IF(ISNUMBER(G21),G21,F21)=0),"",S21/IF(ISNUMBER(G21),G21,F21)) | U21: =IF(ISNUMBER(T21),ABS(T21),"") | V21: =IF(OR($D20<>"측정",$C20<>$C21,NOT(ISNUMBER(L21)),NOT(ISNUMBER(L20)),(IF(ISNUMBER(G21),G21,F21)-IF(ISNUMBER(G20),G20,F20))=0),"",(L21-L20)/(IF(ISNUMBER(G21),G21,F21)-IF(ISNUMBER(G20),G20,F20))) | W21: =IF(NOT(AND(ISNUMBER(N21),ISNUMBER(P21))),"",(P21-N21)*1440)
A22: S01 | B22: 태백 신규점 | C22: S01-H서 | D22: 측정 | E22: 서 | F22: 3 | L22: =IF(COUNT(I22:K22)=0,"",MEDIAN(I22:K22)) | M22: =IF(COUNTIFS($C:$C,$C22,$D:$D,"P0(전)",$L:$L,">0")<>1,"P0(전) 유효 1개 아님",IF(COUNTIFS($C:$C,$C22,$D:$D,"P0(후)",$L:$L,">0")<>1,"P0(후) 유효 1개 아님",IF(NOT(AND(ISNUMBER(N22),ISNUMBER(P22),ISNUMBER(H22))),"시각 결측",IF(P22<=N22,"P0 시각 역전",IF(OR(H22<N22,H22>P22),"측정시각 구간 밖","OK"))))) | N22: =IF(COUNTIFS($C:$C,$C22,$D:$D,"P0(전)",$L:$L,">0")<>1,"",SUMIFS($H:$H,$C:$C,$C22,$D:$D,"P0(전)")) | O22: =IF(COUNTIFS($C:$C,$C22,$D:$D,"P0(전)",$L:$L,">0")<>1,"",SUMIFS($L:$L,$C:$C,$C22,$D:$D,"P0(전)")) | P22: =IF(COUNTIFS($C:$C,$C22,$D:$D,"P0(후)",$L:$L,">0")<>1,"",SUMIFS($H:$H,$C:$C,$C22,$D:$D,"P0(후)")) | Q22: =IF(COUNTIFS($C:$C,$C22,$D:$D,"P0(후)",$L:$L,">0")<>1,"",SUMIFS($L:$L,$C:$C,$C22,$D:$D,"P0(후)")) | R22: =IF(M22<>"OK","",O22+(Q22-O22)*(H22-N22)/(P22-N22)) | S22: =IF(OR(M22<>"OK",NOT(ISNUMBER(L22))),"",L22-R22) | T22: =IF(OR(NOT(ISNUMBER(S22)),IF(ISNUMBER(G22),G22,F22)=0),"",S22/IF(ISNUMBER(G22),G22,F22)) | U22: =IF(ISNUMBER(T22),ABS(T22),"") | V22: =IF(OR($D21<>"측정",$C21<>$C22,NOT(ISNUMBER(L22)),NOT(ISNUMBER(L21)),(IF(ISNUMBER(G22),G22,F22)-IF(ISNUMBER(G21),G21,F21))=0),"",(L22-L21)/(IF(ISNUMBER(G22),G22,F22)-IF(ISNUMBER(G21),G21,F21))) | W22: =IF(NOT(AND(ISNUMBER(N22),ISNUMBER(P22))),"",(P22-N22)*1440)
A23: S01 | B23: 태백 신규점 | C23: S01-H서 | D23: 측정 | E23: 서 | F23: 4 | L23: =IF(COUNT(I23:K23)=0,"",MEDIAN(I23:K23)) | M23: =IF(COUNTIFS($C:$C,$C23,$D:$D,"P0(전)",$L:$L,">0")<>1,"P0(전) 유효 1개 아님",IF(COUNTIFS($C:$C,$C23,$D:$D,"P0(후)",$L:$L,">0")<>1,"P0(후) 유효 1개 아님",IF(NOT(AND(ISNUMBER(N23),ISNUMBER(P23),ISNUMBER(H23))),"시각 결측",IF(P23<=N23,"P0 시각 역전",IF(OR(H23<N23,H23>P23),"측정시각 구간 밖","OK"))))) | N23: =IF(COUNTIFS($C:$C,$C23,$D:$D,"P0(전)",$L:$L,">0")<>1,"",SUMIFS($H:$H,$C:$C,$C23,$D:$D,"P0(전)")) | O23: =IF(COUNTIFS($C:$C,$C23,$D:$D,"P0(전)",$L:$L,">0")<>1,"",SUMIFS($L:$L,$C:$C,$C23,$D:$D,"P0(전)")) | P23: =IF(COUNTIFS($C:$C,$C23,$D:$D,"P0(후)",$L:$L,">0")<>1,"",SUMIFS($H:$H,$C:$C,$C23,$D:$D,"P0(후)")) | Q23: =IF(COUNTIFS($C:$C,$C23,$D:$D,"P0(후)",$L:$L,">0")<>1,"",SUMIFS($L:$L,$C:$C,$C23,$D:$D,"P0(후)")) | R23: =IF(M23<>"OK","",O23+(Q23-O23)*(H23-N23)/(P23-N23)) | S23: =IF(OR(M23<>"OK",NOT(ISNUMBER(L23))),"",L23-R23) | T23: =IF(OR(NOT(ISNUMBER(S23)),IF(ISNUMBER(G23),G23,F23)=0),"",S23/IF(ISNUMBER(G23),G23,F23)) | U23: =IF(ISNUMBER(T23),ABS(T23),"") | V23: =IF(OR($D22<>"측정",$C22<>$C23,NOT(ISNUMBER(L23)),NOT(ISNUMBER(L22)),(IF(ISNUMBER(G23),G23,F23)-IF(ISNUMBER(G22),G22,F22))=0),"",(L23-L22)/(IF(ISNUMBER(G23),G23,F23)-IF(ISNUMBER(G22),G22,F22))) | W23: =IF(NOT(AND(ISNUMBER(N23),ISNUMBER(P23))),"",(P23-N23)*1440)
A24: S01 | B24: 태백 신규점 | C24: S01-H서 | D24: 측정 | E24: 서 | F24: 5 | L24: =IF(COUNT(I24:K24)=0,"",MEDIAN(I24:K24)) | M24: =IF(COUNTIFS($C:$C,$C24,$D:$D,"P0(전)",$L:$L,">0")<>1,"P0(전) 유효 1개 아님",IF(COUNTIFS($C:$C,$C24,$D:$D,"P0(후)",$L:$L,">0")<>1,"P0(후) 유효 1개 아님",IF(NOT(AND(ISNUMBER(N24),ISNUMBER(P24),ISNUMBER(H24))),"시각 결측",IF(P24<=N24,"P0 시각 역전",IF(OR(H24<N24,H24>P24),"측정시각 구간 밖","OK"))))) | N24: =IF(COUNTIFS($C:$C,$C24,$D:$D,"P0(전)",$L:$L,">0")<>1,"",SUMIFS($H:$H,$C:$C,$C24,$D:$D,"P0(전)")) | O24: =IF(COUNTIFS($C:$C,$C24,$D:$D,"P0(전)",$L:$L,">0")<>1,"",SUMIFS($L:$L,$C:$C,$C24,$D:$D,"P0(전)")) | P24: =IF(COUNTIFS($C:$C,$C24,$D:$D,"P0(후)",$L:$L,">0")<>1,"",SUMIFS($H:$H,$C:$C,$C24,$D:$D,"P0(후)")) | Q24: =IF(COUNTIFS($C:$C,$C24,$D:$D,"P0(후)",$L:$L,">0")<>1,"",SUMIFS($L:$L,$C:$C,$C24,$D:$D,"P0(후)")) | R24: =IF(M24<>"OK","",O24+(Q24-O24)*(H24-N24)/(P24-N24)) | S24: =IF(OR(M24<>"OK",NOT(ISNUMBER(L24))),"",L24-R24) | T24: =IF(OR(NOT(ISNUMBER(S24)),IF(ISNUMBER(G24),G24,F24)=0),"",S24/IF(ISNUMBER(G24),G24,F24)) | U24: =IF(ISNUMBER(T24),ABS(T24),"") | V24: =IF(OR($D23<>"측정",$C23<>$C24,NOT(ISNUMBER(L24)),NOT(ISNUMBER(L23)),(IF(ISNUMBER(G24),G24,F24)-IF(ISNUMBER(G23),G23,F23))=0),"",(L24-L23)/(IF(ISNUMBER(G24),G24,F24)-IF(ISNUMBER(G23),G23,F23))) | W24: =IF(NOT(AND(ISNUMBER(N24),ISNUMBER(P24))),"",(P24-N24)*1440)
A25: S01 | B25: 태백 신규점 | C25: S01-H서 | D25: 측정 | E25: 서 | F25: 6 | L25: =IF(COUNT(I25:K25)=0,"",MEDIAN(I25:K25)) | M25: =IF(COUNTIFS($C:$C,$C25,$D:$D,"P0(전)",$L:$L,">0")<>1,"P0(전) 유효 1개 아님",IF(COUNTIFS($C:$C,$C25,$D:$D,"P0(후)",$L:$L,">0")<>1,"P0(후) 유효 1개 아님",IF(NOT(AND(ISNUMBER(N25),ISNUMBER(P25),ISNUMBER(H25))),"시각 결측",IF(P25<=N25,"P0 시각 역전",IF(OR(H25<N25,H25>P25),"측정시각 구간 밖","OK"))))) | N25: =IF(COUNTIFS($C:$C,$C25,$D:$D,"P0(전)",$L:$L,">0")<>1,"",SUMIFS($H:$H,$C:$C,$C25,$D:$D,"P0(전)")) | O25: =IF(COUNTIFS($C:$C,$C25,$D:$D,"P0(전)",$L:$L,">0")<>1,"",SUMIFS($L:$L,$C:$C,$C25,$D:$D,"P0(전)")) | P25: =IF(COUNTIFS($C:$C,$C25,$D:$D,"P0(후)",$L:$L,">0")<>1,"",SUMIFS($H:$H,$C:$C,$C25,$D:$D,"P0(후)")) | Q25: =IF(COUNTIFS($C:$C,$C25,$D:$D,"P0(후)",$L:$L,">0")<>1,"",SUMIFS($L:$L,$C:$C,$C25,$D:$D,"P0(후)")) | R25: =IF(M25<>"OK","",O25+(Q25-O25)*(H25-N25)/(P25-N25)) | S25: =IF(OR(M25<>"OK",NOT(ISNUMBER(L25))),"",L25-R25) | T25: =IF(OR(NOT(ISNUMBER(S25)),IF(ISNUMBER(G25),G25,F25)=0),"",S25/IF(ISNUMBER(G25),G25,F25)) | U25: =IF(ISNUMBER(T25),ABS(T25),"") | V25: =IF(OR($D24<>"측정",$C24<>$C25,NOT(ISNUMBER(L25)),NOT(ISNUMBER(L24)),(IF(ISNUMBER(G25),G25,F25)-IF(ISNUMBER(G24),G24,F24))=0),"",(L25-L24)/(IF(ISNUMBER(G25),G25,F25)-IF(ISNUMBER(G24),G24,F24))) | W25: =IF(NOT(AND(ISNUMBER(N25),ISNUMBER(P25))),"",(P25-N25)*1440)
A26: S01 | B26: 태백 신규점 | C26: S01-H서 | D26: 측정 | E26: 서 | F26: 7 | L26: =IF(COUNT(I26:K26)=0,"",MEDIAN(I26:K26)) | M26: =IF(COUNTIFS($C:$C,$C26,$D:$D,"P0(전)",$L:$L,">0")<>1,"P0(전) 유효 1개 아님",IF(COUNTIFS($C:$C,$C26,$D:$D,"P0(후)",$L:$L,">0")<>1,"P0(후) 유효 1개 아님",IF(NOT(AND(ISNUMBER(N26),ISNUMBER(P26),ISNUMBER(H26))),"시각 결측",IF(P26<=N26,"P0 시각 역전",IF(OR(H26<N26,H26>P26),"측정시각 구간 밖","OK"))))) | N26: =IF(COUNTIFS($C:$C,$C26,$D:$D,"P0(전)",$L:$L,">0")<>1,"",SUMIFS($H:$H,$C:$C,$C26,$D:$D,"P0(전)")) | O26: =IF(COUNTIFS($C:$C,$C26,$D:$D,"P0(전)",$L:$L,">0")<>1,"",SUMIFS($L:$L,$C:$C,$C26,$D:$D,"P0(전)")) | P26: =IF(COUNTIFS($C:$C,$C26,$D:$D,"P0(후)",$L:$L,">0")<>1,"",SUMIFS($H:$H,$C:$C,$C26,$D:$D,"P0(후)")) | Q26: =IF(COUNTIFS($C:$C,$C26,$D:$D,"P0(후)",$L:$L,">0")<>1,"",SUMIFS($L:$L,$C:$C,$C26,$D:$D,"P0(후)")) | R26: =IF(M26<>"OK","",O26+(Q26-O26)*(H26-N26)/(P26-N26)) | S26: =IF(OR(M26<>"OK",NOT(ISNUMBER(L26))),"",L26-R26) | T26: =IF(OR(NOT(ISNUMBER(S26)),IF(ISNUMBER(G26),G26,F26)=0),"",S26/IF(ISNUMBER(G26),G26,F26)) | U26: =IF(ISNUMBER(T26),ABS(T26),"") | V26: =IF(OR($D25<>"측정",$C25<>$C26,NOT(ISNUMBER(L26)),NOT(ISNUMBER(L25)),(IF(ISNUMBER(G26),G26,F26)-IF(ISNUMBER(G25),G25,F25))=0),"",(L26-L25)/(IF(ISNUMBER(G26),G26,F26)-IF(ISNUMBER(G25),G25,F25))) | W26: =IF(NOT(AND(ISNUMBER(N26),ISNUMBER(P26))),"",(P26-N26)*1440)
A27: S01 | B27: 태백 신규점 | C27: S01-H서 | D27: 측정 | E27: 서 | F27: 8 | L27: =IF(COUNT(I27:K27)=0,"",MEDIAN(I27:K27)) | M27: =IF(COUNTIFS($C:$C,$C27,$D:$D,"P0(전)",$L:$L,">0")<>1,"P0(전) 유효 1개 아님",IF(COUNTIFS($C:$C,$C27,$D:$D,"P0(후)",$L:$L,">0")<>1,"P0(후) 유효 1개 아님",IF(NOT(AND(ISNUMBER(N27),ISNUMBER(P27),ISNUMBER(H27))),"시각 결측",IF(P27<=N27,"P0 시각 역전",IF(OR(H27<N27,H27>P27),"측정시각 구간 밖","OK"))))) | N27: =IF(COUNTIFS($C:$C,$C27,$D:$D,"P0(전)",$L:$L,">0")<>1,"",SUMIFS($H:$H,$C:$C,$C27,$D:$D,"P0(전)")) | O27: =IF(COUNTIFS($C:$C,$C27,$D:$D,"P0(전)",$L:$L,">0")<>1,"",SUMIFS($L:$L,$C:$C,$C27,$D:$D,"P0(전)")) | P27: =IF(COUNTIFS($C:$C,$C27,$D:$D,"P0(후)",$L:$L,">0")<>1,"",SUMIFS($H:$H,$C:$C,$C27,$D:$D,"P0(후)")) | Q27: =IF(COUNTIFS($C:$C,$C27,$D:$D,"P0(후)",$L:$L,">0")<>1,"",SUMIFS($L:$L,$C:$C,$C27,$D:$D,"P0(후)")) | R27: =IF(M27<>"OK","",O27+(Q27-O27)*(H27-N27)/(P27-N27)) | S27: =IF(OR(M27<>"OK",NOT(ISNUMBER(L27))),"",L27-R27) | T27: =IF(OR(NOT(ISNUMBER(S27)),IF(ISNUMBER(G27),G27,F27)=0),"",S27/IF(ISNUMBER(G27),G27,F27)) | U27: =IF(ISNUMBER(T27),ABS(T27),"") | V27: =IF(OR($D26<>"측정",$C26<>$C27,NOT(ISNUMBER(L27)),NOT(ISNUMBER(L26)),(IF(ISNUMBER(G27),G27,F27)-IF(ISNUMBER(G26),G26,F26))=0),"",(L27-L26)/(IF(ISNUMBER(G27),G27,F27)-IF(ISNUMBER(G26),G26,F26))) | W27: =IF(NOT(AND(ISNUMBER(N27),ISNUMBER(P27))),"",(P27-N27)*1440)
A28: S01 | B28: 태백 신규점 | C28: S01-H서 | D28: 측정 | E28: 서 | F28: 9 | L28: =IF(COUNT(I28:K28)=0,"",MEDIAN(I28:K28)) | M28: =IF(COUNTIFS($C:$C,$C28,$D:$D,"P0(전)",$L:$L,">0")<>1,"P0(전) 유효 1개 아님",IF(COUNTIFS($C:$C,$C28,$D:$D,"P0(후)",$L:$L,">0")<>1,"P0(후) 유효 1개 아님",IF(NOT(AND(ISNUMBER(N28),ISNUMBER(P28),ISNUMBER(H28))),"시각 결측",IF(P28<=N28,"P0 시각 역전",IF(OR(H28<N28,H28>P28),"측정시각 구간 밖","OK"))))) | N28: =IF(COUNTIFS($C:$C,$C28,$D:$D,"P0(전)",$L:$L,">0")<>1,"",SUMIFS($H:$H,$C:$C,$C28,$D:$D,"P0(전)")) | O28: =IF(COUNTIFS($C:$C,$C28,$D:$D,"P0(전)",$L:$L,">0")<>1,"",SUMIFS($L:$L,$C:$C,$C28,$D:$D,"P0(전)")) | P28: =IF(COUNTIFS($C:$C,$C28,$D:$D,"P0(후)",$L:$L,">0")<>1,"",SUMIFS($H:$H,$C:$C,$C28,$D:$D,"P0(후)")) | Q28: =IF(COUNTIFS($C:$C,$C28,$D:$D,"P0(후)",$L:$L,">0")<>1,"",SUMIFS($L:$L,$C:$C,$C28,$D:$D,"P0(후)")) | R28: =IF(M28<>"OK","",O28+(Q28-O28)*(H28-N28)/(P28-N28)) | S28: =IF(OR(M28<>"OK",NOT(ISNUMBER(L28))),"",L28-R28) | T28: =IF(OR(NOT(ISNUMBER(S28)),IF(ISNUMBER(G28),G28,F28)=0),"",S28/IF(ISNUMBER(G28),G28,F28)) | U28: =IF(ISNUMBER(T28),ABS(T28),"") | V28: =IF(OR($D27<>"측정",$C27<>$C28,NOT(ISNUMBER(L28)),NOT(ISNUMBER(L27)),(IF(ISNUMBER(G28),G28,F28)-IF(ISNUMBER(G27),G27,F27))=0),"",(L28-L27)/(IF(ISNUMBER(G28),G28,F28)-IF(ISNUMBER(G27),G27,F27))) | W28: =IF(NOT(AND(ISNUMBER(N28),ISNUMBER(P28))),"",(P28-N28)*1440)
A29: S01 | B29: 태백 신규점 | C29: S01-H서 | D29: 측정 | E29: 서 | F29: 10 | L29: =IF(COUNT(I29:K29)=0,"",MEDIAN(I29:K29)) | M29: =IF(COUNTIFS($C:$C,$C29,$D:$D,"P0(전)",$L:$L,">0")<>1,"P0(전) 유효 1개 아님",IF(COUNTIFS($C:$C,$C29,$D:$D,"P0(후)",$L:$L,">0")<>1,"P0(후) 유효 1개 아님",IF(NOT(AND(ISNUMBER(N29),ISNUMBER(P29),ISNUMBER(H29))),"시각 결측",IF(P29<=N29,"P0 시각 역전",IF(OR(H29<N29,H29>P29),"측정시각 구간 밖","OK"))))) | N29: =IF(COUNTIFS($C:$C,$C29,$D:$D,"P0(전)",$L:$L,">0")<>1,"",SUMIFS($H:$H,$C:$C,$C29,$D:$D,"P0(전)")) | O29: =IF(COUNTIFS($C:$C,$C29,$D:$D,"P0(전)",$L:$L,">0")<>1,"",SUMIFS($L:$L,$C:$C,$C29,$D:$D,"P0(전)")) | P29: =IF(COUNTIFS($C:$C,$C29,$D:$D,"P0(후)",$L:$L,">0")<>1,"",SUMIFS($H:$H,$C:$C,$C29,$D:$D,"P0(후)")) | Q29: =IF(COUNTIFS($C:$C,$C29,$D:$D,"P0(후)",$L:$L,">0")<>1,"",SUMIFS($L:$L,$C:$C,$C29,$D:$D,"P0(후)")) | R29: =IF(M29<>"OK","",O29+(Q29-O29)*(H29-N29)/(P29-N29)) | S29: =IF(OR(M29<>"OK",NOT(ISNUMBER(L29))),"",L29-R29) | T29: =IF(OR(NOT(ISNUMBER(S29)),IF(ISNUMBER(G29),G29,F29)=0),"",S29/IF(ISNUMBER(G29),G29,F29)) | U29: =IF(ISNUMBER(T29),ABS(T29),"") | V29: =IF(OR($D28<>"측정",$C28<>$C29,NOT(ISNUMBER(L29)),NOT(ISNUMBER(L28)),(IF(ISNUMBER(G29),G29,F29)-IF(ISNUMBER(G28),G28,F28))=0),"",(L29-L28)/(IF(ISNUMBER(G29),G29,F29)-IF(ISNUMBER(G28),G28,F28))) | W29: =IF(NOT(AND(ISNUMBER(N29),ISNUMBER(P29))),"",(P29-N29)*1440)
A30: S01 | B30: 태백 신규점 | C30: S01-H서 | D30: P0(후) | E30: 서 | L30: =IF(COUNT(I30:K30)=0,"",MEDIAN(I30:K30))
A31: S01 | B31: 태백 신규점 | C31: S01-H남 | D31: P0(전) | E31: 남 | L31: =IF(COUNT(I31:K31)=0,"",MEDIAN(I31:K31))
A32: S01 | B32: 태백 신규점 | C32: S01-H남 | D32: 측정 | E32: 남 | F32: 0.5 | L32: =IF(COUNT(I32:K32)=0,"",MEDIAN(I32:K32)) | M32: =IF(COUNTIFS($C:$C,$C32,$D:$D,"P0(전)",$L:$L,">0")<>1,"P0(전) 유효 1개 아님",IF(COUNTIFS($C:$C,$C32,$D:$D,"P0(후)",$L:$L,">0")<>1,"P0(후) 유효 1개 아님",IF(NOT(AND(ISNUMBER(N32),ISNUMBER(P32),ISNUMBER(H32))),"시각 결측",IF(P32<=N32,"P0 시각 역전",IF(OR(H32<N32,H32>P32),"측정시각 구간 밖","OK"))))) | N32: =IF(COUNTIFS($C:$C,$C32,$D:$D,"P0(전)",$L:$L,">0")<>1,"",SUMIFS($H:$H,$C:$C,$C32,$D:$D,"P0(전)")) | O32: =IF(COUNTIFS($C:$C,$C32,$D:$D,"P0(전)",$L:$L,">0")<>1,"",SUMIFS($L:$L,$C:$C,$C32,$D:$D,"P0(전)")) | P32: =IF(COUNTIFS($C:$C,$C32,$D:$D,"P0(후)",$L:$L,">0")<>1,"",SUMIFS($H:$H,$C:$C,$C32,$D:$D,"P0(후)")) | Q32: =IF(COUNTIFS($C:$C,$C32,$D:$D,"P0(후)",$L:$L,">0")<>1,"",SUMIFS($L:$L,$C:$C,$C32,$D:$D,"P0(후)")) | R32: =IF(M32<>"OK","",O32+(Q32-O32)*(H32-N32)/(P32-N32)) | S32: =IF(OR(M32<>"OK",NOT(ISNUMBER(L32))),"",L32-R32) | T32: =IF(OR(NOT(ISNUMBER(S32)),IF(ISNUMBER(G32),G32,F32)=0),"",S32/IF(ISNUMBER(G32),G32,F32)) | U32: =IF(ISNUMBER(T32),ABS(T32),"") | V32: =IF(OR($D31<>"측정",$C31<>$C32,NOT(ISNUMBER(L32)),NOT(ISNUMBER(L31)),(IF(ISNUMBER(G32),G32,F32)-IF(ISNUMBER(G31),G31,F31))=0),"",(L32-L31)/(IF(ISNUMBER(G32),G32,F32)-IF(ISNUMBER(G31),G31,F31))) | W32: =IF(NOT(AND(ISNUMBER(N32),ISNUMBER(P32))),"",(P32-N32)*1440)
