Workbook
Name KpFix_01: '01_태백 신규점'!$AJ$1:$AJ$2
Name KpFix_01: '02_임계 신규점1'!$AJ$1:$AJ$2
Name KpFix_01: '03_예산 신규점2'!$AJ$1:$AJ$2
Name KpFix_01: '04_진안 신규점1'!$AJ$1:$AJ$2
Name KpFix_01: '05_무풍 신규점1'!$AJ$1:$AJ$2
Name KpFix_01: '06_길담 신규점'!$AJ$1:$AJ$2
Name KpFix_01: '07_남해 신규점1'!$AJ$1:$AJ$2
Name KpFix_01: '08_청일 신규점2'!$AJ$1:$AJ$2
Name KpFix_01: '09_어론 신규점'!$AJ$1:$AJ$2
Name KpFix_01: '10_예안 신규점1'!$AJ$1:$AJ$2
Name KpFix_01: '11_소천 신규점4'!$AJ$1:$AJ$2
Name KpFix_01: '12_순창 신규점'!$AJ$1:$AJ$2
Name KpFix_01: '13_순천 신규점'!$AJ$1:$AJ$2
Name KpFix_01: '14_청송 신규점1'!$AJ$1:$AJ$2
Name KpFix_01: '15_의성 신규점'!$AJ$1:$AJ$2
Name KpFix_01: '16_예천 신규점'!$AJ$1:$AJ$2
Name KpFix_01: '17_영양 신규점4'!$AJ$1:$AJ$2
Name KpFix_01: '18_통영 신규점'!$AJ$1:$AJ$2
Name KpFix_01: '19_오호 신규점'!$AJ$1:$AJ$2
Name KpFix_01: '20_보령 신규점2'!$AJ$1:$AJ$2
Name KpFix_01: '21_담양 신규점2'!$AJ$1:$AJ$2
Name KpFix_01: '22_완도 신규점'!$AJ$1:$AJ$2
Name KpFix_01: '23_덕산 신규점1'!$AJ$1:$AJ$2
Name KpFix_01: '24_회천 신규점2'!$AJ$1:$AJ$2
Name KpFix_01: '25_관리 신규점3'!$AJ$1:$AJ$2
Name KpFix_01: '26_고남 신규점2'!$AJ$1:$AJ$2
Name KpFix_01: '27_전의 신규점'!$AJ$1:$AJ$2
Name KpFix_01: '28_이원 신규점'!$AJ$1:$AJ$2
Name KpFix_01: '29_가야 신규점1'!$AJ$1:$AJ$2
Name KpFix_01: '30_창녕 신규점'!$AJ$1:$AJ$2
Name KpFix_01: '31_언양 신규점3'!$AJ$1:$AJ$2
Name KpFix_01: '32_함양 신규점'!$AJ$1:$AJ$2
Name KpFix_01: '33_문산 신규점'!$AJ$1:$AJ$2
Name KpFix_01: '34_부안 신규점'!$AJ$1:$AJ$2
Name KpFix_01: '35_상주'!$AJ$1:$AJ$2
Name KpFix_01: '36_미원'!$AJ$1:$AJ$2
Name KpFix_01: '37_부안'!$AJ$1:$AJ$2
Name KpFix_01: '38_강화'!$AJ$1:$AJ$2
Name KpFix_01: '39_언양'!$AJ$1:$AJ$2
Name KpFix_01: '40_남지'!$AJ$1:$AJ$2
Name KpFix_01: '41_거제'!$AJ$1:$AJ$2
Name KpFix_01: '42_조도'!$AJ$1:$AJ$2
Name KpFix_01: '43_포천'!$AJ$1:$AJ$2
Name KpFix_01: '44_성산'!$AJ$1:$AJ$2
Name KpFix_01: '45_여주'!$AJ$1:$AJ$2
Name KpFix_01: '46_화천'!$AJ$1:$AJ$2
Name KpFix_01: '47_봉평'!$AJ$1:$AJ$2
Name KpFix_01: '48_삼척'!$AJ$1:$AJ$2
Name KpFix_01: '49_제천'!$AJ$1:$AJ$2
Name KpFix_01: '50_함양'!$AJ$1:$AJ$2
Name KpPre27_01: '01_태백 신규점'!$AI$1:$AI$41
Name KpPre27_01: '02_임계 신규점1'!$AI$1:$AI$40
Name KpPre27_01: '03_예산 신규점2'!$AI$1:$AI$40
Name KpPre27_01: '04_진안 신규점1'!$AI$1:$AI$40
Name KpPre27_01: '05_무풍 신규점1'!$AI$1:$AI$40
Name KpPre27_01: '06_길담 신규점'!$AI$1:$AI$40
Name KpPre27_01: '07_남해 신규점1'!$AI$1:$AI$40
Name KpPre27_01: '08_청일 신규점2'!$AI$1:$AI$40
Name KpPre27_01: '09_어론 신규점'!$AI$1:$AI$40
Name KpPre27_01: '10_예안 신규점1'!$AI$1:$AI$40

Sheet ⑧a Kp 예보
A1: NOAA Kp 예보 조회 | U1: NOAA 3-day raw | W1: NOAA 27-day raw | Y1: 선택일 KST 시각 | Z1: Kp | AB1: 선택일 전후 UTC 날짜 | AC1: 일 최대 Kp
A2: ⑧ 시트 C열에 탐사일시를 한국시간(KST)으로 입력하면 E·F열이 자동 계산됩니다. 인터넷 연결 후 ‘데이터 > 모두 새로 고침’을 실행하십시오. | U2: :Product: 3-Day Forecast | W2: :Product: 27-day Space Weather Outlook Table 27DO.txt | Y2: =IF($B$4="","",TEXT(INT($B$4)+(ROW()-2)*3/24,"hh:mm")) -> 00:00 | Z2: =IF($B$4="",NA(),IF(AND(INT($B$4)+(ROW()-2)*3/24-9/24>=$A$12,INT($B$4)+(ROW()-2)*3/24-9/24<$B$35),INDEX($E$12:$E$35,MATCH(INT($B$4)+(ROW()-2)*3/24-9/24,$A$12:$A$35,1)),NA())) -> #N/A | AB2: =IF($B$4="","",TEXT(MAX($H$12,MIN(INT($B$4-9/24)-3,$H$38-6))+ROW()-2,"m/d")) -> 9/21 | AC2: =IF($B$4="",NA(),IFERROR(INDEX($I$12:$I$38,MATCH(MAX($H$12,MIN(INT($B$4-9/24)-3,$H$38-6))+ROW()-2,$H$12:$H$38,0)),NA())) -> 2
U3: :Issued: 2026 Sep 21 1230 UTC | W3: :Issued: 2026 Sep 21 0317 UTC | Y3: =IF($B$4="","",TEXT(INT($B$4)+(ROW()-2)*3/24,"hh:mm")) -> 03:00 | Z3: =IF($B$4="",NA(),IF(AND(INT($B$4)+(ROW()-2)*3/24-9/24>=$A$12,INT($B$4)+(ROW()-2)*3/24-9/24<$B$35),INDEX($E$12:$E$35,MATCH(INT($B$4)+(ROW()-2)*3/24-9/24,$A$12:$A$35,1)),NA())) -> #N/A | AB3: =IF($B$4="","",TEXT(MAX($H$12,MIN(INT($B$4-9/24)-3,$H$38-6))+ROW()-2,"m/d")) -> 9/22 | AC3: =IF($B$4="",NA(),IFERROR(INDEX($I$12:$I$38,MATCH(MAX($H$12,MIN(INT($B$4-9/24)-3,$H$38-6))+ROW()-2,$H$12:$H$38,0)),NA())) -> 2
A4: 조회 날짜·시각 (KST) | B4: 46279.547 | D4: 3일 예보 발행 (UTC) | E4: =IF($U$3="","미수신",MID($U$3,9,24)) -> 2026 Sep 21 1230 UTC | U4: # Prepared by the U.S. Dept. of Commerce, NOAA, Space Weather Prediction Center | W4: # Prepared by the US Dept. of Commerce, NOAA, Space Weather Prediction Center | Y4: =IF($B$4="","",TEXT(INT($B$4)+(ROW()-2)*3/24,"hh:mm")) -> 06:00 | Z4: =IF($B$4="",NA(),IF(AND(INT($B$4)+(ROW()-2)*3/24-9/24>=$A$12,INT($B$4)+(ROW()-2)*3/24-9/24<$B$35),INDEX($E$12:$E$35,MATCH(INT($B$4)+(ROW()-2)*3/24-9/24,$A$12:$A$35,1)),NA())) -> #N/A | AB4: =IF($B$4="","",TEXT(MAX($H$12,MIN(INT($B$4-9/24)-3,$H$38-6))+ROW()-2,"m/d")) -> 9/23 | AC4: =IF($B$4="",NA(),IFERROR(INDEX($I$12:$I$38,MATCH(MAX($H$12,MIN(INT($B$4-9/24)-3,$H$38-6))+ROW()-2,$H$12:$H$38,0)),NA())) -> 2
A5: UTC 환산 | B5: =IF(B4="","",B4-9/24) -> 46279.172 | D5: 27일 예보 발행 (UTC) | E5: =IF($W$3="","미수신",MID($W$3,9,24)) -> 2026 Sep 21 0317 UTC | U5: # | W5: # Product description and SWPC contact on the Web | Y5: =IF($B$4="","",TEXT(INT($B$4)+(ROW()-2)*3/24,"hh:mm")) -> 09:00 | Z5: =IF($B$4="",NA(),IF(AND(INT($B$4)+(ROW()-2)*3/24-9/24>=$A$12,INT($B$4)+(ROW()-2)*3/24-9/24<$B$35),INDEX($E$12:$E$35,MATCH(INT($B$4)+(ROW()-2)*3/24-9/24,$A$12:$A$35,1)),NA())) -> #N/A | AB5: =IF($B$4="","",TEXT(MAX($H$12,MIN(INT($B$4-9/24)-3,$H$38-6))+ROW()-2,"m/d")) -> 9/24 | AC5: =IF($B$4="",NA(),IFERROR(INDEX($I$12:$I$38,MATCH(MAX($H$12,MIN(INT($B$4-9/24)-3,$H$38-6))+ROW()-2,$H$12:$H$38,0)),NA())) -> 4
A6: 3일 예보 Kp (3시간) | B6: =IF(B4="","",IF(AND(B5>=$A$12,B5<$B$35),INDEX($E$12:$E$35,MATCH(B5,$A$12:$A$35,1)),"범위 밖")) -> 범위 밖 | D6: 새로 고침 | E6: 데이터 > 모두 새로 고침 | U6: A. NOAA Geomagnetic Activity Observation and Forecast | W6: # https://www.swpc.noaa.gov/content/subscription-services | Y6: =IF($B$4="","",TEXT(INT($B$4)+(ROW()-2)*3/24,"hh:mm")) -> 12:00 | Z6: =IF($B$4="",NA(),IF(AND(INT($B$4)+(ROW()-2)*3/24-9/24>=$A$12,INT($B$4)+(ROW()-2)*3/24-9/24<$B$35),INDEX($E$12:$E$35,MATCH(INT($B$4)+(ROW()-2)*3/24-9/24,$A$12:$A$35,1)),NA())) -> #N/A | AB6: =IF($B$4="","",TEXT(MAX($H$12,MIN(INT($B$4-9/24)-3,$H$38-6))+ROW()-2,"m/d")) -> 9/25 | AC6: =IF($B$4="",NA(),IFERROR(INDEX($I$12:$I$38,MATCH(MAX($H$12,MIN(INT($B$4-9/24)-3,$H$38-6))+ROW()-2,$H$12:$H$38,0)),NA())) -> 5
A7: 27일 예보 Kp (UTC 일 최대) | B7: =IF(B4="","",IFERROR(INDEX($I$12:$I$38,MATCH(INT(B5),$H$12:$H$38,0)),"범위 밖")) -> 범위 밖 | D7: NOAA 3일 원문 | E7: https://services.swpc.noaa.gov/text/3-day-forecast.txt | W7: # | Y7: =IF($B$4="","",TEXT(INT($B$4)+(ROW()-2)*3/24,"hh:mm")) -> 15:00 | Z7: =IF($B$4="",NA(),IF(AND(INT($B$4)+(ROW()-2)*3/24-9/24>=$A$12,INT($B$4)+(ROW()-2)*3/24-9/24<$B$35),INDEX($E$12:$E$35,MATCH(INT($B$4)+(ROW()-2)*3/24-9/24,$A$12:$A$35,1)),NA())) -> #N/A | AB7: =IF($B$4="","",TEXT(MAX($H$12,MIN(INT($B$4-9/24)-3,$H$38-6))+ROW()-2,"m/d")) -> 9/26 | AC7: =IF($B$4="",NA(),IFERROR(INDEX($I$12:$I$38,MATCH(MAX($H$12,MIN(INT($B$4-9/24)-3,$H$38-6))+ROW()-2,$H$12:$H$38,0)),NA())) -> 3
A8: 사용 예보 | B8: =IF(B4="","",IF(ISNUMBER(B6),"3일 예보",IF(ISNUMBER(B7),"27일 예보","예보범위 밖"))) -> 예보범위 밖 | D8: NOAA 27일 원문 | E8: https://services.swpc.noaa.gov/text/27-day-outlook.txt | U8: The greatest observed 3 hr Kp over the past 24 hours was 2 (below NOAA | W8: # 27-day Space Weather Outlook Table | Y8: =IF($B$4="","",TEXT(INT($B$4)+(ROW()-2)*3/24,"hh:mm")) -> 18:00 | Z8: =IF($B$4="",NA(),IF(AND(INT($B$4)+(ROW()-2)*3/24-9/24>=$A$12,INT($B$4)+(ROW()-2)*3/24-9/24<$B$35),INDEX($E$12:$E$35,MATCH(INT($B$4)+(ROW()-2)*3/24-9/24,$A$12:$A$35,1)),NA())) -> #N/A | AB8: =IF($B$4="","",TEXT(MAX($H$12,MIN(INT($B$4-9/24)-3,$H$38-6))+ROW()-2,"m/d")) -> 9/27 | AC8: =IF($B$4="",NA(),IFERROR(INDEX($I$12:$I$38,MATCH(MAX($H$12,MIN(INT($B$4-9/24)-3,$H$38-6))+ROW()-2,$H$12:$H$38,0)),NA())) -> 3
A9: 운영 원칙 | B9: Kp·예보는 기록용입니다. 배제 기준은 1~4 가능, 5이상 불가능 | D9: 시간 기준 | E9: KST = UTC+9 · 조회 시 KST에서 9시간을 뺍니다. | U9: Scale levels). | W9: # Issued 2026-09-21 | Y9: =IF($B$4="","",TEXT(INT($B$4)+(ROW()-2)*3/24,"hh:mm")) -> 21:00 | Z9: =IF($B$4="",NA(),IF(AND(INT($B$4)+(ROW()-2)*3/24-9/24>=$A$12,INT($B$4)+(ROW()-2)*3/24-9/24<$B$35),INDEX($E$12:$E$35,MATCH(INT($B$4)+(ROW()-2)*3/24-9/24,$A$12:$A$35,1)),NA())) -> #N/A
D10: 인터넷 미연결 | E10: 저장된 마지막 예보가 남을 수 있으므로 발행시각을 확인합니다. | U10: The greatest expected 3 hr Kp for Sep 21-Sep 23 2026 is 2.00 (below NOAA | W10: #
A11: UTC 시작 | B11: UTC 종료 | C11: KST 시작 | D11: KST 종료 | E11: Kp 예보 | H11: UTC 날짜 | I11: 일 최대 Kp | J11: A index | K11: F10.7 | U11: Scale levels). | W11: # UTC Radio Flux Planetary Largest
A12: =IF($U$3="","",DATE(VALUE(MID($U$3,10,4)),MATCH(MID($U$3,15,3),{"Jan","Feb","Mar","Apr","May","Jun","Jul","Aug","Sep","Oct","Nov","Dec"},0),VALUE(MID($U$3,19,2)))+INT((ROW()-12)/8)+MOD(ROW()-12,8)*3/24) -> 46286 | B12: =IF(A12="","",A12+3/24) -> 46286.125 | C12: =IF(A12="","",A12+9/24) -> 46286.375 | D12: =IF(B12="","",B12+9/24) -> 46286.5 | E12: =IFERROR(VALUE(MID(INDEX($U$2:$U$70,MATCH(CHOOSE(MOD(ROW()-12,8)+1,"00-03UT*","03-06UT*","06-09UT*","09-12UT*","12-15UT*","15-18UT*","18-21UT*","21-00UT*"),$U$2:$U$70,0)),15+13*INT((ROW()-12)/8),4)),"") -> 1.67 | H12: =IF($W13="","",DATE(VALUE(LEFT($W13,4)),MATCH(MID($W13,6,3),{"Jan","Feb","Mar","Apr","May","Jun","Jul","Aug","Sep","Oct","Nov","Dec"},0),VALUE(MID($W13,10,2)))) -> 46286 | I12: =IFERROR(VALUE(MID($W13,42,2)),"") -> 2 | J12: =IFERROR(VALUE(MID($W13,30,3)),"") -> 5 | K12: =IFERROR(VALUE(MID($W13,17,3)),"") -> 105 | W12: # Date 10.7 cm A Index Kp Index
A13: =IF($U$3="","",DATE(VALUE(MID($U$3,10,4)),MATCH(MID($U$3,15,3),{"Jan","Feb","Mar","Apr","May","Jun","Jul","Aug","Sep","Oct","Nov","Dec"},0),VALUE(MID($U$3,19,2)))+INT((ROW()-12)/8)+MOD(ROW()-12,8)*3/24) -> 46286.125 | B13: =IF(A13="","",A13+3/24) -> 46286.25 | C13: =IF(A13="","",A13+9/24) -> 46286.5 | D13: =IF(B13="","",B13+9/24) -> 46286.625 | E13: =IFERROR(VALUE(MID(INDEX($U$2:$U$70,MATCH(CHOOSE(MOD(ROW()-12,8)+1,"00-03UT*","03-06UT*","06-09UT*","09-12UT*","12-15UT*","15-18UT*","18-21UT*","21-00UT*"),$U$2:$U$70,0)),15+13*INT((ROW()-12)/8),4)),"") -> 1 | H13: =IF($W14="","",DATE(VALUE(LEFT($W14,4)),MATCH(MID($W14,6,3),{"Jan","Feb","Mar","Apr","May","Jun","Jul","Aug","Sep","Oct","Nov","Dec"},0),VALUE(MID($W14,10,2)))) -> 46287 | I13: =IFERROR(VALUE(MID($W14,42,2)),"") -> 2 | J13: =IFERROR(VALUE(MID($W14,30,3)),"") -> 5 | K13: =IFERROR(VALUE(MID($W14,17,3)),"") -> 105 | U13: NOAA Kp index breakdown Sep 21-Sep 23 2026 | W13: 2026 Sep 21 105 5 2
A14: =IF($U$3="","",DATE(VALUE(MID($U$3,10,4)),MATCH(MID($U$3,15,3),{"Jan","Feb","Mar","Apr","May","Jun","Jul","Aug","Sep","Oct","Nov","Dec"},0),VALUE(MID($U$3,19,2)))+INT((ROW()-12)/8)+MOD(ROW()-12,8)*3/24) -> 46286.25 | B14: =IF(A14="","",A14+3/24) -> 46286.375 | C14: =IF(A14="","",A14+9/24) -> 46286.625 | D14: =IF(B14="","",B14+9/24) -> 46286.75 | E14: =IFERROR(VALUE(MID(INDEX($U$2:$U$70,MATCH(CHOOSE(MOD(ROW()-12,8)+1,"00-03UT*","03-06UT*","06-09UT*","09-12UT*","12-15UT*","15-18UT*","18-21UT*","21-00UT*"),$U$2:$U$70,0)),15+13*INT((ROW()-12)/8),4)),"") -> 1.67 | H14: =IF($W15="","",DATE(VALUE(LEFT($W15,4)),MATCH(MID($W15,6,3),{"Jan","Feb","Mar","Apr","May","Jun","Jul","Aug","Sep","Oct","Nov","Dec"},0),VALUE(MID($W15,10,2)))) -> 46288 | I14: =IFERROR(VALUE(MID($W15,42,2)),"") -> 2 | J14: =IFERROR(VALUE(MID($W15,30,3)),"") -> 5 | K14: =IFERROR(VALUE(MID($W15,17,3)),"") -> 100 | W14: 2026 Sep 22 105 5 2
A15: =IF($U$3="","",DATE(VALUE(MID($U$3,10,4)),MATCH(MID($U$3,15,3),{"Jan","Feb","Mar","Apr","May","Jun","Jul","Aug","Sep","Oct","Nov","Dec"},0),VALUE(MID($U$3,19,2)))+INT((ROW()-12)/8)+MOD(ROW()-12,8)*3/24) -> 46286.375 | B15: =IF(A15="","",A15+3/24) -> 46286.5 | C15: =IF(A15="","",A15+9/24) -> 46286.75 | D15: =IF(B15="","",B15+9/24) -> 46286.875 | E15: =IFERROR(VALUE(MID(INDEX($U$2:$U$70,MATCH(CHOOSE(MOD(ROW()-12,8)+1,"00-03UT*","03-06UT*","06-09UT*","09-12UT*","12-15UT*","15-18UT*","18-21UT*","21-00UT*"),$U$2:$U$70,0)),15+13*INT((ROW()-12)/8),4)),"") -> 1.67 | H15: =IF($W16="","",DATE(VALUE(LEFT($W16,4)),MATCH(MID($W16,6,3),{"Jan","Feb","Mar","Apr","May","Jun","Jul","Aug","Sep","Oct","Nov","Dec"},0),VALUE(MID($W16,10,2)))) -> 46289 | I15: =IFERROR(VALUE(MID($W16,42,2)),"") -> 4 | J15: =IFERROR(VALUE(MID($W16,30,3)),"") -> 20 | K15: =IFERROR(VALUE(MID($W16,17,3)),"") -> 100 | U15: Sep 21 Sep 22 Sep 23 | W15: 2026 Sep 23 100 5 2
A16: =IF($U$3="","",DATE(VALUE(MID($U$3,10,4)),MATCH(MID($U$3,15,3),{"Jan","Feb","Mar","Apr","May","Jun","Jul","Aug","Sep","Oct","Nov","Dec"},0),VALUE(MID($U$3,19,2)))+INT((ROW()-12)/8)+MOD(ROW()-12,8)*3/24) -> 46286.5 | B16: =IF(A16="","",A16+3/24) -> 46286.625 | C16: =IF(A16="","",A16+9/24) -> 46286.875 | D16: =IF(B16="","",B16+9/24) -> 46287 | E16: =IFERROR(VALUE(MID(INDEX($U$2:$U$70,MATCH(CHOOSE(MOD(ROW()-12,8)+1,"00-03UT*","03-06UT*","06-09UT*","09-12UT*","12-15UT*","15-18UT*","18-21UT*","21-00UT*"),$U$2:$U$70,0)),15+13*INT((ROW()-12)/8),4)),"") -> 1.33 | H16: =IF($W17="","",DATE(VALUE(LEFT($W17,4)),MATCH(MID($W17,6,3),{"Jan","Feb","Mar","Apr","May","Jun","Jul","Aug","Sep","Oct","Nov","Dec"},0),VALUE(MID($W17,10,2)))) -> 46290 | I16: =IFERROR(VALUE(MID($W17,42,2)),"") -> 5 | J16: =IFERROR(VALUE(MID($W17,30,3)),"") -> 18 | K16: =IFERROR(VALUE(MID($W17,17,3)),"") -> 105 | U16: 00-03UT 1.67 1.67 1.67 | W16: 2026 Sep 24 100 20 4
A17: =IF($U$3="","",DATE(VALUE(MID($U$3,10,4)),MATCH(MID($U$3,15,3),{"Jan","Feb","Mar","Apr","May","Jun","Jul","Aug","Sep","Oct","Nov","Dec"},0),VALUE(MID($U$3,19,2)))+INT((ROW()-12)/8)+MOD(ROW()-12,8)*3/24) -> 46286.625 | B17: =IF(A17="","",A17+3/24) -> 46286.75 | C17: =IF(A17="","",A17+9/24) -> 46287 | D17: =IF(B17="","",B17+9/24) -> 46287.125 | E17: =IFERROR(VALUE(MID(INDEX($U$2:$U$70,MATCH(CHOOSE(MOD(ROW()-12,8)+1,"00-03UT*","03-06UT*","06-09UT*","09-12UT*","12-15UT*","15-18UT*","18-21UT*","21-00UT*"),$U$2:$U$70,0)),15+13*INT((ROW()-12)/8),4)),"") -> 1.33 | H17: =IF($W18="","",DATE(VALUE(LEFT($W18,4)),MATCH(MID($W18,6,3),{"Jan","Feb","Mar","Apr","May","Jun","Jul","Aug","Sep","Oct","Nov","Dec"},0),VALUE(MID($W18,10,2)))) -> 46291 | I17: =IFERROR(VALUE(MID($W18,42,2)),"") -> 3 | J17: =IFERROR(VALUE(MID($W18,30,3)),"") -> 12 | K17: =IFERROR(VALUE(MID($W18,17,3)),"") -> 105 | U17: 03-06UT 1.00 2.00 2.00 | W17: 2026 Sep 25 105 18 5
A18: =IF($U$3="","",DATE(VALUE(MID($U$3,10,4)),MATCH(MID($U$3,15,3),{"Jan","Feb","Mar","Apr","May","Jun","Jul","Aug","Sep","Oct","Nov","Dec"},0),VALUE(MID($U$3,19,2)))+INT((ROW()-12)/8)+MOD(ROW()-12,8)*3/24) -> 46286.75 | B18: =IF(A18="","",A18+3/24) -> 46286.875 | C18: =IF(A18="","",A18+9/24) -> 46287.125 | D18: =IF(B18="","",B18+9/24) -> 46287.25 | E18: =IFERROR(VALUE(MID(INDEX($U$2:$U$70,MATCH(CHOOSE(MOD(ROW()-12,8)+1,"00-03UT*","03-06UT*","06-09UT*","09-12UT*","12-15UT*","15-18UT*","18-21UT*","21-00UT*"),$U$2:$U$70,0)),15+13*INT((ROW()-12)/8),4)),"") -> 1.33 | H18: =IF($W19="","",DATE(VALUE(LEFT($W19,4)),MATCH(MID($W19,6,3),{"Jan","Feb","Mar","Apr","May","Jun","Jul","Aug","Sep","Oct","Nov","Dec"},0),VALUE(MID($W19,10,2)))) -> 46292 | I18: =IFERROR(VALUE(MID($W19,42,2)),"") -> 3 | J18: =IFERROR(VALUE(MID($W19,30,3)),"") -> 8 | K18: =IFERROR(VALUE(MID($W19,17,3)),"") -> 100 | U18: 06-09UT 1.67 1.67 1.67 | W18: 2026 Sep 26 105 12 3
A19: =IF($U$3="","",DATE(VALUE(MID($U$3,10,4)),MATCH(MID($U$3,15,3),{"Jan","Feb","Mar","Apr","May","Jun","Jul","Aug","Sep","Oct","Nov","Dec"},0),VALUE(MID($U$3,19,2)))+INT((ROW()-12)/8)+MOD(ROW()-12,8)*3/24) -> 46286.875 | B19: =IF(A19="","",A19+3/24) -> 46287 | C19: =IF(A19="","",A19+9/24) -> 46287.25 | D19: =IF(B19="","",B19+9/24) -> 46287.375 | E19: =IFERROR(VALUE(MID(INDEX($U$2:$U$70,MATCH(CHOOSE(MOD(ROW()-12,8)+1,"00-03UT*","03-06UT*","06-09UT*","09-12UT*","12-15UT*","15-18UT*","18-21UT*","21-00UT*"),$U$2:$U$70,0)),15+13*INT((ROW()-12)/8),4)),"") -> 1.33 | H19: =IF($W20="","",DATE(VALUE(LEFT($W20,4)),MATCH(MID($W20,6,3),{"Jan","Feb","Mar","Apr","May","Jun","Jul","Aug","Sep","Oct","Nov","Dec"},0),VALUE(MID($W20,10,2)))) -> 46293 | I19: =IFERROR(VALUE(MID($W20,42,2)),"") -> 2 | J19: =IFERROR(VALUE(MID($W20,30,3)),"") -> 5 | K19: =IFERROR(VALUE(MID($W20,17,3)),"") -> 105 | U19: 09-12UT 1.67 1.33 1.33 | W19: 2026 Sep 27 100 8 3
A20: =IF($U$3="","",DATE(VALUE(MID($U$3,10,4)),MATCH(MID($U$3,15,3),{"Jan","Feb","Mar","Apr","May","Jun","Jul","Aug","Sep","Oct","Nov","Dec"},0),VALUE(MID($U$3,19,2)))+INT((ROW()-12)/8)+MOD(ROW()-12,8)*3/24) -> 46287 | B20: =IF(A20="","",A20+3/24) -> 46287.125 | C20: =IF(A20="","",A20+9/24) -> 46287.375 | D20: =IF(B20="","",B20+9/24) -> 46287.5 | E20: =IFERROR(VALUE(MID(INDEX($U$2:$U$70,MATCH(CHOOSE(MOD(ROW()-12,8)+1,"00-03UT*","03-06UT*","06-09UT*","09-12UT*","12-15UT*","15-18UT*","18-21UT*","21-00UT*"),$U$2:$U$70,0)),15+13*INT((ROW()-12)/8),4)),"") -> 1.67 | H20: =IF($W21="","",DATE(VALUE(LEFT($W21,4)),MATCH(MID($W21,6,3),{"Jan","Feb","Mar","Apr","May","Jun","Jul","Aug","Sep","Oct","Nov","Dec"},0),VALUE(MID($W21,10,2)))) -> 46294 | I20: =IFERROR(VALUE(MID($W21,42,2)),"") -> 2 | J20: =IFERROR(VALUE(MID($W21,30,3)),"") -> 5 | K20: =IFERROR(VALUE(MID($W21,17,3)),"") -> 110 | U20: 12-15UT 1.33 0.67 0.67 | W20: 2026 Sep 28 105 5 2
A21: =IF($U$3="","",DATE(VALUE(MID($U$3,10,4)),MATCH(MID($U$3,15,3),{"Jan","Feb","Mar","Apr","May","Jun","Jul","Aug","Sep","Oct","Nov","Dec"},0),VALUE(MID($U$3,19,2)))+INT((ROW()-12)/8)+MOD(ROW()-12,8)*3/24) -> 46287.125 | B21: =IF(A21="","",A21+3/24) -> 46287.25 | C21: =IF(A21="","",A21+9/24) -> 46287.5 | D21: =IF(B21="","",B21+9/24) -> 46287.625 | E21: =IFERROR(VALUE(MID(INDEX($U$2:$U$70,MATCH(CHOOSE(MOD(ROW()-12,8)+1,"00-03UT*","03-06UT*","06-09UT*","09-12UT*","12-15UT*","15-18UT*","18-21UT*","21-00UT*"),$U$2:$U$70,0)),15+13*INT((ROW()-12)/8),4)),"") -> 2 | H21: =IF($W22="","",DATE(VALUE(LEFT($W22,4)),MATCH(MID($W22,6,3),{"Jan","Feb","Mar","Apr","May","Jun","Jul","Aug","Sep","Oct","Nov","Dec"},0),VALUE(MID($W22,10,2)))) -> 46295 | I21: =IFERROR(VALUE(MID($W22,42,2)),"") -> 2 | J21: =IFERROR(VALUE(MID($W22,30,3)),"") -> 5 | K21: =IFERROR(VALUE(MID($W22,17,3)),"") -> 115 | U21: 15-18UT 1.33 0.67 0.67 | W21: 2026 Sep 29 110 5 2
A22: =IF($U$3="","",DATE(VALUE(MID($U$3,10,4)),MATCH(MID($U$3,15,3),{"Jan","Feb","Mar","Apr","May","Jun","Jul","Aug","Sep","Oct","Nov","Dec"},0),VALUE(MID($U$3,19,2)))+INT((ROW()-12)/8)+MOD(ROW()-12,8)*3/24) -> 46287.25 | B22: =IF(A22="","",A22+3/24) -> 46287.375 | C22: =IF(A22="","",A22+9/24) -> 46287.625 | D22: =IF(B22="","",B22+9/24) -> 46287.75 | E22: =IFERROR(VALUE(MID(INDEX($U$2:$U$70,MATCH(CHOOSE(MOD(ROW()-12,8)+1,"00-03UT*","03-06UT*","06-09UT*","09-12UT*","12-15UT*","15-18UT*","18-21UT*","21-00UT*"),$U$2:$U$70,0)),15+13*INT((ROW()-12)/8),4)),"") -> 1.67 | H22: =IF($W23="","",DATE(VALUE(LEFT($W23,4)),MATCH(MID($W23,6,3),{"Jan","Feb","Mar","Apr","May","Jun","Jul","Aug","Sep","Oct","Nov","Dec"},0),VALUE(MID($W23,10,2)))) -> 46296 | I22: =IFERROR(VALUE(MID($W23,42,2)),"") -> 2 | J22: =IFERROR(VALUE(MID($W23,30,3)),"") -> 5 | K22: =IFERROR(VALUE(MID($W23,17,3)),"") -> 115 | U22: 18-21UT 1.33 1.67 1.67 | W22: 2026 Sep 30 115 5 2
A23: =IF($U$3="","",DATE(VALUE(MID($U$3,10,4)),MATCH(MID($U$3,15,3),{"Jan","Feb","Mar","Apr","May","Jun","Jul","Aug","Sep","Oct","Nov","Dec"},0),VALUE(MID($U$3,19,2)))+INT((ROW()-12)/8)+MOD(ROW()-12,8)*3/24) -> 46287.375 | B23: =IF(A23="","",A23+3/24) -> 46287.5 | C23: =IF(A23="","",A23+9/24) -> 46287.75 | D23: =IF(B23="","",B23+9/24) -> 46287.875 | E23: =IFERROR(VALUE(MID(INDEX($U$2:$U$70,MATCH(CHOOSE(MOD(ROW()-12,8)+1,"00-03UT*","03-06UT*","06-09UT*","09-12UT*","12-15UT*","15-18UT*","18-21UT*","21-00UT*"),$U$2:$U$70,0)),15+13*INT((ROW()-12)/8),4)),"") -> 1.33 | H23: =IF($W24="","",DATE(VALUE(LEFT($W24,4)),MATCH(MID($W24,6,3),{"Jan","Feb","Mar","Apr","May","Jun","Jul","Aug","Sep","Oct","Nov","Dec"},0),VALUE(MID($W24,10,2)))) -> 46297 | I23: =IFERROR(VALUE(MID($W24,42,2)),"") -> 2 | J23: =IFERROR(VALUE(MID($W24,30,3)),"") -> 5 | K23: =IFERROR(VALUE(MID($W24,17,3)),"") -> 110 | U23: 21-00UT 1.33 1.67 1.67 | W23: 2026 Oct 01 115 5 2
A24: =IF($U$3="","",DATE(VALUE(MID($U$3,10,4)),MATCH(MID($U$3,15,3),{"Jan","Feb","Mar","Apr","May","Jun","Jul","Aug","Sep","Oct","Nov","Dec"},0),VALUE(MID($U$3,19,2)))+INT((ROW()-12)/8)+MOD(ROW()-12,8)*3/24) -> 46287.5 | B24: =IF(A24="","",A24+3/24) -> 46287.625 | C24: =IF(A24="","",A24+9/24) -> 46287.875 | D24: =IF(B24="","",B24+9/24) -> 46288 | E24: =IFERROR(VALUE(MID(INDEX($U$2:$U$70,MATCH(CHOOSE(MOD(ROW()-12,8)+1,"00-03UT*","03-06UT*","06-09UT*","09-12UT*","12-15UT*","15-18UT*","18-21UT*","21-00UT*"),$U$2:$U$70,0)),15+13*INT((ROW()-12)/8),4)),"") -> 0.67 | H24: =IF($W25="","",DATE(VALUE(LEFT($W25,4)),MATCH(MID($W25,6,3),{"Jan","Feb","Mar","Apr","May","Jun","Jul","Aug","Sep","Oct","Nov","Dec"},0),VALUE(MID($W25,10,2)))) -> 46298 | I24: =IFERROR(VALUE(MID($W25,42,2)),"") -> 2 | J24: =IFERROR(VALUE(MID($W25,30,3)),"") -> 5 | K24: =IFERROR(VALUE(MID($W25,17,3)),"") -> 105 | W24: 2026 Oct 02 110 5 2
A25: =IF($U$3="","",DATE(VALUE(MID($U$3,10,4)),MATCH(MID($U$3,15,3),{"Jan","Feb","Mar","Apr","May","Jun","Jul","Aug","Sep","Oct","Nov","Dec"},0),VALUE(MID($U$3,19,2)))+INT((ROW()-12)/8)+MOD(ROW()-12,8)*3/24) -> 46287.625 | B25: =IF(A25="","",A25+3/24) -> 46287.75 | C25: =IF(A25="","",A25+9/24) -> 46288 | D25: =IF(B25="","",B25+9/24) -> 46288.125 | E25: =IFERROR(VALUE(MID(INDEX($U$2:$U$70,MATCH(CHOOSE(MOD(ROW()-12,8)+1,"00-03UT*","03-06UT*","06-09UT*","09-12UT*","12-15UT*","15-18UT*","18-21UT*","21-00UT*"),$U$2:$U$70,0)),15+13*INT((ROW()-12)/8),4)),"") -> 0.67 | H25: =IF($W26="","",DATE(VALUE(LEFT($W26,4)),MATCH(MID($W26,6,3),{"Jan","Feb","Mar","Apr","May","Jun","Jul","Aug","Sep","Oct","Nov","Dec"},0),VALUE(MID($W26,10,2)))) -> 46299 | I25: =IFERROR(VALUE(MID($W26,42,2)),"") -> 3 | J25: =IFERROR(VALUE(MID($W26,30,3)),"") -> 12 | K25: =IFERROR(VALUE(MID($W26,17,3)),"") -> 110 | U25: Rationale: No G1 (Minor) or greater geomagnetic storms are expected. No | W25: 2026 Oct 03 105 5 2
A26: =IF($U$3="","",DATE(VALUE(MID($U$3,10,4)),MATCH(MID($U$3,15,3),{"Jan","Feb","Mar","Apr","May","Jun","Jul","Aug","Sep","Oct","Nov","Dec"},0),VALUE(MID($U$3,19,2)))+INT((ROW()-12)/8)+MOD(ROW()-12,8)*3/24) -> 46287.75 | B26: =IF(A26="","",A26+3/24) -> 46287.875 | C26: =IF(A26="","",A26+9/24) -> 46288.125 | D26: =IF(B26="","",B26+9/24) -> 46288.25 | E26: =IFERROR(VALUE(MID(INDEX($U$2:$U$70,MATCH(CHOOSE(MOD(ROW()-12,8)+1,"00-03UT*","03-06UT*","06-09UT*","09-12UT*","12-15UT*","15-18UT*","18-21UT*","21-00UT*"),$U$2:$U$70,0)),15+13*INT((ROW()-12)/8),4)),"") -> 1.67 | H26: =IF($W27="","",DATE(VALUE(LEFT($W27,4)),MATCH(MID($W27,6,3),{"Jan","Feb","Mar","Apr","May","Jun","Jul","Aug","Sep","Oct","Nov","Dec"},0),VALUE(MID($W27,10,2)))) -> 46300 | I26: =IFERROR(VALUE(MID($W27,42,2)),"") -> 4 | J26: =IFERROR(VALUE(MID($W27,30,3)),"") -> 15 | K26: =IFERROR(VALUE(MID($W27,17,3)),"") -> 110 | U26: significant transient or recurrent solar wind features are forecast. | W26: 2026 Oct 04 110 12 3
A27: =IF($U$3="","",DATE(VALUE(MID($U$3,10,4)),MATCH(MID($U$3,15,3),{"Jan","Feb","Mar","Apr","May","Jun","Jul","Aug","Sep","Oct","Nov","Dec"},0),VALUE(MID($U$3,19,2)))+INT((ROW()-12)/8)+MOD(ROW()-12,8)*3/24) -> 46287.875 | B27: =IF(A27="","",A27+3/24) -> 46288 | C27: =IF(A27="","",A27+9/24) -> 46288.25 | D27: =IF(B27="","",B27+9/24) -> 46288.375 | E27: =IFERROR(VALUE(MID(INDEX($U$2:$U$70,MATCH(CHOOSE(MOD(ROW()-12,8)+1,"00-03UT*","03-06UT*","06-09UT*","09-12UT*","12-15UT*","15-18UT*","18-21UT*","21-00UT*"),$U$2:$U$70,0)),15+13*INT((ROW()-12)/8),4)),"") -> 1.67 | H27: =IF($W28="","",DATE(VALUE(LEFT($W28,4)),MATCH(MID($W28,6,3),{"Jan","Feb","Mar","Apr","May","Jun","Jul","Aug","Sep","Oct","Nov","Dec"},0),VALUE(MID($W28,10,2)))) -> 46301 | I27: =IFERROR(VALUE(MID($W28,42,2)),"") -> 4 | J27: =IFERROR(VALUE(MID($W28,30,3)),"") -> 12 | K27: =IFERROR(VALUE(MID($W28,17,3)),"") -> 115 | W27: 2026 Oct 05 110 15 4
A28: =IF($U$3="","",DATE(VALUE(MID($U$3,10,4)),MATCH(MID($U$3,15,3),{"Jan","Feb","Mar","Apr","May","Jun","Jul","Aug","Sep","Oct","Nov","Dec"},0),VALUE(MID($U$3,19,2)))+INT((ROW()-12)/8)+MOD(ROW()-12,8)*3/24) -> 46288 | B28: =IF(A28="","",A28+3/24) -> 46288.125 | C28: =IF(A28="","",A28+9/24) -> 46288.375 | D28: =IF(B28="","",B28+9/24) -> 46288.5 | E28: =IFERROR(VALUE(MID(INDEX($U$2:$U$70,MATCH(CHOOSE(MOD(ROW()-12,8)+1,"00-03UT*","03-06UT*","06-09UT*","09-12UT*","12-15UT*","15-18UT*","18-21UT*","21-00UT*"),$U$2:$U$70,0)),15+13*INT((ROW()-12)/8),4)),"") -> 1.67 | H28: =IF($W29="","",DATE(VALUE(LEFT($W29,4)),MATCH(MID($W29,6,3),{"Jan","Feb","Mar","Apr","May","Jun","Jul","Aug","Sep","Oct","Nov","Dec"},0),VALUE(MID($W29,10,2)))) -> 46302 | I28: =IFERROR(VALUE(MID($W29,42,2)),"") -> 3 | J28: =IFERROR(VALUE(MID($W29,30,3)),"") -> 10 | K28: =IFERROR(VALUE(MID($W29,17,3)),"") -> 115 | U28: B. NOAA Solar Radiation Activity Observation and Forecast | W28: 2026 Oct 06 115 12 4
A29: =IF($U$3="","",DATE(VALUE(MID($U$3,10,4)),MATCH(MID($U$3,15,3),{"Jan","Feb","Mar","Apr","May","Jun","Jul","Aug","Sep","Oct","Nov","Dec"},0),VALUE(MID($U$3,19,2)))+INT((ROW()-12)/8)+MOD(ROW()-12,8)*3/24) -> 46288.125 | B29: =IF(A29="","",A29+3/24) -> 46288.25 | C29: =IF(A29="","",A29+9/24) -> 46288.5 | D29: =IF(B29="","",B29+9/24) -> 46288.625 | E29: =IFERROR(VALUE(MID(INDEX($U$2:$U$70,MATCH(CHOOSE(MOD(ROW()-12,8)+1,"00-03UT*","03-06UT*","06-09UT*","09-12UT*","12-15UT*","15-18UT*","18-21UT*","21-00UT*"),$U$2:$U$70,0)),15+13*INT((ROW()-12)/8),4)),"") -> 2 | H29: =IF($W30="","",DATE(VALUE(LEFT($W30,4)),MATCH(MID($W30,6,3),{"Jan","Feb","Mar","Apr","May","Jun","Jul","Aug","Sep","Oct","Nov","Dec"},0),VALUE(MID($W30,10,2)))) -> 46303 | I29: =IFERROR(VALUE(MID($W30,42,2)),"") -> 3 | J29: =IFERROR(VALUE(MID($W30,30,3)),"") -> 8 | K29: =IFERROR(VALUE(MID($W30,17,3)),"") -> 110 | W29: 2026 Oct 07 115 10 3
A30: =IF($U$3="","",DATE(VALUE(MID($U$3,10,4)),MATCH(MID($U$3,15,3),{"Jan","Feb","Mar","Apr","May","Jun","Jul","Aug","Sep","Oct","Nov","Dec"},0),VALUE(MID($U$3,19,2)))+INT((ROW()-12)/8)+MOD(ROW()-12,8)*3/24) -> 46288.25 | B30: =IF(A30="","",A30+3/24) -> 46288.375 | C30: =IF(A30="","",A30+9/24) -> 46288.625 | D30: =IF(B30="","",B30+9/24) -> 46288.75 | E30: =IFERROR(VALUE(MID(INDEX($U$2:$U$70,MATCH(CHOOSE(MOD(ROW()-12,8)+1,"00-03UT*","03-06UT*","06-09UT*","09-12UT*","12-15UT*","15-18UT*","18-21UT*","21-00UT*"),$U$2:$U$70,0)),15+13*INT((ROW()-12)/8),4)),"") -> 1.67 | H30: =IF($W31="","",DATE(VALUE(LEFT($W31,4)),MATCH(MID($W31,6,3),{"Jan","Feb","Mar","Apr","May","Jun","Jul","Aug","Sep","Oct","Nov","Dec"},0),VALUE(MID($W31,10,2)))) -> 46304 | I30: =IFERROR(VALUE(MID($W31,42,2)),"") -> 2 | J30: =IFERROR(VALUE(MID($W31,30,3)),"") -> 5 | K30: =IFERROR(VALUE(MID($W31,17,3)),"") -> 105 | U30: Solar radiation, as observed by NOAA GOES-18 over the past 24 hours, was | W30: 2026 Oct 08 110 8 3
A31: =IF($U$3="","",DATE(VALUE(MID($U$3,10,4)),MATCH(MID($U$3,15,3),{"Jan","Feb","Mar","Apr","May","Jun","Jul","Aug","Sep","Oct","Nov","Dec"},0),VALUE(MID($U$3,19,2)))+INT((ROW()-12)/8)+MOD(ROW()-12,8)*3/24) -> 46288.375 | B31: =IF(A31="","",A31+3/24) -> 46288.5 | C31: =IF(A31="","",A31+9/24) -> 46288.75 | D31: =IF(B31="","",B31+9/24) -> 46288.875 | E31: =IFERROR(VALUE(MID(INDEX($U$2:$U$70,MATCH(CHOOSE(MOD(ROW()-12,8)+1,"00-03UT*","03-06UT*","06-09UT*","09-12UT*","12-15UT*","15-18UT*","18-21UT*","21-00UT*"),$U$2:$U$70,0)),15+13*INT((ROW()-12)/8),4)),"") -> 1.33 | H31: =IF($W32="","",DATE(VALUE(LEFT($W32,4)),MATCH(MID($W32,6,3),{"Jan","Feb","Mar","Apr","May","Jun","Jul","Aug","Sep","Oct","Nov","Dec"},0),VALUE(MID($W32,10,2)))) -> 46305 | I31: =IFERROR(VALUE(MID($W32,42,2)),"") -> 2 | J31: =IFERROR(VALUE(MID($W32,30,3)),"") -> 5 | K31: =IFERROR(VALUE(MID($W32,17,3)),"") -> 110 | U31: below S-scale storm level thresholds. | W31: 2026 Oct 09 105 5 2
A32: =IF($U$3="","",DATE(VALUE(MID($U$3,10,4)),MATCH(MID($U$3,15,3),{"Jan","Feb","Mar","Apr","May","Jun","Jul","Aug","Sep","Oct","Nov","Dec"},0),VALUE(MID($U$3,19,2)))+INT((ROW()-12)/8)+MOD(ROW()-12,8)*3/24) -> 46288.5 | B32: =IF(A32="","",A32+3/24) -> 46288.625 | C32: =IF(A32="","",A32+9/24) -> 46288.875 | D32: =IF(B32="","",B32+9/24) -> 46289 | E32: =IFERROR(VALUE(MID(INDEX($U$2:$U$70,MATCH(CHOOSE(MOD(ROW()-12,8)+1,"00-03UT*","03-06UT*","06-09UT*","09-12UT*","12-15UT*","15-18UT*","18-21UT*","21-00UT*"),$U$2:$U$70,0)),15+13*INT((ROW()-12)/8),4)),"") -> 0.67 | H32: =IF($W33="","",DATE(VALUE(LEFT($W33,4)),MATCH(MID($W33,6,3),{"Jan","Feb","Mar","Apr","May","Jun","Jul","Aug","Sep","Oct","Nov","Dec"},0),VALUE(MID($W33,10,2)))) -> 46306 | I32: =IFERROR(VALUE(MID($W33,42,2)),"") -> 3 | J32: =IFERROR(VALUE(MID($W33,30,3)),"") -> 9 | K32: =IFERROR(VALUE(MID($W33,17,3)),"") -> 100 | W32: 2026 Oct 10 110 5 2
A33: =IF($U$3="","",DATE(VALUE(MID($U$3,10,4)),MATCH(MID($U$3,15,3),{"Jan","Feb","Mar","Apr","May","Jun","Jul","Aug","Sep","Oct","Nov","Dec"},0),VALUE(MID($U$3,19,2)))+INT((ROW()-12)/8)+MOD(ROW()-12,8)*3/24) -> 46288.625 | B33: =IF(A33="","",A33+3/24) -> 46288.75 | C33: =IF(A33="","",A33+9/24) -> 46289 | D33: =IF(B33="","",B33+9/24) -> 46289.125 | E33: =IFERROR(VALUE(MID(INDEX($U$2:$U$70,MATCH(CHOOSE(MOD(ROW()-12,8)+1,"00-03UT*","03-06UT*","06-09UT*","09-12UT*","12-15UT*","15-18UT*","18-21UT*","21-00UT*"),$U$2:$U$70,0)),15+13*INT((ROW()-12)/8),4)),"") -> 0.67 | H33: =IF($W34="","",DATE(VALUE(LEFT($W34,4)),MATCH(MID($W34,6,3),{"Jan","Feb","Mar","Apr","May","Jun","Jul","Aug","Sep","Oct","Nov","Dec"},0),VALUE(MID($W34,10,2)))) -> 46307 | I33: =IFERROR(VALUE(MID($W34,42,2)),"") -> 3 | J33: =IFERROR(VALUE(MID($W34,30,3)),"") -> 8 | K33: =IFERROR(VALUE(MID($W34,17,3)),"") -> 97 | U33: Solar Radiation Storm Forecast for Sep 21-Sep 23 2026 | W33: 2026 Oct 11 100 9 3
A34: =IF($U$3="","",DATE(VALUE(MID($U$3,10,4)),MATCH(MID($U$3,15,3),{"Jan","Feb","Mar","Apr","May","Jun","Jul","Aug","Sep","Oct","Nov","Dec"},0),VALUE(MID($U$3,19,2)))+INT((ROW()-12)/8)+MOD(ROW()-12,8)*3/24) -> 46288.75 | B34: =IF(A34="","",A34+3/24) -> 46288.875 | C34: =IF(A34="","",A34+9/24) -> 46289.125 | D34: =IF(B34="","",B34+9/24) -> 46289.25 | E34: =IFERROR(VALUE(MID(INDEX($U$2:$U$70,MATCH(CHOOSE(MOD(ROW()-12,8)+1,"00-03UT*","03-06UT*","06-09UT*","09-12UT*","12-15UT*","15-18UT*","18-21UT*","21-00UT*"),$U$2:$U$70,0)),15+13*INT((ROW()-12)/8),4)),"") -> 1.67 | H34: =IF($W35="","",DATE(VALUE(LEFT($W35,4)),MATCH(MID($W35,6,3),{"Jan","Feb","Mar","Apr","May","Jun","Jul","Aug","Sep","Oct","Nov","Dec"},0),VALUE(MID($W35,10,2)))) -> 46308 | I34: =IFERROR(VALUE(MID($W35,42,2)),"") -> 3 | J34: =IFERROR(VALUE(MID($W35,30,3)),"") -> 8 | K34: =IFERROR(VALUE(MID($W35,17,3)),"") -> 96 | W34: 2026 Oct 12 97 8 3
A35: =IF($U$3="","",DATE(VALUE(MID($U$3,10,4)),MATCH(MID($U$3,15,3),{"Jan","Feb","Mar","Apr","May","Jun","Jul","Aug","Sep","Oct","Nov","Dec"},0),VALUE(MID($U$3,19,2)))+INT((ROW()-12)/8)+MOD(ROW()-12,8)*3/24) -> 46288.875 | B35: =IF(A35="","",A35+3/24) -> 46289 | C35: =IF(A35="","",A35+9/24) -> 46289.25 | D35: =IF(B35="","",B35+9/24) -> 46289.375 | E35: =IFERROR(VALUE(MID(INDEX($U$2:$U$70,MATCH(CHOOSE(MOD(ROW()-12,8)+1,"00-03UT*","03-06UT*","06-09UT*","09-12UT*","12-15UT*","15-18UT*","18-21UT*","21-00UT*"),$U$2:$U$70,0)),15+13*INT((ROW()-12)/8),4)),"") -> 1.67 | H35: =IF($W36="","",DATE(VALUE(LEFT($W36,4)),MATCH(MID($W36,6,3),{"Jan","Feb","Mar","Apr","May","Jun","Jul","Aug","Sep","Oct","Nov","Dec"},0),VALUE(MID($W36,10,2)))) -> 46309 | I35: =IFERROR(VALUE(MID($W36,42,2)),"") -> 3 | J35: =IFERROR(VALUE(MID($W36,30,3)),"") -> 8 | K35: =IFERROR(VALUE(MID($W36,17,3)),"") -> 95 | U35: Sep 21 Sep 22 Sep 23 | W35: 2026 Oct 13 96 8 3
H36: =IF($W37="","",DATE(VALUE(LEFT($W37,4)),MATCH(MID($W37,6,3),{"Jan","Feb","Mar","Apr","May","Jun","Jul","Aug","Sep","Oct","Nov","Dec"},0),VALUE(MID($W37,10,2)))) -> 46310 | I36: =IFERROR(VALUE(MID($W37,42,2)),"") -> 2 | J36: =IFERROR(VALUE(MID($W37,30,3)),"") -> 5 | K36: =IFERROR(VALUE(MID($W37,17,3)),"") -> 100 | U36: S1 or greater 1% 1% 1% | W36: 2026 Oct 14 95 8 3
H37: =IF($W38="","",DATE(VALUE(LEFT($W38,4)),MATCH(MID($W38,6,3),{"Jan","Feb","Mar","Apr","May","Jun","Jul","Aug","Sep","Oct","Nov","Dec"},0),VALUE(MID($W38,10,2)))) -> 46311 | I37: =IFERROR(VALUE(MID($W38,42,2)),"") -> 2 | J37: =IFERROR(VALUE(MID($W38,30,3)),"") -> 5 | K37: =IFERROR(VALUE(MID($W38,17,3)),"") -> 105 | L37: 노란색 KST 날짜·시각을 바꾸면 그래프도 해당 날짜로 갱신됩니다. ‘데이터 > 모두 새로 고침’ 후 최신 NOAA 예보를 확인하십시오. Kp는 기록 항목이며 배제 기준은 아직 확정되지 않았습니다. | W37: 2026 Oct 15 100 5 2
H38: =IF($W39="","",DATE(VALUE(LEFT($W39,4)),MATCH(MID($W39,6,3),{"Jan","Feb","Mar","Apr","May","Jun","Jul","Aug","Sep","Oct","Nov","Dec"},0),VALUE(MID($W39,10,2)))) -> 46312 | I38: =IFERROR(VALUE(MID($W39,42,2)),"") -> 2 | J38: =IFERROR(VALUE(MID($W39,30,3)),"") -> 5 | K38: =IFERROR(VALUE(MID($W39,17,3)),"") -> 100 | U38: Rationale: No S1 (Minor) or greater solar radiation storms are expected. | W38: 2026 Oct 16 105 5 2
U39: No significant active region activity favorable for radiation storm | W39: 2026 Oct 17 100 5 2
U40: production is forecast.
...

Sheet ⑩ 원문 보관
A1: ⑩ 원문 보관 — 지점마다 다섯 칸. 여기에 붙여 넣는 것이 곧 저장입니다 (⑨ 시트가 고른 지점의 칸을 읽어 계산합니다)
A2: 01_태백 신규점 — 아래 다섯 칸에 그 방향 txt 를 통째로 붙여 넣습니다
A3: 동 원문 | B3: 서 원문 | C3: 남 원문 | D3: 북 원문 | E3: 수직(삼각대) 원문 | F3: =HYPERLINK("#'⑨ 구배 자동계산'!A1","◂ ⑨ 계산 시트로") -> ◂ ⑨ 계산 시트로
A705: 02_임계 신규점1 — 아래 다섯 칸에 그 방향 txt 를 통째로 붙여 넣습니다
A706: 동 원문 | B706: 서 원문 | C706: 남 원문 | D706: 북 원문 | E706: 수직(삼각대) 원문 | F706: =HYPERLINK("#'⑨ 구배 자동계산'!A1","◂ ⑨ 계산 시트로") -> ◂ ⑨ 계산 시트로
A1408: 03_예산 신규점2 — 아래 다섯 칸에 그 방향 txt 를 통째로 붙여 넣습니다
A1409: 동 원문 | B1409: 서 원문 | C1409: 남 원문 | D1409: 북 원문 | E1409: 수직(삼각대) 원문 | F1409: =HYPERLINK("#'⑨ 구배 자동계산'!A1","◂ ⑨ 계산 시트로") -> ◂ ⑨ 계산 시트로
A2111: 04_진안 신규점1 — 아래 다섯 칸에 그 방향 txt 를 통째로 붙여 넣습니다
A2112: 동 원문 | B2112: 서 원문 | C2112: 남 원문 | D2112: 북 원문 | E2112: 수직(삼각대) 원문 | F2112: =HYPERLINK("#'⑨ 구배 자동계산'!A1","◂ ⑨ 계산 시트로") -> ◂ ⑨ 계산 시트로
A2814: 05_무풍 신규점1 — 아래 다섯 칸에 그 방향 txt 를 통째로 붙여 넣습니다
A2815: 동 원문 | B2815: 서 원문 | C2815: 남 원문 | D2815: 북 원문 | E2815: 수직(삼각대) 원문 | F2815: =HYPERLINK("#'⑨ 구배 자동계산'!A1","◂ ⑨ 계산 시트로") -> ◂ ⑨ 계산 시트로
A3517: 06_길담 신규점 — 아래 다섯 칸에 그 방향 txt 를 통째로 붙여 넣습니다
A3518: 동 원문 | B3518: 서 원문 | C3518: 남 원문 | D3518: 북 원문 | E3518: 수직(삼각대) 원문 | F3518: =HYPERLINK("#'⑨ 구배 자동계산'!A1","◂ ⑨ 계산 시트로") -> ◂ ⑨ 계산 시트로
A4220: 07_남해 신규점1 — 아래 다섯 칸에 그 방향 txt 를 통째로 붙여 넣습니다
A4221: 동 원문 | B4221: 서 원문 | C4221: 남 원문 | D4221: 북 원문 | E4221: 수직(삼각대) 원문 | F4221: =HYPERLINK("#'⑨ 구배 자동계산'!A1","◂ ⑨ 계산 시트로") -> ◂ ⑨ 계산 시트로
A4923: 08_청일 신규점2 — 아래 다섯 칸에 그 방향 txt 를 통째로 붙여 넣습니다
A4924: 동 원문 | B4924: 서 원문 | C4924: 남 원문 | D4924: 북 원문 | E4924: 수직(삼각대) 원문 | F4924: =HYPERLINK("#'⑨ 구배 자동계산'!A1","◂ ⑨ 계산 시트로") -> ◂ ⑨ 계산 시트로
A5626: 09_어론 신규점 — 아래 다섯 칸에 그 방향 txt 를 통째로 붙여 넣습니다
A5627: 동 원문 | B5627: 서 원문 | C5627: 남 원문 | D5627: 북 원문 | E5627: 수직(삼각대) 원문 | F5627: =HYPERLINK("#'⑨ 구배 자동계산'!A1","◂ ⑨ 계산 시트로") -> ◂ ⑨ 계산 시트로
A6329: 10_예안 신규점1 — 아래 다섯 칸에 그 방향 txt 를 통째로 붙여 넣습니다
A6330: 동 원문 | B6330: 서 원문 | C6330: 남 원문 | D6330: 북 원문 | E6330: 수직(삼각대) 원문 | F6330: =HYPERLINK("#'⑨ 구배 자동계산'!A1","◂ ⑨ 계산 시트로") -> ◂ ⑨ 계산 시트로
A7032: 11_소천 신규점4 — 아래 다섯 칸에 그 방향 txt 를 통째로 붙여 넣습니다
A7033: 동 원문 | B7033: 서 원문 | C7033: 남 원문 | D7033: 북 원문 | E7033: 수직(삼각대) 원문 | F7033: =HYPERLINK("#'⑨ 구배 자동계산'!A1","◂ ⑨ 계산 시트로") -> ◂ ⑨ 계산 시트로
A7735: 12_순창 신규점 — 아래 다섯 칸에 그 방향 txt 를 통째로 붙여 넣습니다
A7736: 동 원문 | B7736: 서 원문 | C7736: 남 원문 | D7736: 북 원문 | E7736: 수직(삼각대) 원문 | F7736: =HYPERLINK("#'⑨ 구배 자동계산'!A1","◂ ⑨ 계산 시트로") -> ◂ ⑨ 계산 시트로
A8438: 13_순천 신규점 — 아래 다섯 칸에 그 방향 txt 를 통째로 붙여 넣습니다
A8439: 동 원문 | B8439: 서 원문 | C8439: 남 원문 | D8439: 북 원문 | E8439: 수직(삼각대) 원문 | F8439: =HYPERLINK("#'⑨ 구배 자동계산'!A1","◂ ⑨ 계산 시트로") -> ◂ ⑨ 계산 시트로
A9141: 14_청송 신규점1 — 아래 다섯 칸에 그 방향 txt 를 통째로 붙여 넣습니다
A9142: 동 원문 | B9142: 서 원문 | C9142: 남 원문 | D9142: 북 원문 | E9142: 수직(삼각대) 원문 | F9142: =HYPERLINK("#'⑨ 구배 자동계산'!A1","◂ ⑨ 계산 시트로") -> ◂ ⑨ 계산 시트로
A9844: 15_의성 신규점 — 아래 다섯 칸에 그 방향 txt 를 통째로 붙여 넣습니다
A9845: 동 원문 | B9845: 서 원문 | C9845: 남 원문 | D9845: 북 원문 | E9845: 수직(삼각대) 원문 | F9845: =HYPERLINK("#'⑨ 구배 자동계산'!A1","◂ ⑨ 계산 시트로") -> ◂ ⑨ 계산 시트로
A10547: 16_예천 신규점 — 아래 다섯 칸에 그 방향 txt 를 통째로 붙여 넣습니다
A10548: 동 원문 | B10548: 서 원문 | C10548: 남 원문 | D10548: 북 원문 | E10548: 수직(삼각대) 원문 | F10548: =HYPERLINK("#'⑨ 구배 자동계산'!A1","◂ ⑨ 계산 시트로") -> ◂ ⑨ 계산 시트로
A11250: 17_영양 신규점4 — 아래 다섯 칸에 그 방향 txt 를 통째로 붙여 넣습니다
A11251: 동 원문 | B11251: 서 원문 | C11251: 남 원문 | D11251: 북 원문 | E11251: 수직(삼각대) 원문 | F11251: =HYPERLINK("#'⑨ 구배 자동계산'!A1","◂ ⑨ 계산 시트로") -> ◂ ⑨ 계산 시트로
A11953: 18_통영 신규점 — 아래 다섯 칸에 그 방향 txt 를 통째로 붙여 넣습니다
A11954: 동 원문 | B11954: 서 원문 | C11954: 남 원문 | D11954: 북 원문 | E11954: 수직(삼각대) 원문 | F11954: =HYPERLINK("#'⑨ 구배 자동계산'!A1","◂ ⑨ 계산 시트로") -> ◂ ⑨ 계산 시트로
A12656: 19_오호 신규점 — 아래 다섯 칸에 그 방향 txt 를 통째로 붙여 넣습니다
A12657: 동 원문 | B12657: 서 원문 | C12657: 남 원문 | D12657: 북 원문 | E12657: 수직(삼각대) 원문 | F12657: =HYPERLINK("#'⑨ 구배 자동계산'!A1","◂ ⑨ 계산 시트로") -> ◂ ⑨ 계산 시트로
B12658: file 11survey.b 21 IX 26 | C12658: file 22survey.b 21 IX 26 | D12658: file 28survey.b 21 IX 26
...

Sheet ⑨ 구배 자동계산
A1: ⑨ 구배 자동계산 — GSM-19T 파일 내용을 그대로 붙여 넣는 곳
A2: ① 오른쪽 위에서 **지점을 고르고**, 바로 아래 「원문 칸으로 가기」를 누르면 그 지점의 다섯 칸(동·서·남·북·수직)으로 갑니다. 거기에 그 방향 txt 를 «통째로» 붙여 넣으세요(메모장에서 Ctrl+A → Ctrl+C → 칸 하나만 고르고 Ctrl+V). ② 붙여 넣는 자리가 곧 보관 자리라 **따로 저장할 필요가 없습니다** — 지점을 바꿨다가 돌아와도 원문이 그대로 있고 결과도 다시 나옵니다. ③ 오른쪽 초록 표가 바로 채워지고, 고른 지점 카드에도 저절로 들어갑니다 — 블록을 시각순으로 줄 세워 P0(전)·1 m·…·P0(후) 로 배정하고, 0.00 읽음과 품질 뒷자리 0, 중앙값에서 ±5 nT 벗어난 값을 빼고 평균을 냅니다. ④ 아래 A9:E708 은 보관 칸을 비춰 보는 곳이라 여기에 붙여 넣지 않습니다.
A4: 지점 | B4: 19_오호 신규점 | C4: =IF($B$4="","지점을 고르면 그 지점 원문 칸과 카드가 이어집니다 — 먼저 골라 주세요","「"&$B$4&"」 원문은 ⑩ 보관 시트에 남고, 결과는 같은 이름 카드에 자동으로 들어갑니다") -> 「19_오호 신규점」 원문은 ⑩ 보관 시트에 남고, 결과는 같은 이름 카드에 자동으로 들어갑니다
A6: =IF($B$4="","▶ 먼저 지점을 골라 주세요",HYPERLINK("#'⑩ 원문 보관'!A"&$CM$6,"▶ 「"&$B$4&"」 원문 칸으로 가기 — 거기에 붙여 넣으면 이 표가 채워지고 그대로 보관됩니다")) -> ▶ 「19_오호 신규점」 원문 칸으로 가기 — 거기에 붙여 넣으면 이 표가 채워지고 그대로 보관됩니다 | CM6: =IFERROR(MATCH($B$4,$CM$9:$CM$58,0)*703-699,0) -> 12658
A7: =IF(COUNTIFS($Q$9:$Q$708,0,$R$9:$R$708,">0")+COUNTIFS($V$9:$V$708,0,$W$9:$W$708,">0")+COUNTIFS($AA$9:$AA$708,0,$AB$9:$AB$708,">0")+COUNTIFS($AF$9:$AF$708,0,$AG$9:$AG$708,">0")+COUNTIFS($AK$9:$AK$708,0,$AL$9:$AL$708,">0")>0,"⚠ 첫 /time 머리글이 빠진 자료가 있습니다 — 그 방향은 첫 측점이 버려지고 거리가 한 칸씩 당겨집니다. 파일을 머리글째 다시 붙여 넣으세요",IF(OR(AND(COUNT($AS$9:$AS$22)>1,MAX($AS$9:$AS$22)-MIN($AS$9:$AS$22)>120000),AND(COUNT($BB$9:$BB$22)>1,MAX($BB$9:$BB$22)-MIN($BB$9:$BB$22)>120000),AND(COUNT($BK$9:$BK$22)>1,MAX($BK$9:$BK$22)-MIN($BK$9:$BK$22)>120000),AND(COUNT($BT$9:$BT$22)>1,MAX($BT$9:$BT$22)-MIN($BT$9:$BT$22)>120000),AND(COUNT($CC$9:$CC$22)>1,MAX($CC$9:$CC$22)-MIN($CC$9:$CC$22)>120000)),"⚠ 한 자료 안에서 시각이 12시간 넘게 벌어졌습니다 — 자정을 넘겼다면 블록 순서가 뒤집힙니다. 시각을 확인하고 필요하면 날짜별로 나눠 붙여 넣으세요",IF(COUNTIFS($AS$9:$AS$22,">=180000")+COUNTIFS($AS$9:$AS$22,">0",$AS$9:$AS$22,"<60000")+COUNTIFS($BB$9:$BB$22,">=180000")+COUNTIFS($BB$9:$BB$22,">0",$BB$9:$BB$22,"<60000")+COUNTIFS($BK$9:$BK$22,">=180000")+COUNTIFS($BK$9:$BK$22,">0",$BK$9:$BK$22,"<60000")+COUNTIFS($BT$9:$BT$22,">=180000")+COUNTIFS($BT$9:$BT$22,">0",$BT$9:$BT$22,"<60000")+COUNTIFS($CC$9:$CC$22,">=180000")+COUNTIFS($CC$9:$CC$22,">0",$CC$9:$CC$22,"<60000")>0,"⚠ 야간(18시 이후·06시 이전) 시각이 "&COUNTIFS($AS$9:$AS$22,">=180000")+COUNTIFS($AS$9:$AS$22,">0",$AS$9:$AS$22,"<60000")+COUNTIFS($BB$9:$BB$22,">=180000")+COUNTIFS($BB$9:$BB$22,">0",$BB$9:$BB$22,"<60000")+COUNTIFS($BK$9:$BK$22,">=180000")+COUNTIFS($BK$9:$BK$22,">0",$BK$9:$BK$22,"<60000")+COUNTIFS($BT$9:$BT$22,">=180000")+COUNTIFS($BT$9:$BT$22,">0",$BT$9:$BT$22,"<60000")+COUNTIFS($CC$9:$CC$22,">=180000")+COUNTIFS($CC$9:$CC$22,">0",$CC$9:$CC$22,"<60000")&"개 있습니다 — 야간에는 재지 않기로 했으니 기기 시각이 맞는지 확인해 주세요","")))
A8: 동 원문 (⑩ 보관에서 읽음) | B8: 서 원문 (⑩ 보관에서 읽음) | C8: 남 원문 (⑩ 보관에서 읽음) | D8: 북 원문 (⑩ 보관에서 읽음) | E8: 수직(삼각대) 원문 (⑩ 보관에서 읽음) | G8: 거리 | H8: 동 시각 | I8: 동 평균 F(nT) | J8: 서 시각 | K8: 서 평균 F(nT) | L8: 남 시각 | M8: 남 평균 F(nT) | N8: 북 시각 | O8: 북 평균 F(nT)
A9: =IF($CM$6=0,"",IF(INDEX('⑩ 원문 보관'!$A:$E,$CM$6+ROW()-9,COLUMN())="","",INDEX('⑩ 원문 보관'!$A:$E,$CM$6+ROW()-9,COLUMN()))) | B9: =IF($CM$6=0,"",IF(INDEX('⑩ 원문 보관'!$A:$E,$CM$6+ROW()-9,COLUMN())="","",INDEX('⑩ 원문 보관'!$A:$E,$CM$6+ROW()-9,COLUMN()))) -> file 11survey.b 21 IX 26 | C9: =IF($CM$6=0,"",IF(INDEX('⑩ 원문 보관'!$A:$E,$CM$6+ROW()-9,COLUMN())="","",INDEX('⑩ 원문 보관'!$A:$E,$CM$6+ROW()-9,COLUMN()))) -> file 22survey.b 21 IX 26 | D9: =IF($CM$6=0,"",IF(INDEX('⑩ 원문 보관'!$A:$E,$CM$6+ROW()-9,COLUMN())="","",INDEX('⑩ 원문 보관'!$A:$E,$CM$6+ROW()-9,COLUMN()))) -> file 28survey.b 21 IX 26 | E9: =IF($CM$6=0,"",IF(INDEX('⑩ 원문 보관'!$A:$E,$CM$6+ROW()-9,COLUMN())="","",INDEX('⑩ 원문 보관'!$A:$E,$CM$6+ROW()-9,COLUMN()))) | G9: P0(전) | H9: =IFERROR(INT(IFERROR(INDEX($AS$9:$AS$22,MATCH(1,$AY$9:$AY$22,0)),"")/100),"") -> 1116 | I9: =IFERROR(INDEX($AW$9:$AW$22,MATCH(1,$AY$9:$AY$22,0)),"") -> 51389.35 | J9: =IFERROR(INT(IFERROR(INDEX($BB$9:$BB$22,MATCH(1,$BH$9:$BH$22,0)),"")/100),"") -> 1143 | K9: =IFERROR(INDEX($BF$9:$BF$22,MATCH(1,$BH$9:$BH$22,0)),"") -> 51409.21 | L9: =IFERROR(INT(IFERROR(INDEX($BK$9:$BK$22,MATCH(1,$BQ$9:$BQ$22,0)),"")/100),"") -> 1218 | M9: =IFERROR(INDEX($BO$9:$BO$22,MATCH(1,$BQ$9:$BQ$22,0)),"") -> 51388.66 | N9: =IFERROR(INT(IFERROR(INDEX($BT$9:$BT$22,MATCH(1,$BZ$9:$BZ$22,0)),"")/100),"") -> 1235 | O9: =IFERROR(INDEX($BX$9:$BX$22,MATCH(1,$BZ$9:$BZ$22,0)),"") -> 51398.6 | Q9: =IF(A9="",0,IF(LEFT(TRIM(A9),5)="/time",0+1,0)) -> 0 | R9: =IFERROR(IF(ISNUMBER(--LEFT(TRIM(A9),1)),VALUE(LEFT(TRIM(A9),6)),""),"") | S9: =IFERROR(VALUE(TRIM(MID(SUBSTITUTE(TRIM(A9)," ",REPT(" ",30)),31,30))),"") | T9: =IFERROR(TRIM(MID(SUBSTITUTE(TRIM(A9)," ",REPT(" ",30)),61,30)),"") | U9: =IF(OR(R9="",S9="",T9=""),0,IF(AND(S9>1000,RIGHT(T9,1)<>"0"),1,0)) -> 0 | V9: =IF(B9="",0,IF(LEFT(TRIM(B9),5)="/time",0+1,0)) -> 0 | W9: =IFERROR(IF(ISNUMBER(--LEFT(TRIM(B9),1)),VALUE(LEFT(TRIM(B9),6)),""),"") | X9: =IFERROR(VALUE(TRIM(MID(SUBSTITUTE(TRIM(B9)," ",REPT(" ",30)),31,30))),"") | Y9: =IFERROR(TRIM(MID(SUBSTITUTE(TRIM(B9)," ",REPT(" ",30)),61,30)),"") -> 21 | Z9: =IF(OR(W9="",X9="",Y9=""),0,IF(AND(X9>1000,RIGHT(Y9,1)<>"0"),1,0)) -> 0 | AA9: =IF(C9="",0,IF(LEFT(TRIM(C9),5)="/time",0+1,0)) -> 0 | AB9: =IFERROR(IF(ISNUMBER(--LEFT(TRIM(C9),1)),VALUE(LEFT(TRIM(C9),6)),""),"") | AC9: =IFERROR(VALUE(TRIM(MID(SUBSTITUTE(TRIM(C9)," ",REPT(" ",30)),31,30))),"") | AD9: =IFERROR(TRIM(MID(SUBSTITUTE(TRIM(C9)," ",REPT(" ",30)),61,30)),"") -> 21 | AE9: =IF(OR(AB9="",AC9="",AD9=""),0,IF(AND(AC9>1000,RIGHT(AD9,1)<>"0"),1,0)) -> 0 | AF9: =IF(D9="",0,IF(LEFT(TRIM(D9),5)="/time",0+1,0)) -> 0 | AG9: =IFERROR(IF(ISNUMBER(--LEFT(TRIM(D9),1)),VALUE(LEFT(TRIM(D9),6)),""),"") | AH9: =IFERROR(VALUE(TRIM(MID(SUBSTITUTE(TRIM(D9)," ",REPT(" ",30)),31,30))),"") | AI9: =IFERROR(TRIM(MID(SUBSTITUTE(TRIM(D9)," ",REPT(" ",30)),61,30)),"") -> 21 | AJ9: =IF(OR(AG9="",AH9="",AI9=""),0,IF(AND(AH9>1000,RIGHT(AI9,1)<>"0"),1,0)) -> 0 | AK9: =IF(E9="",0,IF(LEFT(TRIM(E9),5)="/time",0+1,0)) -> 0 | AL9: =IFERROR(IF(ISNUMBER(--LEFT(TRIM(E9),1)),VALUE(LEFT(TRIM(E9),6)),""),"") | AM9: =IFERROR(VALUE(TRIM(MID(SUBSTITUTE(TRIM(E9)," ",REPT(" ",30)),31,30))),"") | AN9: =IFERROR(TRIM(MID(SUBSTITUTE(TRIM(E9)," ",REPT(" ",30)),61,30)),"") | AO9: =IF(OR(AL9="",AM9="",AN9=""),0,IF(AND(AM9>1000,RIGHT(AN9,1)<>"0"),1,0)) -> 0 | AQ9: 1 | AR9: =COUNTIFS($Q$9:$Q$708,AQ9,$U$9:$U$708,1) -> 32 | AS9: {=IFERROR(SMALL(IF($Q$9:$Q$708=AQ9,$R$9:$R$708,""),1),"")} -> 111632 | AT9: {=IFERROR(LARGE(IF($Q$9:$Q$708=AQ9,$R$9:$R$708,""),1),"")} -> 111907 | AU9: {=IFERROR(MEDIAN(IF(($Q$9:$Q$708=AQ9)*($U$9:$U$708=1),$S$9:$S$708,"")),"")} -> 51389.35 | AV9: =IF(AU9="",0,COUNTIFS($Q$9:$Q$708,AQ9,$U$9:$U$708,1,$S$9:$S$708,">="&AU9-5,$S$9:$S$708,"<="&AU9+5)) -> 32 | AW9: =IF(AV9=0,"",ROUND(AVERAGEIFS($S$9:$S$708,$Q$9:$Q$708,AQ9,$U$9:$U$708,1,$S$9:$S$708,">="&AU9-5,$S$9:$S$708,"<="&AU9+5),2)) -> 51389.35 | AX9: =IF(AU9="","",COUNTIFS($Q$9:$Q$708,AQ9,$R$9:$R$708,">0")-AV9) -> 0 | AY9: =IF(AS9="","",RANK(AS9,$AS$9:$AS$22,1)) -> 1 | AZ9: 1 | BA9: =COUNTIFS($V$9:$V$708,AZ9,$Z$9:$Z$708,1) -> 30 | BB9: {=IFERROR(SMALL(IF($V$9:$V$708=AZ9,$W$9:$W$708,""),1),"")} -> 114727 | BC9: {=IFERROR(LARGE(IF($V$9:$V$708=AZ9,$W$9:$W$708,""),1),"")} -> 114952 | BD9: {=IFERROR(MEDIAN(IF(($V$9:$V$708=AZ9)*($Z$9:$Z$708=1),$X$9:$X$708,"")),"")} -> 51388.955 | BE9: =IF(BD9="",0,COUNTIFS($V$9:$V$708,AZ9,$Z$9:$Z$708,1,$X$9:$X$708,">="&BD9-5,$X$9:$X$708,"<="&BD9+5)) -> 30 | BF9: =IF(BE9=0,"",ROUND(AVERAGEIFS($X$9:$X$708,$V$9:$V$708,AZ9,$Z$9:$Z$708,1,$X$9:$X$708,">="&BD9-5,$X$9:$X$708,"<="&BD9+5),2)) -> 51388.95 | BG9: =IF(BD9="","",COUNTIFS($V$9:$V$708,AZ9,$W$9:$W$708,">0")-BE9) -> 0 | BH9: =IF(BB9="","",RANK(BB9,$BB$9:$BB$22,1)) -> 2 | BI9: 1 | BJ9: =COUNTIFS($AA$9:$AA$708,BI9,$AE$9:$AE$708,1) -> 26 | BK9: {=IFERROR(SMALL(IF($AA$9:$AA$708=BI9,$AB$9:$AB$708,""),1),"")} -> 121822 | BL9: {=IFERROR(LARGE(IF($AA$9:$AA$708=BI9,$AB$9:$AB$708,""),1),"")} -> 122027 | BM9: {=IFERROR(MEDIAN(IF(($AA$9:$AA$708=BI9)*($AE$9:$AE$708=1),$AC$9:$AC$708,"")),"")} -> 51388.675 | BN9: =IF(BM9="",0,COUNTIFS($AA$9:$AA$708,BI9,$AE$9:$AE$708,1,$AC$9:$AC$708,">="&BM9-5,$AC$9:$AC$708,"<="&BM9+5)) -> 26 | BO9: =IF(BN9=0,"",ROUND(AVERAGEIFS($AC$9:$AC$708,$AA$9:$AA$708,BI9,$AE$9:$AE$708,1,$AC$9:$AC$708,">="&BM9-5,$AC$9:$AC$708,"<="&BM9+5),2)) -> 51388.66 | BP9: =IF(BM9="","",COUNTIFS($AA$9:$AA$708,BI9,$AB$9:$AB$708,">0")-BN9) -> 0 | BQ9: =IF(BK9="","",RANK(BK9,$BK$9:$BK$22,1)) -> 1 | BR9: 1 | BS9: =COUNTIFS($AF$9:$AF$708,BR9,$AJ$9:$AJ$708,1) -> 30 | BT9: {=IFERROR(SMALL(IF($AF$9:$AF$708=BR9,$AG$9:$AG$708,""),1),"")} -> 123522 | BU9: {=IFERROR(LARGE(IF($AF$9:$AF$708=BR9,$AG$9:$AG$708,""),1),"")} -> 123747 | BV9: {=IFERROR(MEDIAN(IF(($AF$9:$AF$708=BR9)*($AJ$9:$AJ$708=1),$AH$9:$AH$708,"")),"")} -> 51398.67 | BW9: =IF(BV9="",0,COUNTIFS($AF$9:$AF$708,BR9,$AJ$9:$AJ$708,1,$AH$9:$AH$708,">="&BV9-5,$AH$9:$AH$708,"<="&BV9+5)) -> 28 | BX9: =IF(BW9=0,"",ROUND(AVERAGEIFS($AH$9:$AH$708,$AF$9:$AF$708,BR9,$AJ$9:$AJ$708,1,$AH$9:$AH$708,">="&BV9-5,$AH$9:$AH$708,"<="&BV9+5),2)) -> 51398.6 | BY9: =IF(BV9="","",COUNTIFS($AF$9:$AF$708,BR9,$AG$9:$AG$708,">0")-BW9) -> 2 | BZ9: =IF(BT9="","",RANK(BT9,$BT$9:$BT$22,1)) -> 1 | CA9: 1 | CB9: =COUNTIFS($AK$9:$AK$708,CA9,$AO$9:$AO$708,1) -> 27 | CC9: {=IFERROR(SMALL(IF($AK$9:$AK$708=CA9,$AL$9:$AL$708,""),1),"")} -> 130352 | CD9: {=IFERROR(LARGE(IF($AK$9:$AK$708=CA9,$AL$9:$AL$708,""),1),"")} -> 130602 | CE9: {=IFERROR(MEDIAN(IF(($AK$9:$AK$708=CA9)*($AO$9:$AO$708=1),$AM$9:$AM$708,"")),"")} -> 51406.29 | CF9: =IF(CE9="",0,COUNTIFS($AK$9:$AK$708,CA9,$AO$9:$AO$708,1,$AM$9:$AM$708,">="&CE9-5,$AM$9:$AM$708,"<="&CE9+5)) -> 27 | CG9: =IF(CF9=0,"",ROUND(AVERAGEIFS($AM$9:$AM$708,$AK$9:$AK$708,CA9,$AO$9:$AO$708,1,$AM$9:$AM$708,">="&CE9-5,$AM$9:$AM$708,"<="&CE9+5),2)) -> 51406.33 | CH9: =IF(CE9="","",COUNTIFS($AK$9:$AK$708,CA9,$AL$9:$AL$708,">0")-CF9) -> 0 | CI9: =IF(CC9="","",RANK(CC9,$CC$9:$CC$22,1)) -> 1 | CM9: 01_태백 신규점 | CQ9: P0~1 m | CR9: =IF(OR($I$9="",$I$10=""),"",ABS($I$10-$I$9)) -> 26.72 | CS9: =IF(OR($K$9="",$K$10=""),"",ABS($K$10-$K$9)) -> 20.26 | CT9: =IF(OR($M$9="",$M$10=""),"",ABS($M$10-$M$9)) -> 20.09 | CU9: =IF(OR($O$9="",$O$10=""),"",ABS($O$10-$O$9)) -> 56.52
A10: =IF($CM$6=0,"",IF(INDEX('⑩ 원문 보관'!$A:$E,$CM$6+ROW()-9,COLUMN())="","",INDEX('⑩ 원문 보관'!$A:$E,$CM$6+ROW()-9,COLUMN()))) | B10: =IF($CM$6=0,"",IF(INDEX('⑩ 원문 보관'!$A:$E,$CM$6+ROW()-9,COLUMN())="","",INDEX('⑩ 원문 보관'!$A:$E,$CM$6+ROW()-9,COLUMN()))) -> /datum 57000.00 | C10: =IF($CM$6=0,"",IF(INDEX('⑩ 원문 보관'!$A:$E,$CM$6+ROW()-9,COLUMN())="","",INDEX('⑩ 원문 보관'!$A:$E,$CM$6+ROW()-9,COLUMN()))) -> /datum 57000.00 | D10: =IF($CM$6=0,"",IF(INDEX('⑩ 원문 보관'!$A:$E,$CM$6+ROW()-9,COLUMN())="","",INDEX('⑩ 원문 보관'!$A:$E,$CM$6+ROW()-9,COLUMN()))) -> /datum 57000.00 | E10: =IF($CM$6=0,"",IF(INDEX('⑩ 원문 보관'!$A:$E,$CM$6+ROW()-9,COLUMN())="","",INDEX('⑩ 원문 보관'!$A:$E,$CM$6+ROW()-9,COLUMN()))) | G10: 1 m | H10: =IF(COUNT($AS$9:$AS$22)-1<2,"",IFERROR(INT(IFERROR(INDEX($AS$9:$AS$22,MATCH(2,$AY$9:$AY$22,0)),"")/100),"")) -> 1119 | I10: =IF(COUNT($AS$9:$AS$22)-1<2,"",IFERROR(INDEX($AW$9:$AW$22,MATCH(2,$AY$9:$AY$22,0)),"")) -> 51362.63 | J10: =IF(COUNT($BB$9:$BB$22)-1<2,"",IFERROR(INT(IFERROR(INDEX($BB$9:$BB$22,MATCH(2,$BH$9:$BH$22,0)),"")/100),"")) -> 1147 | K10: =IF(COUNT($BB$9:$BB$22)-1<2,"",IFERROR(INDEX($BF$9:$BF$22,MATCH(2,$BH$9:$BH$22,0)),"")) -> 51388.95 | L10: =IF(COUNT($BK$9:$BK$22)-1<2,"",IFERROR(INT(IFERROR(INDEX($BK$9:$BK$22,MATCH(2,$BQ$9:$BQ$22,0)),"")/100),"")) -> 1221 | M10: =IF(COUNT($BK$9:$BK$22)-1<2,"",IFERROR(INDEX($BO$9:$BO$22,MATCH(2,$BQ$9:$BQ$22,0)),"")) -> 51368.57 | N10: =IF(COUNT($BT$9:$BT$22)-1<2,"",IFERROR(INT(IFERROR(INDEX($BT$9:$BT$22,MATCH(2,$BZ$9:$BZ$22,0)),"")/100),"")) -> 1238 | O10: =IF(COUNT($BT$9:$BT$22)-1<2,"",IFERROR(INDEX($BX$9:$BX$22,MATCH(2,$BZ$9:$BZ$22,0)),"")) -> 51455.12 | Q10: =IF(A10="",N(Q9),IF(LEFT(TRIM(A10),5)="/time",N(Q9)+1,N(Q9))) -> 0 | R10: =IFERROR(IF(ISNUMBER(--LEFT(TRIM(A10),1)),VALUE(LEFT(TRIM(A10),6)),""),"") | S10: =IFERROR(VALUE(TRIM(MID(SUBSTITUTE(TRIM(A10)," ",REPT(" ",30)),31,30))),"") | T10: =IFERROR(TRIM(MID(SUBSTITUTE(TRIM(A10)," ",REPT(" ",30)),61,30)),"") | U10: =IF(OR(R10="",S10="",T10=""),0,IF(AND(S10>1000,RIGHT(T10,1)<>"0"),1,0)) -> 0 | V10: =IF(B10="",N(V9),IF(LEFT(TRIM(B10),5)="/time",N(V9)+1,N(V9))) -> 0 | W10: =IFERROR(IF(ISNUMBER(--LEFT(TRIM(B10),1)),VALUE(LEFT(TRIM(B10),6)),""),"") | X10: =IFERROR(VALUE(TRIM(MID(SUBSTITUTE(TRIM(B10)," ",REPT(" ",30)),31,30))),"") -> 57000 | Y10: =IFERROR(TRIM(MID(SUBSTITUTE(TRIM(B10)," ",REPT(" ",30)),61,30)),"") | Z10: =IF(OR(W10="",X10="",Y10=""),0,IF(AND(X10>1000,RIGHT(Y10,1)<>"0"),1,0)) -> 0 | AA10: =IF(C10="",N(AA9),IF(LEFT(TRIM(C10),5)="/time",N(AA9)+1,N(AA9))) -> 0 | AB10: =IFERROR(IF(ISNUMBER(--LEFT(TRIM(C10),1)),VALUE(LEFT(TRIM(C10),6)),""),"") | AC10: =IFERROR(VALUE(TRIM(MID(SUBSTITUTE(TRIM(C10)," ",REPT(" ",30)),31,30))),"") -> 57000 | AD10: =IFERROR(TRIM(MID(SUBSTITUTE(TRIM(C10)," ",REPT(" ",30)),61,30)),"") | AE10: =IF(OR(AB10="",AC10="",AD10=""),0,IF(AND(AC10>1000,RIGHT(AD10,1)<>"0"),1,0)) -> 0 | AF10: =IF(D10="",N(AF9),IF(LEFT(TRIM(D10),5)="/time",N(AF9)+1,N(AF9))) -> 0 | AG10: =IFERROR(IF(ISNUMBER(--LEFT(TRIM(D10),1)),VALUE(LEFT(TRIM(D10),6)),""),"") | AH10: =IFERROR(VALUE(TRIM(MID(SUBSTITUTE(TRIM(D10)," ",REPT(" ",30)),31,30))),"") -> 57000 | AI10: =IFERROR(TRIM(MID(SUBSTITUTE(TRIM(D10)," ",REPT(" ",30)),61,30)),"") | AJ10: =IF(OR(AG10="",AH10="",AI10=""),0,IF(AND(AH10>1000,RIGHT(AI10,1)<>"0"),1,0)) -> 0 | AK10: =IF(E10="",N(AK9),IF(LEFT(TRIM(E10),5)="/time",N(AK9)+1,N(AK9))) -> 0 | AL10: =IFERROR(IF(ISNUMBER(--LEFT(TRIM(E10),1)),VALUE(LEFT(TRIM(E10),6)),""),"") | AM10: =IFERROR(VALUE(TRIM(MID(SUBSTITUTE(TRIM(E10)," ",REPT(" ",30)),31,30))),"") | AN10: =IFERROR(TRIM(MID(SUBSTITUTE(TRIM(E10)," ",REPT(" ",30)),61,30)),"") | AO10: =IF(OR(AL10="",AM10="",AN10=""),0,IF(AND(AM10>1000,RIGHT(AN10,1)<>"0"),1,0)) -> 0 | AQ10: 2 | AR10: =COUNTIFS($Q$9:$Q$708,AQ10,$U$9:$U$708,1) -> 31 | AS10: {=IFERROR(SMALL(IF($Q$9:$Q$708=AQ10,$R$9:$R$708,""),1),"")} -> 111952 | AT10: {=IFERROR(LARGE(IF($Q$9:$Q$708=AQ10,$R$9:$R$708,""),1),"")} -> 112222 | AU10: {=IFERROR(MEDIAN(IF(($Q$9:$Q$708=AQ10)*($U$9:$U$708=1),$S$9:$S$708,"")),"")} -> 51362.63 | AV10: =IF(AU10="",0,COUNTIFS($Q$9:$Q$708,AQ10,$U$9:$U$708,1,$S$9:$S$708,">="&AU10-5,$S$9:$S$708,"<="&AU10+5)) -> 31 | AW10: =IF(AV10=0,"",ROUND(AVERAGEIFS($S$9:$S$708,$Q$9:$Q$708,AQ10,$U$9:$U$708,1,$S$9:$S$708,">="&AU10-5,$S$9:$S$708,"<="&AU10+5),2)) -> 51362.63 | AX10: =IF(AU10="","",COUNTIFS($Q$9:$Q$708,AQ10,$R$9:$R$708,">0")-AV10) -> 0 | AY10: =IF(AS10="","",RANK(AS10,$AS$9:$AS$22,1)) -> 2 | AZ10: 2 | BA10: =COUNTIFS($V$9:$V$708,AZ10,$Z$9:$Z$708,1) -> 41 | BB10: {=IFERROR(SMALL(IF($V$9:$V$708=AZ10,$W$9:$W$708,""),1),"")} -> 114357 | BC10: {=IFERROR(LARGE(IF($V$9:$V$708=AZ10,$W$9:$W$708,""),1),"")} -> 114717 | BD10: {=IFERROR(MEDIAN(IF(($V$9:$V$708=AZ10)*($Z$9:$Z$708=1),$X$9:$X$708,"")),"")} -> 51409.1 | BE10: =IF(BD10="",0,COUNTIFS($V$9:$V$708,AZ10,$Z$9:$Z$708,1,$X$9:$X$708,">="&BD10-5,$X$9:$X$708,"<="&BD10+5)) -> 37 | BF10: =IF(BE10=0,"",ROUND(AVERAGEIFS($X$9:$X$708,$V$9:$V$708,AZ10,$Z$9:$Z$708,1,$X$9:$X$708,">="&BD10-5,$X$9:$X$708,"<="&BD10+5),2)) -> 51409.21 | BG10: =IF(BD10="","",COUNTIFS($V$9:$V$708,AZ10,$W$9:$W$708,">0")-BE10) -> 4 | BH10: =IF(BB10="","",RANK(BB10,$BB$9:$BB$22,1)) -> 1 | BI10: 2 | BJ10: =COUNTIFS($AA$9:$AA$708,BI10,$AE$9:$AE$708,1) -> 27 | BK10: {=IFERROR(SMALL(IF($AA$9:$AA$708=BI10,$AB$9:$AB$708,""),1),"")} -> 122117 | BL10: {=IFERROR(LARGE(IF($AA$9:$AA$708=BI10,$AB$9:$AB$708,""),1),"")} -> 122327 | BM10: {=IFERROR(MEDIAN(IF(($AA$9:$AA$708=BI10)*($AE$9:$AE$708=1),$AC$9:$AC$708,"")),"")} -> 51368.56 | BN10: =IF(BM10="",0,COUNTIFS($AA$9:$AA$708,BI10,$AE$9:$AE$708,1,$AC$9:$AC$708,">="&BM10-5,$AC$9:$AC$708,"<="&BM10+5)) -> 27 | BO10: =IF(BN10=0,"",ROUND(AVERAGEIFS($AC$9:$AC$708,$AA$9:$AA$708,BI10,$AE$9:$AE$708,1,$AC$9:$AC$708,">="&BM10-5,$AC$9:$AC$708,"<="&BM10+5),2)) -> 51368.57 | BP10: =IF(BM10="","",COUNTIFS($AA$9:$AA$708,BI10,$AB$9:$AB$708,">0")-BN10) -> 0 | BQ10: =IF(BK10="","",RANK(BK10,$BK$9:$BK$22,1)) -> 2 | BR10: 2 | BS10: =COUNTIFS($AF$9:$AF$708,BR10,$AJ$9:$AJ$708,1) -> 26 | BT10: {=IFERROR(SMALL(IF($AF$9:$AF$708=BR10,$AG$9:$AG$708,""),1),"")} -> 123817 | BU10: {=IFERROR(LARGE(IF($AF$9:$AF$708=BR10,$AG$9:$AG$708,""),1),"")} -> 124022 | BV10: {=IFERROR(MEDIAN(IF(($AF$9:$AF$708=BR10)*($AJ$9:$AJ$708=1),$AH$9:$AH$708,"")),"")} -> 51455.18 | BW10: =IF(BV10="",0,COUNTIFS($AF$9:$AF$708,BR10,$AJ$9:$AJ$708,1,$AH$9:$AH$708,">="&BV10-5,$AH$9:$AH$708,"<="&BV10+5)) -> 26 | BX10: =IF(BW10=0,"",ROUND(AVERAGEIFS($AH$9:$AH$708,$AF$9:$AF$708,BR10,$AJ$9:$AJ$708,1,$AH$9:$AH$708,">="&BV10-5,$AH$9:$AH$708,"<="&BV10+5),2)) -> 51455.12 | BY10: =IF(BV10="","",COUNTIFS($AF$9:$AF$708,BR10,$AG$9:$AG$708,">0")-BW10) -> 0 | BZ10: =IF(BT10="","",RANK(BT10,$BT$9:$BT$22,1)) -> 2 | CA10: 2 | CB10: =COUNTIFS($AK$9:$AK$708,CA10,$AO$9:$AO$708,1) -> 29 | CC10: {=IFERROR(SMALL(IF($AK$9:$AK$708=CA10,$AL$9:$AL$708,""),1),"")} -> 130722 | CD10: {=IFERROR(LARGE(IF($AK$9:$AK$708=CA10,$AL$9:$AL$708,""),1),"")} -> 130942 | CE10: {=IFERROR(MEDIAN(IF(($AK$9:$AK$708=CA10)*($AO$9:$AO$708=1),$AM$9:$AM$708,"")),"")} -> 51399.59 | CF10: =IF(CE10="",0,COUNTIFS($AK$9:$AK$708,CA10,$AO$9:$AO$708,1,$AM$9:$AM$708,">="&CE10-5,$AM$9:$AM$708,"<="&CE10+5)) -> 28 | CG10: =IF(CF10=0,"",ROUND(AVERAGEIFS($AM$9:$AM$708,$AK$9:$AK$708,CA10,$AO$9:$AO$708,1,$AM$9:$AM$708,">="&CE10-5,$AM$9:$AM$708,"<="&CE10+5),2)) -> 51399.6 | CH10: =IF(CE10="","",COUNTIFS($AK$9:$AK$708,CA10,$AL$9:$AL$708,">0")-CF10) -> 1 | CI10: =IF(CC10="","",RANK(CC10,$CC$9:$CC$22,1)) -> 2 | CM10: 02_임계 신규점1 | CQ10: 1~2 m | CR10: =IF(OR($I$10="",$I$11=""),"",ABS($I$11-$I$10)) -> 11.5 | CS10: =IF(OR($K$10="",$K$11=""),"",ABS($K$11-$K$10)) -> 56.36 | CT10: =IF(OR($M$10="",$M$11=""),"",ABS($M$11-$M$10)) -> 14.46 | CU10: =IF(OR($O$10="",$O$11=""),"",ABS($O$11-$O$10)) -> 95.85
